S28837654X6K27GA00004T000500
S28837654A6K27GA00004TB000500IWM   0000736300Y
S28837657A1K27GA00003RB002000AFL   0000061600Y
S28837656X6K27GA00004T000500
S28837656A6K27GA00004TB000500IWM   0000735900Y
S28837658XBK27GA0000DP000100
S28837658XBK27GA0000DQ000100
S28837659X9K27G60000KO001000
S28837658X6K27GA00004T000500
S28837658A6K27GA00004TB000500IWM   0000736300Y
S28837660ABK27GA0000DRS000100TWM   0000702600Y
S28837663A4K27GA000087S000047DIA   0001298800Y
S28837662A6K27GA000051B002000IR    0000431500Y
S28837664XAK27GA0000EX000500
S28837664AAK27GA0000EXB000500SPY   0001424600Y
S28837665XAK27GA0000F2000500
S28837665AAK27GA0000F2B000500SPY   0001424500Y
S28837665XAK27GA0000EW000500
S28837665AAK27GA0000EWS000500SPY   0001425100Y
S28837665XAK27GA0000OZ003000
S28837665XAK27GA0000OX003000
S28837665XAK27GA0000E4001000
S28837665AAK27GA0000E4B001000SPY   0001424600Y
S28837665XAK27GA0000E5001000
S28837665AAK27GA0000E5S001000SPY   0001425200Y
S28837665XAK27GA0000FD000500
S28837665AAK27GA0000FDB000500SPY   0001424600Y
S28837665XAK27GA0000P4001000
S28837665XAK27GA0000O6000500
S28837665AAK27GA0000O6S000500SPY   0001425200Y
S28837665AAK27GA0000P5S003000SPY   0001425200Y
S28837665XAK27GA0000P0003000
S28837665XAK27GA0000OY003000
S28837665AAK27GA0000P6S003000SPY   0001425200Y
S28837666AAK27GA0000P7S002000SPY   0001425300Y
S28837666X4K27GA00003H000200
S28837666A4K27GA00003HB000200DIA   0001298000Y
S28837666X4K27GA000087000047
S28837666XAK27GA0000OJ001000
S28837666AAK27GA0000P8B001000SDS   0000548000Y
S28837666XAK27GA0000KE001000
S28837667AAK27GA0000P9S001000SPY   0001425100Y
S28837667AAK27GA0000PAB003000SPY   0001424300Y
S28837668A2K27G600002NB002000BBT   0000027100Y
S28837667AAK27GA0000PBB001000SPY   0001424600Y
S28837667XBK27GA0000CW001000
S28837667ABK27GA0000DSS001000SSO   0000764700Y
S28837667AAK27GA0000PCB003000SPY   0001424300Y
S28837668XAK27GA0000K1001000
S28837668AAK27GA0000K1S001000SPY   0001425100Y
S28837668AAK27GA0000PDB001000SDS   0000547900Y
S28837671XAK27GA0000FE000500
S28837671AAK27GA0000FEB000500SPY   0001424500Y
S28837673XAK27GA0000F2000500
S28837673AAK27GA0000F2B000500SPY   0001424900Y
S28837673A4K27GA000088S000047DIA   0001298500Y
S28837673A4K27GA000089B000100DOG   0000597200Y
S28837673X4K27GA00007Y000100
S28837673A4K27GA00008AB000100DXD   0000499700Y
S28837674X3K27G600003B000100
S28837674X3K27G600002I000100
S28837674A3K27G600003IS000100DDM   0000802100Y
S28837674XBK27GA0000CP001000
S28837676X9K27G60000KM005000
S28837676X9K27G60000KN005000
S28837676X9K27G60000G2002000
S28837676A9K27G60000G2B002000QQQQ  0000495000Y
S28837677A9K27G60000KPS005000QQQQ  0000495700Y
S28837677A9K27G60000KQS005000QQQQ  0000495700Y
S28837678X9K27G60000EN002000
S28837678A9K27G60000ENS002000QQQQ  0000495700Y
S28837680X4K27GA00007X000200
S28837684A4K27GA00008BS000200DIA   0001298400Y
S28837685A4K27GA00008CB000100DXD   0000499800Y
S28837686A3K27G600003JS000100DDM   0000802000Y
S28837684A6K27GA000052B002000IRF   0000216300Y
S28837688XAK27GA0000KF001000
S28837688X6K27GA00004T000500
S28837688A6K27GA00004TB000500IWM   0000735900Y
S28837691A3K27G600003KB002000COH   0000028800Y
S28837692AAK27GA0000PEB000600SPY   0001424600Y
S28837694XAK27GA0000DU001000
S28837694XBK27GA0000CQ001000
S28837694ABK27GA0000DTB001000SSO   0000763500Y
S28837696ABK27GA0000DUB001000SSO   0000763700Y
S28837696AAK27GA0000PFS001000SDS   0000549400Y
S28837698X8K27G600001J000500
S28837698X8K27G600001K000100
S28837707X6K27GA00002B000500
S28837707A6K27GA00002BS000500IWM   0000736400Y
S28837710ABK27GA0000DVS000100UWM   0000542900Y
S28837710ABK27GA0000DWB000100TWM   0000701500Y
S28837710ABK27GA0000DXB000100TWM   0000701600Y
S28837727A4K27GA00008DB002000EIX   0000041600Y
S28837739X6K27GA00004O002000
S28837741A5K27GA00002GB002000HNZ   0000038400Y
S28837754A5K27GA00002HB002000HOT   0000039100Y
S28837786X9K27G60000KP005000
S28837787A9K27G60000KRS005000QQQQ  0000496100Y
S28837792X9K27G60000G2002000
S28837792A9K27G60000G2B002000QQQQ  0000495500Y
S28837793X9K27G60000EN002000
S28837793A9K27G60000ENS002000QQQQ  0000496000Y
S28837809X9K27G60000KJ005000
S28837810X9K27G60000KI005000
S28837810X9K27G60000G2002000
S28837810A9K27G60000G2B002000QQQQ  0000495000Y
S28837810X9K27G60000KR005000
S28837810A9K27G60000KSS005000QQQQ  0000495700Y
S28837810X9K27G60000EN002000
S28837810A9K27G60000ENS002000QQQQ  0000495700Y
S28837811A9K27G60000KTB005000QQQQ  0000495200Y
S28837811A9K27G60000KUB005000QQQQ  0000495200Y
S28837813X9K27G60000EU002000
S28837813A9K27G60000EUB002000QQQQ  0000495300Y
S28837908X9K27G60000KS005000
S28837908X9K27G60000KT005000
S28837908X9K27G60000KU005000
S28837908A9K27G60000KVB005000QQQQ  0000495600Y
S28837908A9K27G60000KWB005000QQQQ  0000495600Y
S28837909X9K27G60000EU002000
S28837909A9K27G60000EUB002000QQQQ  0000495600Y
S28837909X9K27G60000G2002000
S28837909A9K27G60000G2B002000QQQQ  0000495500Y
S28837910A9K27G60000KXS005000QQQQ  0000496100Y
S28837913X9K27G60000EN002000
S28837913A9K27G60000ENS002000QQQQ  0000496000Y
S28837919X4K27GA000080000100
S28837928A4K27GA00008EB000100DRYS  0001068000Y
S28837938X4K27GA000081000100
S28837948A4K27GA00008FB000100DRYS  0001068000Y
S28837958X4K27GA00008F000100
S28837958A4K27GA00008GB000100DRYS  0001066900Y
S28837986X9K27G60000KX005000
S28837986X9K27G60000KV005000
S28837986X9K27G60000KW005000
S28837986X9K27G60000EN002000
S28837986A9K27G60000ENS002000QQQQ  0000495700Y
S28837986A9K27G60000KYS005000QQQQ  0000495700Y
S28837986X9K27G60000G2002000
S28837986A9K27G60000G2B002000QQQQ  0000495000Y
S28837987A9K27G60000KZB005000QQQQ  0000495200Y
S28837988A9K27G60000L0B005000QQQQ  0000495200Y
S28838002X9K27G60000EU002000
S28838002A9K27G60000EUB002000QQQQ  0000495300Y
S28838066X9K27G60000KY005000
S28838066X9K27G60000KZ005000
S28838066X9K27G60000L0005000
S28838066A9K27G60000L1B005000QQQQ  0000495600Y
S28838066A9K27G60000L2B005000QQQQ  0000495600Y
S28838067X9K27G60000EU002000
S28838067A9K27G60000EUB002000QQQQ  0000495600Y
S28838067X9K27G60000G2002000
S28838067A9K27G60000G2B002000QQQQ  0000495500Y
S28838067A9K27G60000L3S005000QQQQ  0000496100Y
S28838073X9K27G60000EN002000
S28838073A9K27G60000ENS002000QQQQ  0000496000Y
S28838189XAK27GA0000K1001000
S28838189AAK27GA0000K1S001000SPY   0001425500Y
S28838189X4K27GA00008B000200
S28838189XAK27GA0000EW000500
S28838189AAK27GA0000EWS000500SPY   0001425500Y
S28838189XAK27GA0000O6000500
S28838189AAK27GA0000O6S000500SPY   0001425600Y
S28838189XAK27GA0000FE000500
S28838189AAK27GA0000FEB000500SPY   0001424900Y
S28838189XAK27GA0000P9001000
S28838189XAK27GA0000PE000600
S28838189AAK27GA0000PGB000600SPY   0001425000Y
S28838190XAK27GA0000E4001000
S28838190AAK27GA0000E4B001000SPY   0001425000Y
S28838190AAK27GA0000PHS001000SDS   0000549300Y
S28838191XBK27GA0000DU001000
S28838191AAK27GA0000PIS001000SPY   0001425500Y
S28838191ABK27GA0000DYB001000SSO   0000763800Y
S28838191XAK27GA0000EX000500
S28838191AAK27GA0000EXB000500SPY   0001425000Y
S28838193ABK27GA0000DZB001000SSO   0000763600Y
S28838193XBK27GA0000DT001000
S28838193A4K27GA00008HS000200DIA   0001298700Y
S28838194X3K27G600003J000100
S28838194X4K27GA00008C000100
S28838194A3K27G600003LB000100DDM   0000800600Y
S28838194A4K27GA00008IS000100DXD   0000500500Y
S28838201XAK27GA0000FD000500
S28838201AAK27GA0000FDB000500SPY   0001425000Y
S28838201XAK27GA0000P5003000
S28838201XAK27GA0000P6003000
S28838201XAK27GA0000PA003000
S28838201XAK27GA0000O8000500
S28838201AAK27GA0000O8S000500SPY   0001425700Y
S28838202XAK27GA0000E5001000
S28838202AAK27GA0000E5S001000SPY   0001425600Y
S28838202XAK27GA0000O5000500
S28838202AAK27GA0000O5S000500SPY   0001425600Y
S28838202XAK27GA0000OG002000
S28838202AAK27GA0000PJB002000SPY   0001425000Y
S28838202XAK27GA0000PC003000
S28838202AAK27GA0000PKB003000SPY   0001424900Y
S28838202AAK27GA0000PLB003000SPY   0001424900Y
S28838202AAK27GA0000PMB002000SPY   0001424800Y
S28838203AAK27GA0000PNS003000SPY   0001425800Y
S28838203X4K27GA00003H000200
S28838203A4K27GA00003HB000200DIA   0001298300Y
S28838204AAK27GA0000POS003000SPY   0001425800Y
S28838205XAK27GA0000E5001000
S28838205AAK27GA0000E5S001000SPY   0001425200Y
S28838204A6K27GA000053B002000IWM   0000736100Y
S28838206XAK27GA0000O8000500
S28838206AAK27GA0000O8S000500SPY   0001425300Y
S28838207XAK27GA0000O5000500
S28838207AAK27GA0000O5S000500SPY   0001425200Y
S28838214X4K27GA000088000047
S28838217X9K27G60000KQ005000
S28838217A4K27GA00008JS000047DIA   0001298800Y
S28838219A9K27G60000L4S005000QQQQ  0000496100Y
S28838223X9K27G60000L4005000
S28838223X9K27G60000L3005000
S28838223A9K27G60000L5S005000QQQQ  0000495700Y
S28838223A9K27G60000L6S005000QQQQ  0000495700Y
S28838224XAK27GA0000P7001000
S28838225XAK27GA0000EX000500
S28838225AAK27GA0000EXB000500SPY   0001424600Y
S28838224X6K27GA00002B000500
S28838224A6K27GA00002BS000500IWM   0000736800Y
S28838232X9K27G60000EN002000
S28838232A9K27G60000ENS002000QQQQ  0000495700Y
S28838238XBK27GA0000DV000100
S28838238XBK27GA0000DW000100
S28838238XBK27GA0000DX000100
S28838239A6K27GA000054S000100IWM   0000736900Y
S28838241X9K27G60000IR002000
S28838243X4K27GA00008A000100
S28838243X4K27GA000089000100
S28838244X3K27G600003I000100
S28838244X4K27GA00007C000200
S28838244A4K27GA00007CB000200DIA   0001298400Y
S28838243X6K27GA00004T000500
S28838243A6K27GA00004TB000500IWM   0000736300Y
S28838245XAK27GA0000P7001000
S28838244X6K27GA000054000100
S28838246ABK27GA0000E0B000100UWM   0000542100Y
S28838246XBK27GA0000DR000100
S28838246ABK27GA0000E1S000100TWM   0000702400Y
S28838246A4K27GA00008KS000100DXD   0000500400Y
S28838246A4K27GA00008LS000100DOG   0000598500Y
S28838246A3K27G600003MB000100DDM   0000800700Y
S28838246A3K27G600003NS000100DDM   0000802200Y
S28838249X4K27GA00007C000200
S28838249A4K27GA00007CB000200DIA   0001298100Y
S28838250X4K27GA00008L000100
S28838251X3K27G600003M000100
S28838250X4K27GA00008K000100
S28838254A4K27GA00008MS000100DOG   0000598500Y
S28838254A4K27GA00008NS000100DXD   0000500400Y
S28838254A3K27G600003OB000100DDM   0000800700Y
S28838268A9K27G60000L7S002000QQQQ  0000495800Y
S28838271A8K27G600001LS000500MZZ   0000494200Y
S28838271A8K27G600001MB000100MVV   0000805800Y
S28838293XAK27GA0000P1001000
S28838294X8K27G600001H000500
S28838294X8K27G600001G000100
S28838294X8K27G600001I000100
S28838294AAK27GA0000PPS001000SPY   0001425500Y
S28838296A8K27G600001NS000100MVV   0000809200Y
S28838316A8K27G600001OS000100MVV   0000809100Y
S28838330XAK27GA0000EX000500
S28838330AAK27GA0000EXB000500SPY   0001425000Y
S28838330XAK27GA0000OH001000
S28838332AAK27GA0000PQS001000SPY   0001425600Y
S28838344XBK27GA0000DS001000
S28838343XAK27GA0000P8001000
S28838344X4K27GA00007C000200
S28838344A4K27GA00007CB000200DIA   0001298400Y
S28838345XAK27GA0000P3001000
S28838345AAK27GA0000PRB001000SDS   0000547900Y
S28838346ABK27GA0000E2S001000SSO   0000764800Y
S28838347AAK27GA0000PSB001000SDS   0000547800Y
S28838355XAK27GA0000PD001000
S28838359X4K27GA00007C000200
S28838359A4K27GA00007CB000200DIA   0001298100Y
S28838394X4K27GA000043002000
S28838397AAK27GA0000PTB002000SHLD  0000681400Y
S28838397X7K27GA00001Y002000
S28838400X2K27G600002J002000
S28838404X7K27GA00001T002000
S28838416X4K27GA000046002000
S28838420A3K27G600003PB002000CTSH  0000023800Y
S28838422X1K27GA00003Q002000
S28838429X9K27G60000L7002000
S28838433X2K27G600001A002000
S28838432X7K27GA00001Z002000
S28838440X2K27G600002L002000
S28838443X6K27GA000043002000
S28838450X3K27G600003H002000
S28838452X9K27G60000EN002000
S28838452A9K27G60000ENS002000QQQQ  0000496000Y
S28838462X5K27GA00002D002000
S28838469X5K27GA00002E002000
S28838467XCK27GA000028002000
S28838489AAK27GA0000PUB002000SNDK  0000219900Y
S28838489ABK27GA0000E3B002000UTX   0000069100Y
S28838499X9K27G60000IY002000
S28838499X9K27G60000L5005000
S28838499X9K27G60000F9003200
S28838499A9K27G60000F9B003200QQQQ  0000495600Y
S28838499X9K27G60000L6005000
S28838500A9K27G60000L8B002000QQQQ  0000495400Y
S28838501A9K27G60000L9S005000QQQQ  0000496100Y
S28838502A9K27G60000LAS005000QQQQ  0000496100Y
S28838505XAK27GA0000PP001000
S28838507AAK27GA0000PVS001000SPY   0001425600Y
S28838527X9K27G60000F9003200
S28838527A9K27G60000F9B003200QQQQ  0000495100Y
S28838528X9K27G60000L8002000
S28838532X9K27G60000F9003200
S28838532A9K27G60000F9B003200QQQQ  0000495600Y
S28838533A9K27G60000LBB002000QQQQ  0000495400Y
S28838540X1K27GA00003R002000
S28838552ABK27GA0000E4B002000UTX   0000068300Y
S28838558A1K27GA00003SB002000ABT   0000050700Y
S28838565A9K27G60000LCB002000QQQQ  0000495400Y
S28838565ACK27GA000029B002000WYE   0000037400Y
S28838586A2K27G600002OB002000AXP   0000399500Y
S28838588XAK27GA0000OP001000
S28838589AAK27GA0000PWB000600SPY   0001425100Y
S28838590AAK27GA0000PXS000100SH    0000619100Y
S28838591ABK27GA0000E5B001000SSO   0000763900Y
S28838591XBK27GA0000DY001000
S28838593XBK27GA0000DZ001000
S28838593ABK27GA0000E6B001000SSO   0000763700Y
S28838600A2K27G600002PB002000BK    0000425200Y
S28838610X2K27G600001G002000
S28838618A2K27G600002QB002000CAG   0000016400Y
S28838626X4K27GA00008D002000
S28838628A1K27GA00003TB002000ABT   0000049900Y
S28838642X9K27G60000LC002000
S28838647X5K27GA00002G002000
S28838653X5K27GA00002H002000
S28838658A2K27G600002RB002000AXP   0000398700Y
S28838667A3K27G600003QB002000CVS   0000037100Y
S28838673A2K27G600002SB002000BBT   0000027300Y
S28838707A3K27G600003RB002000COH   0000029000Y
S28838710A5K27GA00002IB002000HUM   0000432300Y
S28838731A4K27GA00008OB002000EIX   0000042200Y
S28838740A9K27G60000LDB002000QQQQ  0000495400Y
S28838888AAK27GA0000PYB000100SPY   0001424400Y
S28838888XAK27GA0000NO000100
S28838925X9K27G60000LD002000
S28839083A9K27G60000LEB002000QQQQ  0000495400Y
S28839084XAK27GA0000PJ002000
S28839084XAK27GA0000FD000500
S28839084AAK27GA0000FDB000500SPY   0001424600Y
S28839084XAK27GA0000EX000500
S28839084AAK27GA0000EXB000500SPY   0001424600Y
S28839084XAK27GA0000O6000500
S28839084AAK27GA0000O6S000500SPY   0001425200Y
S28839093X4K27GA00008M000100
S28839093X4K27GA00008N000100
S28839094X3K27G600003O000100
S28839094XBK27GA0000E6001000
S28839176X9K27G60000LE002000
S28839184X4K27GA00008J000047
S28839188X9K27G60000F9003200
S28839188A9K27G60000F9B003200QQQQ  0000495100Y
S28839189X9K27G60000LB002000
S28839193A4K27GA00008PS000047DIA   0001298500Y
S28839195A4K27GA00008QB000100DXD   0000499700Y
S28839364X6K27GA00004U002000
S28839368A2K27G600002TB002000BMY   0000015500Y
S28839389A4K27GA00008RB002000EMR   0000552100Y
S28839405XAK27GA0000PT002000
S28839439XBK27GA0000E3002000
S28839439X9K27G60000IS002000
S28839453A7K27GA000020B002000LMT   0000110300Y
S28839483A7K27GA000021B002000LPNT  0000187800Y
S28839494A4K27GA00008SB002000EMR   0000552900Y
S28839496XBK27GA0000E4002000
S28839503XCK27GA000029002000
S28839518X1K27GA00003S002000
S28839536X1K27GA00003T002000
S28839542A7K27GA000022B002000LMT   0000111100Y
S28839561A1K27GA00003UB002000AFL   0000064500Y
S28839564X2K27G600000Q002000
S28839581X2K27G600002N002000
S28839584X2K27G600000T002000
S28839592A2K27G600002UB002000BK    0000424400Y
S28839598X2K27G6000021002000
S28839603A2K27G600002VB002000CAG   0000016300Y
S28839612A3K27G600003SB002000CVS   0000037500Y
S28839619X4K27GA00008O002000
S28839626X4K27GA00006O002000
S28839633A5K27GA00002JB002000HNZ   0000040100Y
S28839653A5K27GA00002KB002000HOT   0000041000Y
S28839663X2K27G6000020002000
S28839678ACK27GA00002AB002000WYE   0000039400Y
S28839702X3K27G600003K002000
S28839709A6K27GA000055B002000ITW   0000503400Y
S28839715X3K27G600003Q002000
S28839732A1K27GA00003VB002000AFL   0000065300Y
S28839741X4K27GA00006M002000
S28839748A2K27G600002WB002000CAT   0000815800Y
S28839764A4K27GA00008TB002000EIX   0000044400Y
S28839775A5K27GA00002LB002000HNZ   0000040900Y
S28839785A5K27GA00002MB002000HOT   0000041800Y
S28840160XAK27GA0000PQ001000
S28840160AAK27GA0000PZS001000SPY   0001425200Y
S28840161XAK27GA0000FD000500
S28840161AAK27GA0000FDB000500SPY   0001425000Y
S28840161XAK27GA0000O6000500
S28840161AAK27GA0000O6S000500SPY   0001425600Y
S28840161XAK27GA0000EX000500
S28840161AAK27GA0000EXB000500SPY   0001425000Y
S28840162XAK27GA0000PZ001000
S28840163ABK27GA0000E7B001000SSO   0000763700Y
S28840163AAK27GA0000Q0S001000SPY   0001425600Y
S28840172X4K27GA00008P000047
S28840173A4K27GA00008US000047DIA   0001298800Y
S28840174A4K27GA00008VS000100DOG   0000598500Y
S28840174A4K27GA00008WS000100DXD   0000500400Y
S28840174X4K27GA00008Q000100
S28840176A3K27G600003TB000100DDM   0000800700Y
S28840176X6K27GA000026000500
S28840176A6K27GA000026S000500IWM   0000736900Y
S28840176A6K27GA000056B002000IWM   0000736200Y
S28840180X6K27GA00003H000500
S28840180A6K27GA00003HB000500IWM   0000736400Y
S28840183ABK27GA0000E8B000100UWM   0000542300Y
S28840183ABK27GA0000E9S000100TWM   0000702200Y
S28840183XBK27GA0000E1000100
S28840184X6K27GA00003H000500
S28840184A6K27GA00003HB000500IWM   0000736000Y
S28840188XBK27GA0000E8000100
S28840188XBK27GA0000E9000100
S28840188XBK27GA00008X000100
S28840188XBK27GA00008Y000100
S28840188XBK27GA00008Z000100
S28840187X6K27GA00003H000500
S28840187A6K27GA00003HB000500IWM   0000736400Y
S28840190ABK27GA0000EAB000100UWM   0000542300Y
S28840190ABK27GA0000EBS000100TWM   0000702200Y
S28840188A6K27GA000057B000100IWM   0000735900Y
S28840188A6K27GA000058S000100IWM   0000737000Y
S28840191X8K27G600001L000500
S28840191X8K27G600001M000100
S28840189X6K27GA000057000100
S28840190X6K27GA00003H000500
S28840190A6K27GA00003HB000500IWM   0000736000Y
S28840193A8K27G600001PS000500MZZ   0000494200Y
S28840193A8K27G600001QB000100MVV   0000805700Y
S28840194X6K27GA000058000100
S28840195X6K27GA00003H000500
S28840195A6K27GA00003HB000500IWM   0000736400Y
S28840196AAK27GA0000Q1B002000SPY   0001425100Y
S28840196XAK27GA0000M6001000
S28840197XAK27GA0000PB001000
S28840197XAK27GA0000E5001000
S28840197AAK27GA0000E5S001000SPY   0001425600Y
S28840197XAK27GA0000LN003000
S28840197XAK27GA0000LD003000
S28840198X9K27G60000G0002000
S28840198A9K27G60000G0B002000QQQQ  0000495600Y
S28840198X9K27G60000G9002000
S28840198A9K27G60000G9S002000QQQQ  0000496200Y
S28840197XAK27GA0000FG000500
S28840197AAK27GA0000FGB000500SPY   0001425100Y
S28840197AAK27GA0000Q2B002000SPY   0001425100Y
S28840198XAK27GA0000O5000500
S28840198XAK27GA0000O8000500
S28840198AAK27GA0000O8S000500SPY   0001425700Y
S28840198X4K27GA00007C000200
S28840198A4K27GA00007CB000200DIA   0001298500Y
S28840198X4K27GA00006X000200
S28840198X4K27GA00008H000200
S28840198XAK27GA0000O1000500
S28840198XAK27GA0000NY000500
S28840198AAK27GA0000NYS000500SPY   0001425800Y
S28840198XAK27GA0000E6001000
S28840198AAK27GA0000E6S001000SPY   0001425700Y
S28840198XAK27GA0000EB001000
S28840198AAK27GA0000EBB001000SPY   0001425100Y
S28840198XAK27GA0000LT001000
S28840198XAK27GA0000LE003000
S28840198XAK27GA0000NZ000500
S28840198AAK27GA0000NZS000500SPY   0001425700Y
S28840198XAK27GA0000F7000500
S28840198AAK27GA0000F7B000500SPY   0001425100Y
S28840198XAK27GA0000LM003000
S28840198AAK27GA0000Q3B003000SPY   0001425100Y
S28840198XAK27GA0000J2002000
S28840197X6K27GA00003H000500
S28840197A6K27GA00003HB000500IWM   0000736000Y
S28840198X4K27GA00008U000047
S28840198X4K27GA000062000200
S28840198A4K27GA000062B000200DIA   0001298400Y
S28840199X9K27G60000IP001000
S28840199A9K27G60000LFB002000QQQQ  0000495400Y
S28840199X9K27G60000F9003200
S28840199A9K27G60000F9B003200QQQQ  0000495600Y
S28840199X4K27GA00007D000100
S28840199A4K27GA00008XS000100DXD   0000500300Y
S28840199A3K27G600003UB000100DDM   0000800800Y
S28840199AAK27GA0000Q4S003000SPY   0001426000Y
S28840199AAK27GA0000Q5B003000SPY   0001425100Y
S28840199AAK27GA0000Q6B002000SPY   0001425100Y
S28840200X9K27G60000IO001000
S28840200AAK27GA0000Q7S001000SPY   0001425700Y
S28840200AAK27GA0000Q8S000500SPY   0001425600Y
S28840200A4K27GA00008YS000200DIA   0001298900Y
S28840200XBK27GA0000E2001000
S28840199X6K27GA00003H000500
S28840199A6K27GA00003HB000500IWM   0000736400Y
S28840200XAK27GA0000F5000500
S28840200AAK27GA0000F5B000500SPY   0001425100Y
S28840200AAK27GA0000Q9S003000SPY   0001426000Y
S28840200XAK27GA0000LG001000
S28840201XBK27GA0000EA000100
S28840200XAK27GA0000FI000500
S28840200AAK27GA0000FIB000500SPY   0001425100Y
S28840201XBK27GA0000EB000100
S28840201AAK27GA0000QAS001000SDS   0000549200Y
S28840201A9K27G60000LGS001000QQQQ  0000496100Y
S28840201A9K27G60000LHS001000QQQQ  0000496000Y
S28840201XBK27GA0000E5001000
S28840201ABK27GA0000ECB001000SSO   0000764000Y
S28840201AAK27GA0000QBS000500SPY   0001425800Y
S28840202AAK27GA0000QCS001000SPY   0001425800Y
S28840202ABK27GA0000EDS001000SSO   0000764900Y
S28840202XAK27GA0000E8001000
S28840202AAK27GA0000E8B001000SPY   0001425100Y
S28840202XAK27GA0000LU000900
S28840202AAK27GA0000QDB000200SPY   0001425100Y
S28840203ABK27GA0000EEB000100UWM   0000542300Y
S28840201A6K27GA000059B000100IWM   0000735900Y
S28840203ABK27GA0000EFS000100TWM   0000702200Y
S28840201X6K27GA000059000100
S28840203ABK27GA0000EGB001000SSO   0000763800Y
S28840203XBK27GA0000E7001000
S28840203A4K27GA00008ZS000200DIA   0001299000Y
S28840202X6K27GA00003H000500
S28840202A6K27GA00003HB000500IWM   0000736000Y
S28840204XAK27GA0000OI000100
S28840204XAK27GA0000PR001000
S28840204X3K27G600003N000100
S28840204X4K27GA00006R000100
S28840204XAK27GA0000E9001000
S28840204AAK27GA0000E9S001000SPY   0001425800Y
S28840205XAK27GA0000LK000900
S28840205AAK27GA0000QES000100SH    0000619000Y
S28840206XBK27GA0000EC001000
S28840205AAK27GA0000QFS001000SDS   0000549100Y
S28840204X6K27GA00003H000500
S28840204A6K27GA00003HB000500IWM   0000736400Y
S28840206ABK27GA0000EHB001000SSO   0000764100Y
S28840206XAK27GA0000E7001000
S28840206AAK27GA0000E7B001000SPY   0001425100Y
S28840206XBK27GA0000EF000100
S28840206XBK27GA0000EE000100
S28840206AAK27GA0000QGB000200SPY   0001425100Y
S28840206A4K27GA000090S000047DIA   0001299100Y
S28840206A4K27GA000091B000100DXD   0000499300Y
S28840208ABK27GA0000EIS000100TWM   0000702200Y
S28840206X6K27GA00003H000500
S28840206A6K27GA00003HB000500IWM   0000736000Y
S28840208ABK27GA0000EJB000100UWM   0000542300Y
S28840207A6K27GA00005AB000100IWM   0000735900Y
S28840207X6K27GA00005A000100
S28840209X9K27G60000LG001000
S28840209X9K27G60000LH001000
S28840228XBK27GA0000EJ000100
S28840228XBK27GA0000EI000100
S28840230A9K27G60000LIB002000QQQQ  0000495400Y
S28840230ABK27GA0000EKB000100UWM   0000542300Y
S28840230ABK27GA0000ELS000100TWM   0000702200Y
S28840229X6K27GA000042002000
S28840230X6K27GA000028000500
S28840230A6K27GA000028S000500IWM   0000737000Y
S28840232A8K27G600001RS000500MZZ   0000494100Y
S28840232A8K27G600001SB000100MVV   0000805900Y
S28840232X8K27G600001F000500
S28840232X8K27G600001O000100
S28840232X8K27G600001N000100
S28840232X6K27GA000028000500
S28840232A6K27GA000028S000500IWM   0000736600Y
S28840234A8K27G600001TB000500MZZ   0000491600Y
S28840234A8K27G600001US000100MVV   0000809300Y
S28840234XBK27GA0000ED001000
S28840234XAK27GA0000QC001000
S28840234A9K27G60000LJS001000QID   0000382100Y
S28840234A9K27G60000LKB001000QLD   0000888800Y
S28840234X9K27G60000KK001000
S28840234X4K27GA000065000100
S28840234X4K27GA00008Y000200
S28840235X3K27G600002A000100
S28840235AAK27GA0000QHS001000SPY   0001425400Y
S28840236ABK27GA0000EMS001000SSO   0000765000Y
S28840237A3K27G600003VS000100DDM   0000802500Y
S28840237A9K27G60000LLB001000QQQQ  0000495200Y
S28840238XAK27GA0000PV001000
S28840238XBK27GA0000EK000100
S28840238XBK27GA0000EL000100
S28840239X9K27G60000LL001000
S28840239A4K27GA000092S000200DIA   0001298900Y
S28840240ABK27GA0000ENB000100UWM   0000542300Y
S28840240ABK27GA0000EOS000100TWM   0000702200Y
S28840243A9K27G60000LMB001000QLD   0000888900Y
S28840243X9K27G60000LK001000
S28840244X3K27G600003V000100
S28840244A9K27G60000LNS000100QID   0000382300Y
S28840244X4K27GA000063000100
S28840245A9K27G60000LOB001000QQQQ  0000495200Y
S28840245XAK27GA0000PS001000
S28840244A6K27GA00005BB002000IWM   0000736300Y
S28840244X6K27GA000047002000
S28840245A4K27GA000093B000100DXD   0000499200Y
S28840246A3K27G600003WS000100DDM   0000802600Y
S28840249X9K27G60000LO001000
S28840250X4K27GA00003H000200
S28840250A4K27GA00003HB000200DIA   0001298600Y
S28840252A4K27GA000094S000100DOG   0000598400Y
S28840252A4K27GA000095S000100DXD   0000500200Y
S28840252X4K27GA000077000100
S28840253A3K27G600003XB000100DDM   0000801000Y
S28840253X3K27G600002T000100
S28840258XAK27GA0000Q3003000
S28840258AAK27GA0000Q3B003000SPY   0001425200Y
S28840258XAK27GA0000Q5003000
S28840258AAK27GA0000Q5B003000SPY   0001425200Y
S28840258XAK27GA0000Q6002000
S28840258AAK27GA0000Q6B002000SPY   0001425200Y
S28840258XAK27GA0000F5000500
S28840258AAK27GA0000F5B000500SPY   0001425200Y
S28840258XAK27GA0000FI000500
S28840258AAK27GA0000FIB000500SPY   0001425200Y
S28840258XAK27GA0000E8001000
S28840258AAK27GA0000E8B001000SPY   0001425200Y
S28840258XAK27GA0000QD000200
S28840258AAK27GA0000QDB000200SPY   0001425200Y
S28840258XAK27GA0000E7001000
S28840258AAK27GA0000E7B001000SPY   0001425200Y
S28840258XAK27GA0000QG000200
S28840258AAK27GA0000QGB000200SPY   0001425200Y
S28840258X6K27GA000028000500
S28840258A6K27GA000028S000500IWM   0000737000Y
S28840284XAK27GA0000OC001000
S28840284AAK27GA0000QIS001000SPY   0001425700Y
S28840285XBK27GA0000EG001000
S28840286X8K27G600001U000100
S28840285ABK27GA0000EPB001000SSO   0000763900Y
S28840286AAK27GA0000QJS001000SPY   0001425700Y
S28840288A8K27G600001VS000100MVV   0000809400Y
S28840293ABK27GA0000EQB000100TWM   0000701000Y
S28840300A8K27G600001WS000500MZZ   0000494000Y
S28840300A8K27G600001XB000100MVV   0000806100Y
S28840308XBK27GA00009Z000100
S28840308ABK27GA0000ERB000100UWM   0000542400Y
S28840308ABK27GA0000ESS000100TWM   0000702000Y
S28840308XBK27GA0000EO000100
S28840324X9K27G60000J8002000
S28840324X9K27G60000F4003200
S28840324A9K27G60000F4S003200QQQQ  0000496300Y
S28840324X9K27G60000IH005000
S28840324X9K27G60000IG005000
S28840324A9K27G60000LPB005000QQQQ  0000495700Y
S28840324A9K27G60000LQB005000QQQQ  0000495700Y
S28840325A9K27G60000LRB002000QQQQ  0000495700Y
S28840325X9K27G60000EP002000
S28840325A9K27G60000EPB002000QQQQ  0000495700Y
S28840325A9K27G60000LSB001000QLD   0000888800Y
S28840331XAK27GA0000QJ001000
S28840359X3K27G6000036002000
S28840363XAK27GA0000QI001000
S28840363AAK27GA0000QKS001000SPY   0001425800Y
S28840365AAK27GA0000QLS001000SPY   0001425800Y
S28840377X4K27GA000062000200
S28840377A4K27GA000062B000200DIA   0001298700Y
S28840379A3K27G600003YB000100DDM   0000801100Y
S28840379X3K27G600003L000100
S28840379XAK27GA0000NQ000100
S28840379AAK27GA0000QMB001000SDS   0000547500Y
S28840379AAK27GA0000QNB001000SDS   0000547600Y
S28840379AAK27GA0000QOB001000SDS   0000547700Y
S28840381AAK27GA0000QPS000100SPY   0001426900Y
S28840389A6K27GA00005CB002000IMCL  0000321400Y
S28840395X5K27GA00001I002000
S28840421XAK27GA0000OF002000
S28840424X7K27GA000022002000
S28840424X7K27GA000020002000
S28840435XCK27GA00002A002000
S28840437X9K27G60000LP005000
S28840437X9K27G60000LQ005000
S28840442A9K27G60000LTB005000QQQQ  0000495300Y
S28840442A9K27G60000LUB005000QQQQ  0000495300Y
S28840449X9K27G60000F4003200
S28840449A9K27G60000F4S003200QQQQ  0000495800Y
S28840449X9K27G60000EP002000
S28840449A9K27G60000EPB002000QQQQ  0000495400Y
S28840458X9K27G60000LR002000
S28840460X9K27G60000LS001000
S28840462A9K27G60000LVB001000QQQQ  0000495200Y
S28840467X1K27GA00003V002000
S28840467AAK27GA0000QQB002000SHLD  0000686500Y
S28840469X9K27G60000LV001000
S28840481ABK27GA0000ETB002000UTX   0000072300Y
S28840489ABK27GA0000EUB002000UTX   0000073100Y
S28840499A9K27G60000LWB002000PDLI  0000015000Y
S28840507X1K27GA00003U002000
S28840524X9K27G60000LT005000
S28840524X9K27G60000F4003200
S28840524A9K27G60000F4S003200QQQQ  0000496300Y
S28840524X9K27G60000LU005000
S28840524A9K27G60000LXB002000QQQQ  0000495700Y
S28840525A9K27G60000LYB005000QQQQ  0000495700Y
S28840525A9K27G60000LZB005000QQQQ  0000495700Y
S28840526A9K27G60000M0B001000QLD   0000888800Y
S28840526X9K27G60000EP002000
S28840526A9K27G60000EPB002000QQQQ  0000495700Y
S28840542ACK27GA00002BB002000WYE   0000039800Y
S28840546A1K27GA00003WB002000ABT   0000053800Y
S28840548XBK27GA000074000100
S28840548XBK27GA000075000100
S28840546A6K27GA00005DS002000IWM   0000737000Y
S28840548A6K27GA00005ES000100IWM   0000737100Y
S28840550ABK27GA0000EVB000100TWM   0000700900Y
S28840549X6K27GA00003H000500
S28840549A6K27GA00005FB000500IWM   0000736500Y
S28840554X6K27GA00005E000100
S28840555X6K27GA000027000500
S28840555A6K27GA000027B000500IWM   0000736400Y
S28840574X2K27G600002S002000
S28840574A1K27GA00003XB002000ABT   0000053000Y
S28840578A2K27G600002XB002000AZN   0000417500Y
S28840584A9K27G60000M1B002000QQQQ  0000495500Y
S28840584X9K27G60000JC002000
S28840584X9K27G60000JD002000
S28840597X2K27G600002Q002000
S28840602A2K27G600002YB002000BBT   0000030000Y
S28840614A2K27G600002ZB002000BNI   0001058500Y
S28840624E4K27GA00006Q000009000N4AQ00004
S28840629X4K27GA00008T002000
S28840642X4K27GA00008G000100
S28840647X2K27G600001M002000
S28840648A4K27GA000096B000100DRYS  0001068000Y
S28840653A3K27G600003ZB002000COH   0000031800Y
S28840654X3K27G600003R002000
S28840668X4K27GA00006Q000091
S28840669X3K27G600003S002000
S28840679X5K27GA00002L002000
S28840693A2K27G6000030B002000AZN   0000416700Y
S28840693X5K27GA00002M002000
S28840703A3K27G6000040B002000CVS   0000039500Y
S28840708A2K27G6000031B002000BNI   0001057700Y
S28840714X5K27GA00002J002000
S28840725X5K27GA00002K002000
S28840726A4K27GA000097B002000EIX   0000045000Y
S28840726A4K27GA000098B002000FCX   0001224300Y
S28840754A4K27GA000099B002000FCX   0001223500Y
S28840773A6K27GA00005GB002000IWN   0000663500Y
S28840932X9K27G60000EQ002000
S28840932A9K27G60000EQS002000QQQQ  0000496100Y
S28841147XAK27GA0000O2000500
S28841147AAK27GA0000O2S000500SPY   0001425900Y
S28841147XAK27GA0000QH001000
S28841147AAK27GA0000QRB002000SPY   0001425300Y
S28841147XAK27GA0000F2000500
S28841147AAK27GA0000F2B000500SPY   0001425300Y
S28841148XAK27GA0000L8001000
S28841149XAK27GA0000LB001000
S28841149XBK27GA0000EM001000
S28841149AAK27GA0000QSS001000SPY   0001425800Y
S28841150XAK27GA0000QM001000
S28841151AAK27GA0000QTB001000SDS   0000547700Y
S28841151ABK27GA0000EWS001000SSO   0000765100Y
S28841152AAK27GA0000QUB001000SDS   0000547500Y
S28841153XAK27GA0000QU001000
S28841153XAK27GA0000LA000100
S28841155AAK27GA0000QVB001000SDS   0000547500Y
S28841155XAK27GA0000QO001000
S28841157AAK27GA0000QWB001000SDS   0000547400Y
S28841161X4K27GA000092000200
S28841163A4K27GA00009AS000200DIA   0001299200Y
S28841163AAK27GA0000QXB001000SPY   0001425200Y
S28841163XAK27GA0000PM002000
S28841165XAK27GA0000KV003000
S28841165XAK27GA0000KW003000
S28841165X9K27G60000G1002000
S28841165A9K27G60000G1S002000QQQQ  0000496300Y
S28841168AAK27GA0000QYS003000SPY   0001426200Y
S28841168AAK27GA0000QZS003000SPY   0001426200Y
S28841195X4K27GA00007C000200
S28841195A4K27GA00007CB000200DIA   0001298800Y
S28841197A4K27GA00009BS000100DOG   0000598300Y
S28841197X4K27GA00006W000100
S28841197A4K27GA00009CS000100DXD   0000500100Y
S28841198X3K27G600003T000100
S28841198A3K27G6000041B000100DDM   0000801200Y
S28841301AAK27GA0000R0S001000SDS   0000549000Y
S28841301XBK27GA0000EH001000
S28841301ABK27GA0000EXB001000SSO   0000764200Y
S28841306X4K27GA00008Z000200
S28841312A4K27GA00009DS000200DIA   0001299300Y
S28841323X9K27G60000I1002000
S28841323X9K27G60000I0005000
S28841323X9K27G60000HY005000
S28841324X9K27G60000GI002000
S28841334A9K27G60000M2S005000QQQQ  0000496200Y
S28841334A9K27G60000M3S005000QQQQ  0000496200Y
S28841359A3K27G6000042B002000CELG  0000467400Y
S28841386X2K27G600002T002000
S28841426XAK27GA0000QQ002000
S28841431XBK27GA0000ET002000
S28841431XBK27GA0000EU002000
S28841440X3K27G600003P002000
S28841449XCK27GA00002B002000
S28841457X1K27GA00003W002000
S28841467X1K27GA00003X002000
S28841468AAK27GA0000R1B002000SPLS  0000016600Y
S28841471X3K27G6000040002000
S28841475XBK27GA0000EP001000
S28841476ABK27GA0000EYB001000SSO   0000764000Y
S28841495A7K27GA000023B002000LMT   0000117100Y
S28841498X2K27G600002V002000
S28841522ACK27GA00002CB002000WYE   0000041800Y
S28841543A5K27GA00002NB002000GM    0000173400Y
S28841552X4K27GA000097002000
S28841562A7K27GA000024B002000LMT   0000116300Y
S28841576A1K27GA00003YB002000AFL   0000069100Y
S28841588A1K27GA00003ZB002000AFL   0000068300Y
S28841601A2K27G6000032B002000BBT   0000030100Y
S28841609A2K27G6000033B002000CAG   0000018400Y
S28841633A2K27G6000034B002000CAT   0000815100Y
S28841639A4K27GA00009EB002000EIX   0000047200Y
S28841648A3K27G6000043B002000COH   0000032000Y
S28841661A3K27G6000044B002000CVS   0000039900Y
S28841667A5K27GA00002OB002000HNZ   0000043500Y
S28841678A5K27GA00002PB002000HNZ   0000042700Y
S28841691A5K27GA00002QB002000HOT   0000043600Y
S28841691A5K27GA00002RB002000HOT   0000044400Y
S28841707A6K27GA00005HB002000JBL   0000103100Y
S28841710A6K27GA00005IB002000IP    0000260800Y
S28841741X4K27GA000096000100
S28841741X4K27GA00008E000100
S28842061XAK27GA0000FE000500
S28842061AAK27GA0000FEB000500SPY   0001425300Y
S28842088A4K27GA00009FB000100DRYS  0001068800Y
S28842088A4K27GA00009GB000100DRYS  0001068800Y
S28842132X9K27G60000M1002000
S28842386X6K27GA00005C002000
S28842391X7K27GA000024002000
S28842414X1K27GA00003Z002000
S28842414AAK27GA0000R2B002000SHLD  0000691600Y
S28842417X5K27GA00001J002000
S28842428X2K27G600002K002000
S28842441X3K27G6000044002000
S28842445X5K27GA00002P002000
S28842445X5K27GA00002Q002000
S28842456X7K27GA000023002000
S28842466XCK27GA00002C002000
S28842469A3K27G6000045B002000CTSH  0000027300Y
S28842476X1K27GA00003Y002000
S28842482ABK27GA0000EZB002000UTX   0000076300Y
S28842485X2K27G600002Y002000
S28842503X2K27G600002M002000
S28842523X3K27G600003Z002000
S28842523ACK27GA00002DB002000WYE   0000042200Y
S28842529X4K27GA00009E002000
S28842531XAK27GA0000K1001000
S28842531AAK27GA0000K1S001000SPY   0001425900Y
S28842535X5K27GA00002O002000
S28842560X5K27GA00002R002000
S28842560A1K27GA000040B002000ABT   0000056000Y
S28842561A2K27G6000035B002000BMY   0000017400Y
S28842569XAK27GA0000E4001000
S28842569AAK27GA0000E4B001000SPY   0001425400Y
S28842570XAK27GA0000EW000500
S28842570AAK27GA0000EWS000500SPY   0001425900Y
S28842574X9K27G60000G8002000
S28842574A9K27G60000G8B002000QQQQ  0000495700Y
S28842574XAK27GA0000Q2002000
S28842574AAK27GA0000Q2B002000SPY   0001425400Y
S28842574XAK27GA0000EX000500
S28842574AAK27GA0000EXB000500SPY   0001425400Y
S28842574XAK27GA0000O6000500
S28842574AAK27GA0000O6S000500SPY   0001426000Y
S28842574XAK27GA0000PI001000
S28842574XAK27GA0000PG000600
S28842574XAK27GA0000Q8000500
S28842574AAK27GA0000Q8S000500SPY   0001426000Y
S28842574AAK27GA0000R3B001000SPY   0001425400Y
S28842574XAK27GA0000PO003000
S28842574XAK27GA0000IU003000
S28842574XAK27GA0000FD000500
S28842574AAK27GA0000FDB000500SPY   0001425400Y
S28842574XAK27GA0000E5001000
S28842574AAK27GA0000E5S001000SPY   0001426000Y
S28842575XAK27GA0000IT003000
S28842575XAK27GA0000PN003000
S28842575AAK27GA0000R4B003000SPY   0001425400Y
S28842575XAK27GA0000QL001000
S28842575AAK27GA0000R5B003000SPY   0001425400Y
S28842575XAK27GA0000QK001000
S28842575AAK27GA0000R6B002000SPY   0001425300Y
S28842575XAK27GA0000Q1001000
S28842576AAK27GA0000R7S001000SPY   0001425900Y
S28842576AAK27GA0000R8S003000SPY   0001426400Y
S28842576AAK27GA0000R9S003000SPY   0001426400Y
S28842577AAK27GA0000RAS001000SPY   0001425900Y
S28842577AAK27GA0000RBS001000SPY   0001425900Y
S28842584XBK27GA0000EW001000
S28842584XAK27GA0000IW001000
S28842585ABK27GA0000F0B002000UTX   0000077100Y
S28842585XAK27GA0000QW001000
S28842586ABK27GA0000F1S001000SSO   0000765200Y
S28842586XAK27GA0000QV001000
S28842586A6K27GA00005JB002000IWM   0000736400Y
S28842586X6K27GA00002O002000
S28842588AAK27GA0000RCB001000SDS   0000547500Y
S28842588AAK27GA0000RDB001000SDS   0000547400Y
S28842593X9K27G60000F7003200
S28842593A9K27G60000F7B003200QQQQ  0000495700Y
S28842594A9K27G60000M4B004000QQQQ  0000495500Y
S28842595XAK27GA0000QN001000
S28842602A1K27GA000041B002000ABT   0000056900Y
S28842605A2K27G6000036B002000CAG   0000018200Y
S28842613X4K27GA00004O000100
S28842613X4K27GA00004P000100
S28842614X3K27G600003W000100
S28842616A3K27G6000046S000100DDM   0000802700Y
S28842615A4K27GA00009HB000100DOG   0000596900Y
S28842615A4K27GA00009IB000100DXD   0000499100Y
S28842618X6K27GA00002A000500
S28842618A6K27GA00002AS000500IWM   0000737100Y
S28842621A3K27G6000047B002000CVS   0000041900Y
S28842621A4K27GA00009JB002000EIX   0000047800Y
S28842622XAK27GA0000RA001000
S28842622XAK27GA0000RB001000
S28842621X6K27GA00002C000500
S28842621A6K27GA00002CB000500IWM   0000736600Y
S28842624XBK27GA0000BE000100
S28842623X6K27GA00002W002000
S28842624XAK27GA0000QT001000
S28842624ABK27GA0000F2B000100UWM   0000542500Y
S28842625XBK27GA0000ES000100
S28842625ABK27GA0000F3S000100TWM   0000701800Y
S28842624AAK27GA0000RES001000SPY   0001426000Y
S28842624AAK27GA0000RFS001000SPY   0001426000Y
S28842625X6K27GA00002C000500
S28842625A6K27GA00002CB000500IWM   0000736200Y
S28842626AAK27GA0000RGB001000SDS   0000547600Y
S28842626X6K27GA00002C000500
S28842626A6K27GA00002CB000500IWM   0000736600Y
S28842628XBK27GA00006S000100
S28842628XBK27GA0000EQ000100
S28842628XBK27GA000023000100
S28842627A6K27GA00005KS002000IWM   0000737100Y
S28842630ABK27GA0000F4S000100UWM   0000543500Y
S28842630ABK27GA0000F5B000100TWM   0000700700Y
S28842630ABK27GA0000F6B000100TWM   0000700800Y
S28842631A6K27GA00005LB002000IR    0000432300Y
S28842633AAK27GA0000RHS000100SH    0000618900Y
S28842634ABK27GA0000F7B001000SSO   0000764300Y
S28842634XBK27GA0000EX001000
S28842635X6K27GA00002C000500
S28842635A6K27GA00002CB000500IWM   0000736200Y
S28842637X6K27GA00002C000500
S28842637A6K27GA00002CB000500IWM   0000736600Y
S28842647X6K27GA00002C000500
S28842647A6K27GA00002CB000500IWM   0000736200Y
S28842650A6K27GA00005MB002000IRF   0000217100Y
S28842656A8K27G600001YS000500MZZ   0000493900Y
S28842656X8K27G600001B000100
S28842656A8K27G600001ZB000100MVV   0000806200Y
S28842661A6K27GA00005NB002000JCI   0000032000Y
S28842670X6K27GA00002C000500
S28842670A6K27GA00002CB000500IWM   0000736600Y
S28842674A6K27GA00005OB002000ITW   0000504200Y
S28842693A6K27GA00005PB002000IWN   0000664400Y
S28842706XAK27GA0000R6001000
S28842713XAK27GA0000RH000100
S28842714XBK27GA0000F7001000
S28842715ABK27GA0000F8B001000SSO   0000764200Y
S28842716AAK27GA0000RIB001000SPY   0001425300Y
S28842737X8K27G600001C000500
S28842737A8K27G6000020S000500MZZ   0000493800Y
S28842738A8K27G6000021B000100MVV   0000806300Y
S28842738X8K27G600001Q000100
S28842739X8K27G600001P000500
S28842769X6K27GA00005D002000
S28842774XAK27GA0000PW000600
S28842774XAK27GA0000EB001000
S28842774AAK27GA0000EBB001000SPY   0001425500Y
S28842775AAK27GA0000RJB001000SPY   0001425500Y
S28842776AAK27GA0000RKS000100SH    0000618900Y
S28842776XBK27GA0000F8001000
S28842776ABK27GA0000F9B001000SSO   0000764300Y
S28842778XBK27GA0000EY001000
S28842778ABK27GA0000FAB001000SSO   0000764100Y
S28842781X8K27G600001T000500
S28842781X8K27G600001V000100
S28842782A8K27G6000022B000500MZZ   0000491400Y
S28842783A8K27G6000023S000100MVV   0000809600Y
S28842820A8K27G6000024B000500MZZ   0000491500Y
S28842820A8K27G6000025S000100MVV   0000809500Y
S28842822XAK27GA0000RJ001000
S28842822XAK27GA0000R8003000
S28842822XAK27GA0000R5003000
S28842822XAK27GA0000Q8000500
S28842822AAK27GA0000Q8S000500SPY   0001425600Y
S28842822XAK27GA0000EB001000
S28842822AAK27GA0000EBB001000SPY   0001425100Y
S28842822AAK27GA0000RLS003000SPY   0001425700Y
S28842822XAK27GA0000R9003000
S28842822XAK27GA0000R4003000
S28842822AAK27GA0000RMS003000SPY   0001425700Y
S28842822XAK27GA0000RI001000
S28842823AAK27GA0000RNB001000SPY   0001425100Y
S28842823AAK27GA0000ROB003000SPY   0001424700Y
S28842825AAK27GA0000RPB003000SPY   0001424700Y
S28842832X4K27GA00009D000200
S28842836A4K27GA00009KS000200DIA   0001299000Y
S28842839A6K27GA00005QS002000IWM   0000737000Y
S28842841X9K27G60000M4004000
S28842845XAK27GA0000RM003000
S28842845XAK27GA0000RP003000
S28842846XAK27GA0000RO003000
S28842846XAK27GA0000RL003000
S28842846AAK27GA0000RQB003000SPY   0001425400Y
S28842846AAK27GA0000RRB003000SPY   0001425400Y
S28842847XAK27GA0000Q1001000
S28842848AAK27GA0000RSS003000SPY   0001425800Y
S28842848AAK27GA0000RTS003000SPY   0001425800Y
S28842858X6K27GA00002C000500
S28842858A6K27GA00002CB000500IWM   0000736200Y
S28842862A9K27G60000M5S002000QQQQ  0000496000Y
S28842868XBK27GA0000F2000100
S28842868XBK27GA0000F3000100
S28842870ABK27GA0000FBS000100TWM   0000702000Y
S28842869X6K27GA00002C000500
S28842869A6K27GA00002CB000500IWM   0000736600Y
S28842872ABK27GA0000FCB000100UWM   0000542500Y
S28842872XBK27GA0000FB000100
S28842872ABK27GA0000FDS000100TWM   0000701800Y
S28842876X6K27GA00002C000500
S28842876A6K27GA00002CB000500IWM   0000736200Y
S28842881X8K27G6000022000500
S28842881X8K27G6000024000500
S28842881X8K27G6000023000100
S28842881X8K27G6000025000100
S28842883A8K27G6000026B000500MZZ   0000491400Y
S28842883A8K27G6000027S000100MVV   0000809600Y
S28842885X6K27GA00002C000500
S28842885A6K27GA00002CB000500IWM   0000736600Y
S28842898A8K27G6000028B000500MZZ   0000491600Y
S28842898A8K27G6000029S000100MVV   0000809400Y
S28842927X6K27GA00005Q002000
S28842965X8K27G600001Y000500
S28842965X8K27G6000020000500
S28842965X8K27G600001W000500
S28842965X8K27G600001R000500
S28842965X8K27G600001X000100
S28842965X8K27G600001S000100
S28842965X8K27G6000021000100
S28842965X8K27G600001Z000100
S28842967A8K27G600002AS000500MZZ   0000493900Y
S28842967A8K27G600002BB000100MVV   0000806200Y
S28843059XAK27GA0000E5001000
S28843059AAK27GA0000E5S001000SPY   0001425600Y
S28843059X4K27GA00007C000200
S28843059A4K27GA00007CB000200DIA   0001298500Y
S28843059XAK27GA0000RR003000
S28843059XAK27GA0000EX000500
S28843059AAK27GA0000EXB000500SPY   0001425000Y
S28843059XAK27GA0000RQ003000
S28843059XAK27GA0000FD000500
S28843059AAK27GA0000FDB000500SPY   0001425000Y
S28843060AAK27GA0000RUS001000SPY   0001425800Y
S28843060XAK27GA0000RE001000
S28843060XAK27GA0000Q2002000
S28843061X4K27GA00009B000100
S28843061AAK27GA0000RVB003000SPY   0001424700Y
S28843061X4K27GA00009C000100
S28843061X3K27G6000041000100
S28843062AAK27GA0000RWB003000SPY   0001424700Y
S28843071A8K27G600002CS000500MZZ   0000493800Y
S28843071A8K27G600002DB000100MVV   0000806300Y
S28843075X6K27GA00002C000500
S28843075A6K27GA00002CB000500IWM   0000736200Y
S28843077XBK27GA0000FA001000
S28843076A6K27GA00005RS002000IWM   0000737000Y
S28843088XBK27GA0000FC000100
S28843088XBK27GA0000FD000100
S28843088A6K27GA00005SB000100IWM   0000736100Y
S28843088X6K27GA00005S000100
S28843090ABK27GA0000FES000100TWM   0000702000Y
S28843111X8K27G600002C000500
S28843111X8K27G600002B000100
S28843111X8K27G600002A000500
S28843111X8K27G600002D000100
S28843113A8K27G600002EB000100MVV   0000806100Y
S28843113A8K27G600002FS000500MZZ   0000494000Y
S28843135XAK27GA0000QX001000
S28843149XAK27GA0000R6001000
S28843151AAK27GA0000RXB001000SPY   0001425200Y
S28843285X8K27G6000028000500
S28843285X8K27G6000029000100
S28843337XAK27GA0000RU001000
S28843337AAK27GA0000RYS001000SPY   0001425900Y
S28843339AAK27GA0000RZS001000SPY   0001425900Y
S28843364XAK27GA0000R2002000
S28843409X7K27GA000021002000
S28843430XBK27GA0000EZ002000
S28843430XBK27GA0000F0002000
S28843437XCK27GA00002D002000
S28843445A6K27GA00005TB002000IMCL  0000324600Y
S28843449X1K27GA000040002000
S28843476X9K27G60000M3005000
S28843477X9K27G60000F7003200
S28843477A9K27G60000F7B003200QQQQ  0000495200Y
S28843477X9K27G60000M2005000
S28843477A9K27G60000M6S005000QQQQ  0000495800Y
S28843477A9K27G60000M7S005000QQQQ  0000495800Y
S28843478A9K27G60000M8S002000QQQQ  0000495800Y
S28843478X9K27G60000G8002000
S28843478A9K27G60000G8B002000QQQQ  0000495200Y
S28843480X1K27GA000041002000
S28843482X9K27G60000EQ002000
S28843482A9K27G60000EQS002000QQQQ  0000495800Y
S28843485X2K27G600002R002000
S28843485X2K27G6000032002000
S28843493E4K27GA00002Y00010000004AQ00005
S28843492X6K27GA00002A000500
S28843492A6K27GA00002AS000500IWM   0000736700Y
S28843495X9K27G60000G1002000
S28843495A9K27G60000G1S002000QQQQ  0000495800Y
S28843495X9K27G60000LY005000
S28843495ABK27GA0000FFS000100UWM   0000543400Y
S28843495ABK27GA0000FGB000100TWM   0000701000Y
S28843495ABK27GA0000FHB000100TWM   0000701100Y
S28843495A4K27GA00009MS000100DIG   0001246800Y
S28843496X4K27GA00009M000100
S28843495X6K27GA00001J000100
S28843497A9K27G60000M9B005000QQQQ  0000495300Y
S28843498X3K27G6000019002000
S28843498A4K27GA00009NS000100DIG   0001246800Y
S28843499X3K27G6000043002000
S28843503A6K27GA00005UB000100IYE   0001532500Y
S28843503X6K27GA00001L000100
S28843506A6K27GA00005VS000100IYE   0001540600Y
S28843512X9K27G60000LZ005000
S28843515X2K27G600002O002000
S28843514X4K27GA00009J002000
S28843516XAK27GA0000RF001000
S28843516AAK27GA0000S0S001000SPY   0001425800Y
S28843522A9K27G60000MAB005000QQQQ  0000495300Y
S28843532X2K27G6000033002000
S28843532X1K27GA00000V000100
S28843532A1K27GA00000VB000100AAPL  0001828600Y
S28843545X9K27G60000MA005000
S28843546X9K27G60000M9005000
S28843546A9K27G60000MBB005000QQQQ  0000495700Y
S28843546A9K27G60000MCB005000QQQQ  0000495700Y
S28843549E1K27GA00002Y000090000N1AQ00003
S28843551X3K27G6000013002000
S28843561X3K27G6000047002000
S28843562A7K27GA000025B002000LMT   0000122300Y
S28843572X6K27GA00005U000100
S28843572A6K27GA00005WB000100IYE   0001533200Y
S28843574A5K27GA00002SB002000GM    0000174300Y
S28843579A1K27GA000042B002000AFL   0000072000Y
S28843588A2K27G6000037B002000BDX   0000758300Y
S28843596A3K27G6000049B002000CVS   0000042200Y
S28843608A5K27GA00002TB002000HNZ   0000045200Y
S28843613A5K27GA00002UB002000HOT   0000046300Y
S28843626A6K27GA00005XB002000JCP   0000411900Y
S28843641A7K27GA000026B002000LMT   0000123100Y
S28843643A6K27GA00005YB002000JPM   0000443300Y
S28843652ACK27GA00002EB002000WYE   0000044200Y
S28843663A6K27GA00005ZB002000JWN   0000349300Y
S28843670A1K27GA000043B002000AFL   0000072800Y
S28843681A2K27G6000038B002000BBT   0000032800Y
S28843687A6K27GA000060B002000KEY   0000209100Y
S28843711A2K27G6000039B002000BDX   0000759100Y
S28843728A3K27G600004AB002000COH   0000034800Y
S28843739A4K27GA00009OB002000EIX   0000050000Y
S28843749A5K27GA00002VB002000HNZ   0000046000Y
S28844106XAK27GA0000O6000500
S28844106AAK27GA0000O6S000500SPY   0001425600Y
S28844184A8K27G600002GB000500MZZ   0000491500Y
S28844184A8K27G600002HS000100MVV   0000809500Y
S28844355X2K27G6000035002000
S28844381X7K27GA000026002000
S28844387X7K27GA000025002000
S28844387AAK27GA0000S1B002000SHLD  0000696700Y
S28844440X1K27GA000042002000
S28844451ABK27GA0000FIB002000UTX   0000081100Y
S28844453X1K27GA000039002000
S28844459X2K27G6000036002000
S28844463X9K27G60000MC005000
S28844461XCK27GA00002E002000
S28844492A9K27G60000MDB005000QQQQ  0000495300Y
S28844496A7K27GA000027B002000LPNT  0000191200Y
S28844503AAK27GA0000S2S001000SPY   0001425800Y
S28844521A1K27GA000044B002000ABT   0000059900Y
S28844529X1K27GA000043002000
S28844549X1K27GA00003A002000
S28844555ABK27GA0000FJB002000UTX   0000080300Y
S28844568X3K27G6000049002000
S28844583A2K27G600003AB002000AXP   0000400800Y
S28844598A2K27G600003BB002000CAG   0000020300Y
S28844598XAK27GA0000E5001000
S28844598AAK27GA0000E5S001000SPY   0001426000Y
S28844598XAK27GA0000RV003000
S28844598XAK27GA0000EX000500
S28844598AAK27GA0000EXB000500SPY   0001425400Y
S28844598XAK27GA0000RW003000
S28844598XAK27GA0000S2001000
S28844598XAK27GA0000S0001000
S28844598AAK27GA0000S3B001000SPY   0001425300Y
S28844599AAK27GA0000S4B003000SPY   0001425400Y
S28844599AAK27GA0000S5B003000SPY   0001425400Y
S28844599XAK27GA0000RS003000
S28844599XAK27GA0000RT003000
S28844599XAK27GA0000O6000500
S28844599AAK27GA0000O6S000500SPY   0001426000Y
S28844601AAK27GA0000S6S003000SPY   0001426400Y
S28844602AAK27GA0000S7S003000SPY   0001426400Y
S28844608ACK27GA00002FB002000WYE   0000044600Y
S28844610XAK27GA0000RZ001000
S28844613ABK27GA0000FKB001000SSO   0000764100Y
S28844614A3K27G600004BB002000CCE   0000190200Y
S28844615X6K27GA00002A000500
S28844615A6K27GA00002AS000500IWM   0000737100Y
S28844617X9K27G60000MD005000
S28844617X9K27G60000M7005000
S28844617A9K27G60000MEB005000QQQQ  0000495700Y
S28844617X4K27GA00007C000200
S28844617A4K27GA00007CB000200DIA   0001298800Y
S28844618X9K27G60000G1002000
S28844618A9K27G60000G1S002000QQQQ  0000496300Y
S28844618A9K27G60000MFS005000QQQQ  0000496200Y
S28844619A4K27GA00009PS000100DOG   0000598300Y
S28844620A3K27G600004CB000100DDM   0000801200Y
S28844619A4K27GA00009QS000100DXD   0000500100Y
S28844621XAK27GA0000S3001000
S28844622X9K27G60000EQ002000
S28844622A9K27G60000EQS002000QQQQ  0000496100Y
S28844623X9K27G60000M8002000
S28844624AAK27GA0000S8B001000SPY   0001425200Y
S28844628XBK27GA0000FF000100
S28844628XBK27GA0000FH000100
S28844628XBK27GA0000FG000100
S28844632X5K27GA00001Z002000
S28844636X5K27GA00002T002000
S28844637XAK27GA0000RY001000
S28844637AAK27GA0000S9S001000SPY   0001426000Y
S28844637X6K27GA00002C000500
S28844637A6K27GA00002CB000500IWM   0000736600Y
S28844639AAK27GA0000SAS001000SPY   0001426000Y
S28844640ABK27GA0000FLB000100UWM   0000542500Y
S28844638X6K27GA00002C000500
S28844638A6K27GA00002CB000500IWM   0000736200Y
S28844640ABK27GA0000FMS000100TWM   0000701800Y
S28844640XBK27GA0000FE000100
S28844640XAK27GA0000E5001000
S28844640AAK27GA0000E5S001000SPY   0001425600Y
S28844640XAK27GA0000S5003000
S28844640XAK27GA0000EX000500
S28844640AAK27GA0000EXB000500SPY   0001425000Y
S28844640XAK27GA0000S4003000
S28844640XAK27GA0000S6003000
S28844640XAK27GA0000S7003000
S28844641AAK27GA0000SBS003000SPY   0001425800Y
S28844641AAK27GA0000SCS003000SPY   0001425800Y
S28844641AAK27GA0000SDS001000SPY   0001425900Y
S28844642AAK27GA0000SEB003000SPY   0001424700Y
S28844642AAK27GA0000SFB003000SPY   0001424700Y
S28844641X6K27GA00002C000500
S28844641A6K27GA00002CB000500IWM   0000736600Y
S28844643XBK27GA0000FL000100
S28844643XBK27GA0000FM000100
S28844645A1K27GA000045B002000ABT   0000059100Y
S28844645ABK27GA0000FNB000100UWM   0000542500Y
S28844645ABK27GA0000FOS000100TWM   0000701800Y
S28844645X6K27GA00002C000500
S28844645A6K27GA00002CB000500IWM   0000736200Y
S28844647X6K27GA00002C000500
S28844647A6K27GA00002CB000500IWM   0000736600Y
S28844648XBK27GA0000FN000100
S28844648XBK27GA0000FO000100
S28844648X6K27GA00002C000500
S28844648A6K27GA00002CB000500IWM   0000736200Y
S28844650ABK27GA0000FPS000100TWM   0000701800Y
S28844650ABK27GA0000FQB000100UWM   0000542500Y
S28844651X4K27GA00009O002000
S28844650X6K27GA00002C000500
S28844650A6K27GA00002CB000500IWM   0000736600Y
S28844652XBK27GA0000FQ000100
S28844652XBK27GA0000FP000100
S28844654ABK27GA0000FRB000100UWM   0000542500Y
S28844654ABK27GA0000FSS000100TWM   0000701800Y
S28844655X5K27GA00002U002000
S28844655X6K27GA00002C000500
S28844655A6K27GA00002CB000500IWM   0000736200Y
S28844657X6K27GA00002C000500
S28844657A6K27GA00002CB000500IWM   0000736600Y
S28844659X6K27GA00002C000500
S28844659A6K27GA00002CB000500IWM   0000736200Y
S28844661X5K27GA00002V002000
S28844661XAK27GA0000S8001000
S28844662X4K27GA00007C000200
S28844662A4K27GA00007CB000200DIA   0001298500Y
S28844664X4K27GA00009P000100
S28844664X4K27GA00009Q000100
S28844665X3K27G600004C000100
S28844668XBK27GA0000FR000100
S28844668XBK27GA0000FS000100
S28844668X9K27G60000G1002000
S28844668A9K27G60000G1S002000QQQQ  0000495800Y
S28844668X9K27G60000MF005000
S28844669A9K27G60000MGS005000QQQQ  0000495800Y
S28844670A9K27G60000MHS002000QQQQ  0000495800Y
S28844670A3K27G600004DB002000CVS   0000044200Y
S28844670ABK27GA0000FTS000100TWM   0000702000Y
S28844670XBK27GA0000FK001000
S28844672X9K27G60000EQ002000
S28844672A9K27G60000EQS002000QQQQ  0000495800Y
S28844686X6K27GA00005N002000
S28844696X9K27G60000ME005000
S28844698A5K27GA00002WB002000HOT   0000048400Y
S28844700A2K27G600003CB002000AXP   0000400000Y
S28844702A9K27G60000MIB005000QQQQ  0000495300Y
S28844708A2K27G600003DB002000BBT   0000033000Y
S28844710A4K27GA00009RS000100DRYS  0001071900Y
S28844723A3K27G600004EB002000CCE   0000189400Y
S28844729A3K27G600004FB002000COH   0000035000Y
S28844741A4K27GA00009SB002000EIX   0000050600Y
S28844811X4K27GA00009F000100
S28844816XAK27GA0000O6000500
S28844816AAK27GA0000O6S000500SPY   0001425600Y
S28844928XAK27GA0000SD001000
S28845041A4K27GA00009TB000100DOG   0000597000Y
S28845041A4K27GA00009UB000100DXD   0000499400Y
S28845041A3K27G600004GS000100DDM   0000802600Y
S28845131E4K27GA00009G00010000004AQ00006
S28845133A4K27GA00009WB000100DRYS  0001066900Y
S28845165AAK27GA0000SGS002000SPY   0001425800Y
S28845292X9K27G60000MB005000
S28845353X4K27GA00009A000200
S28845375A4K27GA00009XS000200DIA   0001298900Y
S28845374X6K27GA00005T002000
S28845390A9K27G60000MJB005000QQQQ  0000495300Y
S28845419XBK27GA0000FJ002000
S28845419XAK27GA0000S1002000
S28845448XCK27GA00002F002000
S28845450XBK27GA0000FI002000
S28845450XAK27GA0000R1002000
S28845472X3K27G6000045002000
S28845485X1K27GA000045002000
S28845495X1K27GA000044002000
S28845500X1K27GA000022002000
S28845512X2K27G6000038002000
S28845531X3K27G600004A002000
S28845531A7K27GA000028B002000LMT   0000128300Y
S28845540X1K27GA00001X002000
S28845547X3K27G600004D002000
S28845556X4K27GA000057002000
S28845572A1K27GA000046B002000AFL   0000075700Y
S28845588A1K27GA000047B002000ARO   0000293400Y
S28845596X4K27GA00005F002000
S28845607X5K27GA00002W002000
S28845615A2K27G600003EB002000CAG   0000020200Y
S28845621A2K27G600003FB002000BMY   0000019200Y
S28845624X4K27GA00005Q002000
S28845627X4K27GA00009S002000
S28845642A3K27G600004HB002000CVS   0000044600Y
S28845642A7K27GA000029B002000LMT   0000129100Y
S28845660ACK27GA00002GB002000WYE   0000046700Y
S28845671A5K27GA00002XB002000HMY   0000083900Y
S28845681A5K27GA00002YB002000HNZ   0000047800Y
S28845681A1K27GA000048B002000AFL   0000076500Y
S28845691A1K27GA000049B002000ARO   0000294200Y
S28845692A5K27GA00002ZB002000HOT   0000049000Y
S28845709A4K27GA00009YB002000EIX   0000052800Y
S28845726A5K27GA000030B002000HNZ   0000048600Y
S28845740A6K27GA000061B002000JCI   0000034900Y
S28845748A6K27GA000062B002000JBL   0000104000Y
S28845763A6K27GA000063B002000JCI   0000035700Y
S28845839X5K27GA00001F000100
S28846044XAK27GA0000EW000500
S28846044AAK27GA0000EWS000500SPY   0001425600Y
S28846044XAK27GA0000F2000500
S28846044AAK27GA0000F2B000500SPY   0001424900Y
S28846044X4K27GA000062000200
S28846044A4K27GA000062B000200DIA   0001298400Y
S28846053XAK27GA0000RK000100
S28846054AAK27GA0000SHB001000SDS   0000547700Y
S28846054XBK27GA0000F9001000
S28846054X3K27G600003Y000100
S28846055AAK27GA0000SIB001000SDS   0000547600Y
S28846055ABK27GA0000FUS001000SSO   0000765100Y
S28846056XBK27GA0000F1001000
S28846056ABK27GA0000FVB001000SSO   0000764000Y
S28846056ABK27GA0000FWB001000SSO   0000764200Y
S28846054X6K27GA00002A000500
S28846054A6K27GA00002AS000500IWM   0000736700Y
S28846057ABK27GA0000FXS000100UWM   0000543400Y
S28846057ABK27GA0000FYB000100TWM   0000701000Y
S28846057ABK27GA0000FZB000100TWM   0000701100Y
S28846123XAK27GA0000EW000500
S28846123AAK27GA0000EWS000500SPY   0001425500Y
S28846152X9K27G60000MI005000
S28846152X9K27G60000MJ005000
S28846152A9K27G60000MKB005000QQQQ  0000495700Y
S28846153A9K27G60000MLB005000QQQQ  0000495700Y
S28846233X9K27G60000MK005000
S28846242A9K27G60000MMB005000QQQQ  0000495300Y
S28846277X6K27GA00005J002000
S28846326X9K27G60000MM005000
S28846326A9K27G60000MNB005000QQQQ  0000495700Y
S28846376X9K27G60000MN005000
S28846382A9K27G60000MOB005000QQQQ  0000495300Y
S28846381A6K27GA000064B002000IWM   0000736400Y
S28846408X7K27GA000028002000
S28846409XAK27GA0000HG001000
S28846413X7K27GA000029002000
S28846413AAK27GA0000SJB000600SPY   0001419600Y
S28846427XCK27GA00002G002000
S28846467X1K27GA000048002000
S28846471X6K27GA000064002000
S28846480ABK27GA0000G0B002000UTX   0000084300Y
S28846481XAK27GA0000FO002000
S28846482ABK27GA0000G1B002000UTX   0000085100Y
S28846488A6K27GA000065B002000IMCL  0000327900Y
S28846514AAK27GA0000SKB002000SHLD  0000701900Y
S28846516ACK27GA00002HB002000WYE   0000047100Y
S28846538A1K27GA00004AB002000ABT   0000063000Y
S28846552AAK27GA0000SLB002000SPLS  0000019800Y
S28846560X2K27G600003B002000
S28846565A1K27GA00004BB002000ABT   0000062100Y
S28846587A1K27GA00004CB002000ANF   0000721000Y
S28846598A3K27G600004IB002000CTSH  0000030700Y
S28846598X1K27GA000046002000
S28846607X9K27G60000MO005000
S28846608A9K27G60000MPB005000QQQQ  0000495700Y
S28846619A9K27G60000MQS002000QQQQ  0000496000Y
S28846619A1K27GA00004DB002000ANF   0000720200Y
S28846639A2K27G600003GB002000BBT   0000035700Y
S28846645A3K27G600004JS000100DDM   0000802500Y
S28846644A4K27GA00009ZB000100DXD   0000499500Y
S28846647X2K27G600003D002000
S28846658X3K27G600004F002000
S28846662X3K27G600004H002000
S28846671X4K27GA00006G002000
S28846678A3K27G600004KB002000COH   0000037800Y
S28846678X5K27GA00002Y002000
S28846688X5K27GA00002Z002000
S28846707A4K27GA0000A0B002000EAT   0000197600Y
S28846709A3K27G600004LB002000CVS   0000046600Y
S28846721A4K27GA0000A1B002000EIX   0000053400Y
S28846721X4K27GA00009Y002000
S28846732X4K27GA00006F002000
S28846736X9K27G60000MP005000
S28846742A9K27G60000MRB005000QQQQ  0000495300Y
S28846743X9K27G60000ML005000
S28846746X5K27GA000029002000
S28846747A9K27G60000MSB005000QQQQ  0000495300Y
S28846747X9K27G60000EP002000
S28846747A9K27G60000EPB002000QQQQ  0000495400Y
S28846757X5K27GA000030002000
S28846782A4K27GA0000A2B002000DIS   0000328100Y
S28846781A6K27GA000066B002000KFT   0000304000Y
S28846802A7K27GA00002AB002000KMB   0000610800Y
S28846802A4K27GA0000A3B002000EAT   0000198400Y
S28846822X9K27G60000MS005000
S28846822A9K27G60000MTB005000QQQQ  0000495700Y
S28846823X9K27G60000MQ002000
S28846824X6K27GA00005W000100
S28846825A4K27GA0000A4B000100DIG   0001238700Y
S28846825X4K27GA000031000100
S28846826A6K27GA000067B000100IYE   0001532300Y
S28846832X6K27GA000067000100
S28846833X4K27GA0000A4000100
S28846834A6K27GA000068B000100IYE   0001531500Y
S28846843A4K27GA0000A5B000100DIG   0001237700Y
S28846843X4K27GA00009Z000100
S28846844X3K27G600004J000100
S28846871A4K27GA0000A6B000100DXD   0000499500Y
S28846872A3K27G600004MS000100DDM   0000802500Y
S28846903X4K27GA0000A6000100
S28846904X3K27G600004M000100
S28846932A4K27GA0000A7B000100DXD   0000499500Y
S28846932A3K27G600004NS000100DDM   0000802500Y
S28846963X4K27GA0000A7000100
S28846964X3K27G600004N000100
S28847082A6K27GA000069S000100IYE   0001538500Y
S28847083A4K27GA0000A8S000100DIG   0001243500Y
S28847083X4K27GA00009N000100
S28847350X3K27G6000042002000
S28847393X2K27G600003F002000
S28847396XBK27GA0000G0002000
S28847417XAK27GA0000SK002000
S28847426XAK27GA0000PU002000
S28847431XCK27GA00002H002000
S28847452XBK27GA0000G1002000
S28847454X1K27GA00004A002000
S28847457X2K27G600000R002000
S28847457AAK27GA0000SMB002000SOHU  0000798100Y
S28847477X3K27G600004L002000
S28847477X1K27GA00004B002000
S28847492X3K27G600003A002000
S28847508X1K27GA000028002000
S28847523X6K27GA000063002000
S28847537A7K27GA00002BB002000LMT   0000135100Y
S28847548A7K27GA00002CB002000LMT   0000134300Y
S28847554ACK27GA00002IB002000WYE   0000049100Y
S28847565X2K27G600000U002000
S28847569A1K27GA00004EB002000AFL   0000079400Y
S28847585X2K27G600003E002000
S28847589A1K27GA00004FB002000AFL   0000080200Y
S28847610A2K27G600003HB002000CAG   0000022300Y
S28847621A2K27G600003IB002000BBT   0000035800Y
S28847635A4K27GA0000A9B002000EIX   0000055600Y
S28847647X4K27GA0000A1002000
S28847661A3K27G600004OB002000COH   0000038000Y
S28847663A4K27GA0000AAB002000ESI   0000616600Y
S28847683A3K27G600004PB002000CVS   0000047000Y
S28847696A5K27GA000031B002000HMY   0000084900Y
S28847696A4K27GA0000ABB002000ESI   0000615800Y
S28847706XAK27GA0000FE000500
S28847706AAK27GA0000FEB000500SPY   0001424900Y
S28847706XAK27GA0000R7001000
S28847705X6K27GA000061002000
S28847707AAK27GA0000SNS001000SPY   0001425500Y
S28847707XAK27GA0000E4001000
S28847707AAK27GA0000E4B001000SPY   0001425000Y
S28847709A5K27GA000032B002000HNZ   0000050300Y
S28847717XAK27GA0000RX001000
S28847717AAK27GA0000SOB001000SPY   0001425100Y
S28847719AAK27GA0000SPB001000SPY   0001425100Y
S28847721A5K27GA000033B002000HOT   0000051600Y
S28847723A4K27GA0000ACB000100DXD   0000499500Y
S28847724A3K27G600004QS000100DDM   0000802500Y
S28847761A5K27GA000034B002000HNZ   0000051100Y
S28847763X4K27GA0000AC000100
S28847764X3K27G600004Q000100
S28847770A5K27GA000035B002000HOT   0000052400Y
S28848086XAK27GA0000R3001000
S28848091A4K27GA0000ADB000100DXD   0000499500Y
S28848091A3K27G600004RS000100DDM   0000802500Y
S28848101AAK27GA0000SQB001000SPY   0001425000Y
S28848123X4K27GA0000AD000100
S28848124X3K27G600004R000100
S28848258A4K27GA0000AEB000100DRYS  0001066900Y
S28848364X6K27GA000065002000
S28848369X7K27GA00002B002000
S28848369X7K27GA00002C002000
S28848394XCK27GA00002I002000
S28848402X7K27GA000027002000
S28848428X9K27G60000LW002000
S28848429A2K27G600003JB002000BMY   0000021000Y
S28848431A3K27G600004SB002000CELG  0000469900Y
S28848433ABK27GA0000G2B002000UTX   0000088300Y
S28848468AAK27GA0000SRB002000SHLD  0000707000Y
S28848467ACK27GA00002JB002000WYE   0000049500Y
S28848468X1K27GA00004F002000
S28848480X1K27GA00004E002000
S28848502ABK27GA0000G3B002000UTX   0000089100Y
S28848510AAK27GA0000SSB002000SNDK  0000222300Y
S28848520A1K27GA00004GB002000ABT   0000065200Y
S28848534A3K27G600004TS000100DDM   0000802500Y
S28848533A4K27GA0000AFB000100DXD   0000499500Y
S28848536X2K27G600003G002000
S28848563X4K27GA0000AF000100
S28848563X3K27G600004T000100
S28848564X3K27G600004K002000
S28848572A1K27GA00004HB002000ABT   0000066000Y
S28848586A2K27G600003KB002000BA    0000852900Y
S28848591X4K27GA0000A9002000
S28848608X4K27GA00005Y002000
S28848617X5K27GA000034002000
S28848622A1K27GA00004IB002000APC   0000763100Y
S28848624X5K27GA000035002000
S28848638X3K27G600004P002000
S28848639A2K27G600003LB002000BA    0000852100Y
S28848651X4K27GA00005A002000
S28848653A3K27G600004UB002000CVS   0000048900Y
S28848660A2K27G600003MB002000CAG   0000022100Y
S28848674A3K27G600004VB002000DD    0000455600Y
S28848702X5K27GA000032002000
S28848703A6K27GA00006AB002000JCI   0000038500Y
S28848710X5K27GA000033002000
S28848722A6K27GA00006BB002000JCP   0000413000Y
S28848729A4K27GA0000AGB002000EIX   0000056200Y
S28848938X5K27GA00001B000100
S28849164XAK27GA0000QY003000
S28849164XAK27GA0000QR002000
S28849164XAK27GA0000QZ003000
S28849164XAK27GA0000O2000500
S28849164AAK27GA0000O2S000500SPY   0001425500Y
S28849164XAK27GA0000K1001000
S28849164AAK27GA0000K1S001000SPY   0001425500Y
S28849164X4K27GA00003H000200
S28849164A4K27GA00003HB000200DIA   0001298300Y
S28849164X4K27GA000090000047
S28849165AAK27GA0000STS003000SPY   0001425600Y
S28849165AAK27GA0000SUS003000SPY   0001425600Y
S28849169A4K27GA0000AHS000047DIA   0001298800Y
S28849173A4K27GA0000AIB000100DXD   0000499500Y
S28849174A3K27G600004WS000100DDM   0000802500Y
S28849178X4K27GA00003H000200
S28849178A4K27GA00003HB000200DIA   0001298600Y
S28849355XAK27GA0000SR002000
S28849391X3K27G600004I002000
S28849416A6K27GA00006CB002000IMCL  0000331100Y
S28849421XBK27GA0000G3002000
S28849424XBK27GA0000G2002000
S28849443XCK27GA00002J002000
S28849446X1K27GA00004H002000
S28849455X1K27GA00004G002000
S28849467X2K27G600003C002000
S28849474X2K27G600003I002000
S28849489X2K27G600003A002000
S28849493X2K27G6000037002000
S28849511X3K27G600004O002000
S28849514X3K27G600003E002000
S28849514A7K27GA00002DB002000LMT   0000141100Y
S28849514X4K27GA0000AG002000
S28849518A7K27GA00002EB002000LMT   0000140300Y
S28849528A7K27GA00002FB002000LPNT  0000194500Y
S28849535ACK27GA00002KB002000WYE   0000051500Y
S28849544X2K27G6000039002000
S28849553A1K27GA00004JB002000AFL   0000083100Y
S28849563X2K27G600003H002000
S28849575A9K27G60000MUB002000PDLI  0000017400Y
S28849575A3K27G600004XB002000CVS   0000049300Y
S28849591A4K27GA0000AJB002000DIS   0000327400Y
S28849621A1K27GA00004KB002000AFL   0000083900Y
S28849623A5K27GA000036B002000HNZ   0000052900Y
S28849627X3K27G600004U002000
S28849641A5K27GA000037B002000HOT   0000054300Y
S28849650A2K27G600003NB002000BBT   0000038500Y
S28849656A6K27GA00006DB002000JCI   0000038700Y
S28849671A3K27G600004YB002000COH   0000040700Y
S28849671A7K27GA00002GB002000KMX   0000185800Y
S28849683X5K27GA00001G000100
S28849688A5K27GA000038S000100FXP   0000658300Y
S28849693X5K27GA000038000100
S28849695A5K27GA000039S000100FXP   0000658300Y
S28849695A7K27GA00002HB002000LEH   0000416200Y
S28849701A4K27GA0000AKB002000EIX   0000058400Y
S28849703X5K27GA000039000100
S28849740A4K27GA0000ALB002000ELN   0000227000Y
S28849758A5K27GA00003AB002000HNZ   0000053700Y
S28849769A5K27GA00003BB002000HOT   0000055100Y
S28850379XAK27GA0000SL002000
S28850388X9K27G60000MT005000
S28850389X9K27G60000F4003200
S28850389A9K27G60000F4S003200QQQQ  0000495800Y
S28850390X4K27GA00003H000200
S28850390A4K27GA00003HB000200DIA   0001298300Y
S28850390A9K27G60000MVB005000QQQQ  0000495300Y
S28850398X2K27G600003J002000
S28850400X3K27G600000O002000
S28850400X7K27GA00002E002000
S28850408X9K27G60000MV005000
S28850409X9K27G60000F4003200
S28850409A9K27G60000F4S003200QQQQ  0000496300Y
S28850409A9K27G60000MWB005000QQQQ  0000495700Y
S28850413X9K27G60000MR005000
S28850413A9K27G60000MXB005000QQQQ  0000495700Y
S28850413X7K27GA00002D002000
S28850419X9K27G60000MW005000
S28850419X9K27G60000F4003200
S28850419A9K27G60000F4S003200QQQQ  0000495800Y
S28850419X9K27G60000MX005000
S28850419X1K27GA00004J002000
S28850420A9K27G60000MYB005000QQQQ  0000495300Y
S28850420A9K27G60000MZB005000QQQQ  0000495300Y
S28850424XCK27GA00002K002000
S28850427AAK27GA0000SVB002000SHLD  0000712100Y
S28850439X2K27G600003M002000
S28850440X1K27GA00004K002000
S28850446X1K27GA00002B002000
S28850451X4K27GA00005E002000
S28850457A3K27G6000050B002000CTSH  0000034200Y
S28850459X4K27GA0000AK002000
S28850468X4K27GA00005L002000
S28850484X3K27G600004X002000
S28850487X5K27GA00001U002000
S28850498X4K27GA00005P002000
S28850523X5K27GA00003A002000
S28850526X5K27GA00003B002000
S28850526X6K27GA00006A002000
S28850534X4K27GA000067002000
S28850540X5K27GA00001O002000
S28850542X5K27GA000036002000
S28850549X5K27GA000037002000
S28850558ABK27GA0000G4B002000UTX   0000093100Y
S28850571ABK27GA0000G5B002000UTX   0000092300Y
S28850581A1K27GA00004LB002000ABT   0000069100Y
S28850584ACK27GA00002LB002000WYE   0000051900Y
S28850600A1K27GA00004MB002000ABT   0000068300Y
S28850602A2K27G600003OB002000AXP   0000402200Y
S28850620A2K27G600003PB002000AXP   0000401400Y
S28850621A2K27G600003QB002000BDX   0000760500Y
S28850631A2K27G600003RB002000BBT   0000038700Y
S28850640A2K27G600003SB002000CAG   0000024200Y
S28850644A2K27G600003TB002000BDX   0000759700Y
S28850651A3K27G6000051B002000COH   0000040900Y
S28850653A8K27G600002IB000500MZZ   0000491600Y
S28850653A8K27G600002JS000100MVV   0000809300Y
S28850664A3K27G6000052B002000CVS   0000051300Y
S28850664A3K27G6000053B002000DD    0000454900Y
S28850676A4K27GA0000AMB002000EIX   0000059000Y
S28850695A7K27GA00002IB002000LEN   0000180900Y
S28850725A6K27GA00006EB002000JPM   0000444100Y
S28850924X4K27GA00003H000200
S28850924A4K27GA00003HB000200DIA   0001298600Y
S28851346X4K27GA00009R000100
S28851392X6K27GA00006C002000
S28851400XAK27GA0000SV002000
S28851404XBK27GA0000G4002000
S28851409XBK27GA0000G5002000
S28851414XCK27GA000023002000
S28851427X1K27GA00004L002000
S28851428XCK27GA000020002000
S28851440X2K27G600003N002000
S28851440AAK27GA0000SWB002000SPLS  0000022900Y
S28851444X3K27G600004Y002000
S28851451XCK27GA00002L002000
S28851459X3K27G6000052002000
S28851465X1K27GA00004M002000
S28851481X3K27G600001X002000
S28851491X3K27G6000022002000
S28851498A3K27G6000054B002000COST  0000695100Y
S28851499X4K27GA0000AM002000
S28851520A2K27G600003UB002000BMY   0000022900Y
S28851521X6K27GA00006D002000
S28851539A7K27GA00002JB002000LMT   0000146300Y
S28851559A7K27GA00002KB002000LMT   0000147100Y
S28851567X4K27GA000032000100
S28851567A4K27GA0000ANS000100DRYS  0001070900Y
S28851575A1K27GA00004NB002000AFL   0000086800Y
S28851583A2K27G600003VB002000CAG   0000024100Y
S28851589ACK27GA00002MB002000WYE   0000053900Y
S28851593A3K27G6000055B002000CVS   0000051700Y
S28851611A4K27GA0000AOB002000DUK   0000162200Y
S28851615A1K27GA00004OB002000AFL   0000087600Y
S28851623A4K27GA0000APB002000ELN   0000226300Y
S28851628A1K27GA00004PB002000APC   0000764000Y
S28851632A5K27GA00003CB002000GE    0000298200Y
S28851651A5K27GA00003DB002000HNZ   0000055500Y
S28851654A4K27GA0000AQB002000DUK   0000163000Y
S28851658A5K27GA00003EB002000HOT   0000057000Y
S28851674A4K27GA0000ARB002000EIX   0000061200Y
S28851686A7K27GA00002LB002000LLL   0001086200Y
S28851689A4K27GA0000ASB002000EK    0000146500Y
S28851719A5K27GA00003FB002000GE    0000299000Y
S28851731A5K27GA00003GB000100GOOG  0005770100Y
S28852278XAK27GA0000SU003000
S28852279XAK27GA0000ST003000
S28852281AAK27GA0000SXS003000SPY   0001426200Y
S28852281AAK27GA0000SYS003000SPY   0001426200Y
S28852356A6K27GA00006FB002000IMCL  0000334400Y
S28852358X7K27GA00002K002000
S28852360X7K27GA00002J002000
S28852391XCK27GA00002M002000
S28852420X1K27GA00004O002000
S28852424X2K27G600003S002000
S28852427ABK27GA0000G6B002000UTX   0000096300Y
S28852431X4K27GA000058002000
S28852434AAK27GA0000SZB002000SHLD  0000717200Y
S28852443X4K27GA0000AR002000
S28852469ABK27GA0000G7B002000UTX   0000097100Y
S28852467ACK27GA00002NB002000WMT   0000536700Y
S28852477ACK27GA00002OB002000WYE   0000054300Y
S28852492ACK27GA00002PB002000WMT   0000537500Y
S28852499A1K27GA00004QB002000ABT   0000071300Y
S28852507X1K27GA00004N002000
S28852516X2K27G600003R002000
S28852519X3K27G6000051002000
S28852526X3K27G6000055002000
S28852527X4K27GA00005B002000
S28852531X4K27GA00005V002000
S28852532A1K27GA00004RB002000ABT   0000072200Y
S28852535X5K27GA00003D002000
S28852537P8K27G600002KB005000OIH   0002170000000I000HV288
S28852539X5K27GA00003E002000
S28852551A2K27G600003WB002000BBT   0000041300Y
S28852576A3K27G6000056B002000COH   0000043700Y
S28852584A3K27G6000057B002000CVS   0000053700Y
S28852596A3K27G6000058B002000DHR   0000760000Y
S28852615AAK27GA0000T0S000100SPY   0001426600Y
S28852615XAK27GA0000QP000100
S28852629A3K27G6000059B002000DHR   0000759200Y
S28852636A4K27GA0000ATB002000EIX   0000061800Y
S28852651A6K27GA00006GB002000JCI   0000041500Y
S28853027X5K27GA00003G000100
S28853027A5K27GA00003GB000100GOOG  0005775100Y
S28853109X9K27G60000F4003200
S28853109A9K27G60000F4S003200QQQQ  0000496300Y
S28853111A9K27G60000N0B005000QQQQ  0000495700Y
S28853111X9K27G60000MZ005000
S28853111X9K27G60000MY005000
S28853111X9K27G60000EP002000
S28853111A9K27G60000EPB002000QQQQ  0000495700Y
S28853111A9K27G60000N1B005000QQQQ  0000495700Y
S28853114X3K27G600004W000100
S28853113X4K27GA0000AI000100
S28853359XAK27GA0000SZ002000
S28853406X3K27G6000050002000
S28853409X2K27G600003U002000
S28853411X7K27GA00002F002000
S28853427XBK27GA0000G6002000
S28853433XBK27GA0000G7002000
S28853445XCK27GA00002O002000
S28853453X9K27G60000MG005000
S28853453X9K27G60000EQ002000
S28853453A9K27G60000EQS002000QQQQ  0000496100Y
S28853453X9K27G60000M6005000
S28853453X9K27G60000MH002000
S28853454A9K27G60000N2B002000QQQQ  0000495500Y
S28853454A9K27G60000N3S005000QQQQ  0000496200Y
S28853454A9K27G60000N4S005000QQQQ  0000496200Y
S28853460X1K27GA00004Q002000
S28853466X1K27GA00004R002000
S28853468A6K27GA00006HB002000IWM   0000736400Y
S28853474X3K27G6000057002000
S28853493X2K27G600003V002000
S28853497A7K27GA00002MB002000LMT   0000153100Y
S28853509X4K27GA0000AT002000
S28853515ACK27GA00002QB002000WYE   0000056300Y
S28853541A7K27GA00002NB002000LMT   0000152300Y
S28853551A1K27GA00004SB002000AFL   0000091300Y
S28853561A1K27GA00004TB002000AFL   0000090500Y
S28853576A2K27G600003XB002000BBT   0000041500Y
S28853577A4K27GA0000AUS000100DRYS  0001070900Y
S28853580A2K27G600003YB002000CAG   0000026200Y
S28853593A3K27G600005AB002000COH   0000043900Y
S28853601A4K27GA0000AVB002000DOW   0000398300Y
S28853606A3K27G600005BB002000CVS   0000054100Y
S28853614A4K27GA0000AWB002000DOW   0000397500Y
S28853619A4K27GA0000AXB002000EIX   0000064000Y
S28853622A4K27GA0000AYB002000EK    0000145800Y
S28853625A5K27GA00003HB002000HNZ   0000058800Y
S28853630A5K27GA00003IB002000HNZ   0000058000Y
S28853636A5K27GA00003JB002000HOT   0000059600Y
S28853644A5K27GA00003KB002000HOT   0000060400Y
S28853648A7K27GA00002OB002000LLY   0000463400Y
S28853661A6K27GA00006IB002000JCI   0000043200Y
S28853666A7K27GA00002PB002000LTD   0000166600Y
S28854357X3K27G600004S002000
S28854387X7K27GA00002M002000
S28854389X7K27GA00002N002000
S28854396XCK27GA00002Q002000
S28854400X6K27GA00006F002000
S28854418X9K27G60000HC002000
S28854419X1K27GA00004S002000
S28854428X1K27GA00004T002000
S28854442AAK27GA0000T1B002000SHLD  0000722300Y
S28854443X2K27G600003W002000
S28854444X3K27G600005B002000
S28854449X3K27G6000056002000
S28854458X4K27GA00006V002000
S28854471X5K27GA00003I002000
S28854471A3K27G600005CB002000CTSH  0000037600Y
S28854476X5K27GA00003J002000
S28854478X6K27GA00006G002000
S28854484A2K27G600003ZB002000BMY   0000024700Y
S28854500X4K27GA0000AX002000
S28854504A7K27GA00002QB002000LPNT  0000197800Y
S28854505ABK27GA0000G8B002000UTX   0000100300Y
S28854529X4K27GA000074002000
S28854552X5K27GA00003H002000
S28854553ACK27GA00002RB002000WYE   0000056700Y
S28854573X5K27GA00003K002000
S28854578ABK27GA0000G9B002000UTX   0000101100Y
S28854584ABK27GA0000GAB000500TSEM  0000011800Y
S28854600A1K27GA00004UB002000ABT   0000074400Y
S28854600A1K27GA00004VB002000ABT   0000075200Y
S28854620A3K27G600005DB002000CVS   0000056000Y
S28854624A2K27G6000040B002000CAG   0000026000Y
S28854653A6K27GA00006JB002000JWN   0000350600Y
S28854660A4K27GA0000AZB002000EIX   0000064600Y
S28854671A6K27GA00006KB002000KEY   0000210500Y
S28854677A9K27G60000N5B002000QQQQ  0000495500Y
S28854687A6K27GA00006LB002000KFT   0000305100Y
S28854720X9K27G60000F7003200
S28854720A9K27G60000F7B003200QQQQ  0000495700Y
S28855040AAK27GA0000T2B000500SPY   0001425200Y
S28855041XAK27GA0000F2000500
S28855041AAK27GA0000F2B000500SPY   0001425300Y
S28855085X4K27GA0000AH000047
S28855092XAK27GA0000O2000500
S28855092AAK27GA0000O2S000500SPY   0001425900Y
S28855092A4K27GA0000B0S000047DIA   0001299100Y
S28855143XAK27GA0000EW000500
S28855143AAK27GA0000EWS000500SPY   0001425900Y
S28855144XAK27GA0000K1001000
S28855144AAK27GA0000K1S001000SPY   0001425900Y
S28855158X8K27G600002J000100
S28855158X8K27G600002I000500
S28855160X4K27GA000062000200
S28855160A4K27GA000062B000200DIA   0001298700Y
S28855162A3K27G600005EB000100DDM   0000801100Y
S28855165X4K27GA000062000200
S28855165A4K27GA000062B000200DIA   0001298400Y
S28855165XAK27GA0000T0000100
S28855167AAK27GA0000T3S000100SPY   0001426900Y
S28855233X1K27GA00002Y000005
S28855236X6K27GA00002A000500
S28855236A6K27GA00002AS000500IWM   0000737100Y
S28855237A1K27GA00004WB000100AAPL  0001828600Y
S28855247XBK27GA0000FX000100
S28855248XBK27GA0000FZ000100
S28855248XBK27GA0000FY000100
S28855252XAK27GA0000E4001000
S28855252AAK27GA0000E4B001000SPY   0001425400Y
S28855252X4K27GA000062000200
S28855252A4K27GA000062B000200DIA   0001298700Y
S28855252XAK27GA0000FE000500
S28855252AAK27GA0000FEB000500SPY   0001425300Y
S28855252XAK27GA0000SQ001000
S28855253XAK27GA0000EX000500
S28855253AAK27GA0000EXB000500SPY   0001425400Y
S28855253AAK27GA0000T4B002000SPY   0001425400Y
S28855253XAK27GA0000SB003000
S28855253XAK27GA0000SE003000
S28855253AAK27GA0000T5B003000SPY   0001425400Y
S28855253XAK27GA0000Q8000500
S28855253AAK27GA0000Q8S000500SPY   0001426000Y
S28855253XAK27GA0000SN001000
S28855253X4K27GA00009X000200
S28855253X9K27G60000G8002000
S28855253A9K27G60000G8B002000QQQQ  0000495700Y
S28855253AAK27GA0000T6B001000SPY   0001425400Y
S28855253XAK27GA0000O6000500
S28855253AAK27GA0000O6S000500SPY   0001426000Y
S28855254X9K27G60000G1002000
S28855254A9K27G60000G1S002000QQQQ  0000496300Y
S28855253XAK27GA0000SC003000
S28855253XAK27GA0000SF003000
S28855253AAK27GA0000T7B002000SPY   0001425300Y
S28855254XAK27GA0000SG002000
S28855254AAK27GA0000T8B003000SPY   0001425400Y
S28855254XAK27GA0000FD000500
S28855254AAK27GA0000FDB000500SPY   0001425400Y
S28855254XAK27GA0000E5001000
S28855254AAK27GA0000E5S001000SPY   0001426000Y
S28855254AAK27GA0000T9S000500SPY   0001425700Y
S28855255AAK27GA0000TAS001000SPY   0001425900Y
S28855255AAK27GA0000TBS003000SPY   0001426400Y
S28855255XAK27GA0000T2000500
S28855255AAK27GA0000TCS003000SPY   0001426400Y
S28855256X3K27G6000046000100
S28855255AAK27GA0000TDS002000SPY   0001425900Y
S28855260A4K27GA0000B1S000200DIA   0001299200Y
S28855263XAK27GA0000RG001000
S28855263XBK27GA0000FU001000
S28855263X3K27G600004G000100
S28855263X4K27GA00009T000100
S28855263X4K27GA00009U000100
S28855264XAK27GA0000RD001000
S28855264XAK27GA0000RC001000
S28855265ABK27GA0000GBS001000SSO   0000765200Y
S28855265A3K27G600005FS000100DDM   0000802700Y
S28855271X9K27G60000FZ002000
S28855271XAK27GA0000T9000500
S28855273A9K27G60000N6S002000QQQQ  0000496000Y
S28855275XAK27GA0000SI001000
S28855281XAK27GA0000Q0001000
S28855282AAK27GA0000TES001000SPY   0001426000Y
S28855281X6K27GA00002C000500
S28855281A6K27GA00002CB000500IWM   0000736600Y
S28855284ABK27GA0000GCB000100UWM   0000542500Y
S28855283X6K27GA00005R002000
S28855285XBK27GA0000FT000100
S28855285ABK27GA0000GDS000100TWM   0000701800Y
S28855291X4K27GA00007C000200
S28855291A4K27GA00007CB000200DIA   0001298800Y
S28855293A4K27GA0000B2S000100DOG   0000598300Y
S28855293A4K27GA0000B3S000100DXD   0000500100Y
S28855294A3K27G600005GB000100DDM   0000801200Y
S28855295XAK27GA0000TD002000
S28855297XAK27GA0000F7000500
S28855297AAK27GA0000F7B000500SPY   0001425400Y
S28855298XAK27GA0000TE001000
S28855298AAK27GA0000TFS000100SH    0000618900Y
S28855298XAK27GA0000EB001000
S28855298AAK27GA0000EBB001000SPY   0001425400Y
S28855299ABK27GA0000GEB001000SSO   0000764300Y
S28855298AAK27GA0000TGS001000SPY   0001425600Y
S28855299XBK27GA0000FW001000
S28855298XAK27GA0000F7000500
S28855298AAK27GA0000F7B000500SPY   0001425100Y
S28855299XAK27GA0000RN001000
S28855299AAK27GA0000THB001000SPY   0001425400Y
S28855301XBK27GA0000FV001000
S28855301ABK27GA0000GFB001000SSO   0000764100Y
S28855301XAK27GA0000TH001000
S28855302XBK27GA0000GF001000
S28855303AAK27GA0000TIB001000SPY   0001425100Y
S28855303XAK27GA0000SH001000
S28855305AAK27GA0000TJB001000SDS   0000547600Y
S28855305A6K27GA00006MB002000IWM   0000736500Y
S28855305X6K27GA000053002000
S28855322XAK27GA0000SA001000
S28855323XAK27GA0000Q8000500
S28855323AAK27GA0000Q8S000500SPY   0001425600Y
S28855327X1K27GA00000W000100
S28855327A1K27GA00000WS000100AAPL  0001830100Y
S28855330A8K27G600002LS000500MZZ   0000493800Y
S28855331A8K27G600002MB000100MVV   0000806300Y
S28855337X1K27GA00000V000100
S28855337A1K27GA00000VB000100AAPL  0001827600Y
S28855337X1K27GA00000Y000100
S28855337A1K27GA00000YS000100AAPL  0001830100Y
S28855370X1K27GA00000W000100
S28855370A1K27GA00000WS000100AAPL  0001830000Y
S28855370X1K27GA00000Y000100
S28855370A1K27GA00000YS000100AAPL  0001830000Y
S28855375X8K27G600002G000500
S28855375X8K27G6000027000100
S28855375X8K27G600002H000100
S28855377A8K27G600002NS000100MVV   0000809700Y
S28855383X7K27GA00000U002000
S28855384A3K27G600005HB002000CELG  0000472400Y
S28855386A8K27G600002OS000100MVV   0000809600Y
S28855385X7K27GA00000O002000
S28855386XBK27GA0000G8002000
S28855391XAK27GA0000T1002000
S28855392X8K27G600002L000500
S28855392X8K27G600002F000500
S28855392X8K27G600002E000100
S28855392X8K27G600002M000100
S28855394A8K27G600002PS000500MZZ   0000493900Y
S28855394A8K27G600002QB000100MVV   0000806200Y
S28855403XCK27GA00002R002000
S28855414XAK27GA0000SW002000
S28855427XBK27GA0000G9002000
S28855432X1K27GA00004U002000
S28855443X2K27G600003P002000
S28855446X2K27G600003X002000
S28855453X3K27G600005A002000
S28855455AAK27GA0000TKB000500SPY   0001425400Y
S28855468A6K27GA00006NB002000IMCL  0000337600Y
S28855474X1K27GA00004V002000
S28855476A7K27GA00002RB002000LMT   0000158300Y
S28855484X4K27GA0000AZ002000
S28855485A7K27GA00002SB002000LMT   0000159100Y
S28855518A9K27G60000N7B002000PETM  0000205400Y
S28855516ACK27GA00002SB002000WYE   0000058700Y
S28855547A1K27GA00004XB002000AFL   0000094200Y
S28855552X2K27G600003O002000
S28855579A3K27G600005IB002000CVS   0000056400Y
S28855589A4K27GA0000B4B002000FDX   0000877000Y
S28855590A8K27G600002RS000500MZZ   0000493800Y
S28855590A8K27G600002SB000100MVV   0000806300Y
S28855596A1K27GA00004YB002000AFL   0000095000Y
S28855601A5K27GA00003LB002000HNZ   0000060600Y
S28855613X2K27G600003Y002000
S28855635A2K27G6000041B002000BBT   0000044200Y
S28855641A5K27GA00003MB002000HOT   0000062300Y
S28855656X3K27G600005D002000
S28855668A6K27GA00006OB002000JCI   0000044300Y
S28855673A3K27G600005JB002000COH   0000046700Y
S28855696A7K27GA00002TB002000LXK   0000335800Y
S28855700AAK27GA0000TLS000500SPY   0001426000Y
S28855702A4K27GA0000B5B002000EIX   0000066800Y
S28855717A4K27GA0000B6B002000FDX   0000877800Y
S28855717A7K27GA00002UB002000MAR   0000330600Y
S28855738A5K27GA00003NB002000HNZ   0000061400Y
S28855748X6K27GA00006I002000
S28855756A5K27GA00003OB002000HOT   0000063100Y
S28856093AAK27GA0000TMB002000SPY   0001425400Y
S28856093XAK27GA0000Q8000500
S28856093AAK27GA0000Q8S000500SPY   0001426000Y
S28856093XAK27GA0000TI001000
S28856094AAK27GA0000TNB001000SPY   0001425400Y
S28856094ABK27GA0000GGB001000SSO   0000764100Y
S28856243XAK27GA0000EB001000
S28856243AAK27GA0000EBB001000SPY   0001425500Y
S28856243XAK27GA0000TM002000
S28856243AAK27GA0000TMB002000SPY   0001425500Y
S28856243XAK27GA0000TN001000
S28856243AAK27GA0000TNB001000SPY   0001425500Y
S28856373X5K27GA00002N002000
S28856376X2K27G600003Z002000
S28856411X7K27GA00002R002000
S28856423X7K27GA00002S002000
S28856423AAK27GA0000TOB002000SHLD  0000727400Y
S28856446A7K27GA00002VB002000MMM   0000763100Y
S28856450XCK27GA00002S002000
S28856452A7K27GA00002WB002000MMM   0000763900Y
S28856460AAK27GA0000TPB002000SPLS  0000026000Y
S28856463ABK27GA0000GHB002000UTX   0000104300Y
S28856480XAK27GA0000TG001000
S28856482XBK27GA0000GB001000
S28856484ABK27GA0000GIS001000SSO   0000765300Y
S28856493XAK27GA0000TJ001000
S28856494X1K27GA00004X002000
S28856501X1K27GA00004Y002000
S28856508ABK27GA0000GJB002000UTX   0000105100Y
S28856530AAK27GA0000TQS001000SPY   0001426000Y
S28856528ACK27GA00002TB002000WYE   0000059100Y
S28856552X2K27G600003Q002000
S28856568A1K27GA00004ZB002000ABT   0000078300Y
S28856580A2K27G6000042B002000AXP   0000403500Y
S28856594X4K27GA0000B5002000
S28856599A2K27G6000043B002000CAG   0000028100Y
S28856610X5K27GA00003N002000
S28856611A1K27GA000050B002000ABT   0000077400Y
S28856624X5K27GA00003O002000
S28856629X2K27G600003T002000
S28856632X2K27G6000040002000
S28856645A3K27G600005KB002000CVS   0000058400Y
S28856649A2K27G6000044B002000AXP   0000402700Y
S28856659A2K27G6000045B002000BBT   0000044300Y
S28856666X3K27G600005I002000
S28856680A3K27G600005LB002000COH   0000046900Y
S28856683A6K27GA00006PB002000JCI   0000046100Y
S28856702X5K27GA00002X002000
S28856704X5K27GA00003L002000
S28856709X5K27GA00003M002000
S28856727A4K27GA0000B7B002000EIX   0000067400Y
S28857099X4K27GA00009K000200
S28857103A4K27GA0000B8S000200DIA   0001299300Y
S28857126A9K27G60000N8S001000QID   0000381900Y
S28857126A9K27G60000N9B001000QLD   0000889100Y
S28857126A9K27G60000NAS002000QQQQ  0000496100Y
S28857126A9K27G60000NBS001000QID   0000382000Y
S28857126X9K27G60000FZ002000
S28857126X9K27G60000NB001000
S28857126A9K27G60000NCB001000QLD   0000889200Y
S28857126X9K27G60000N9001000
S28857126A9K27G60000NDS000100QID   0000382200Y
S28857128A9K27G60000NES002000QQQQ  0000496100Y
S28857132X9K27G60000NC001000
S28857132A9K27G60000NFB001000QLD   0000889300Y
S28857132AAK27GA0000TRS001000SDS   0000548900Y
S28857133XBK27GA0000GE001000
S28857133ABK27GA0000GKB001000SSO   0000764400Y
S28857134A9K27G60000NGB001000QQQQ  0000495400Y
S28857135XAK27GA0000O8000500
S28857135AAK27GA0000O8S000500SPY   0001426100Y
S28857139X9K27G60000NG001000
S28857139X9K27G60000N6002000
S28857150X9K27G60000F6003200
S28857150A9K27G60000F6S003200QQQQ  0000496400Y
S28857151X9K27G60000GG002000
S28857151A9K27G60000NHS002000QQQQ  0000496200Y
S28857151X9K27G60000FO002000
S28857152A9K27G60000NIB002000QQQQ  0000495800Y
S28857152A9K27G60000NJS002000QQQQ  0000496200Y
S28857153X9K27G60000LM001000
S28857153A9K27G60000NKB001000QLD   0000889200Y
S28857166X9K27G60000FH005000
S28857166X9K27G60000EW005000
S28857167A9K27G60000NLB005000QQQQ  0000495800Y
S28857167A9K27G60000NMB005000QQQQ  0000495800Y
S28857168AAK27GA0000TSS001000SPY   0001426100Y
S28857168XAK27GA0000S9001000
S28857170AAK27GA0000TTS001000SPY   0001426100Y
S28857174X4K27GA00003H000200
S28857174A4K27GA00003HB000200DIA   0001298900Y
S28857174X4K27GA0000B0000047
S28857176X4K27GA00008I000100
S28857176A4K27GA0000B9S000100DXD   0000500000Y
S28857177A3K27G600005MB000100DDM   0000801300Y
S28857177X3K27G600003U000100
S28857177A4K27GA0000BAS000047DIA   0001299400Y
S28857183X4K27GA000091000100
S28857184X3K27G600005F000100
S28857185A4K27GA0000BBB000100DXD   0000499000Y
S28857185A3K27G600005NS000100DDM   0000802800Y
S28857185X6K27GA00002B000500
S28857185A6K27GA00002BS000500IWM   0000737200Y
S28857206X4K27GA0000BA000047
S28857208X9K27G60000EO002000
S28857208A9K27G60000EOB002000QQQQ  0000495800Y
S28857208A4K27GA0000BCS000047DIA   0001299100Y
S28857213X3K27G600005N000100
S28857215A3K27G600005OS000100DDM   0000802900Y
S28857223X3K27G600005O000100
S28857223A3K27G600005PS000100DDM   0000802800Y
S28857227X6K27GA00004T000500
S28857227A6K27GA00004TB000500IWM   0000736700Y
S28857230ABK27GA0000GLB000100UWM   0000542700Y
S28857230ABK27GA0000GMS000100TWM   0000701700Y
S28857230XBK27GA0000GD000100
S28857230XBK27GA0000E0000100
S28857232XBK27GA0000GM000100
S28857231X6K27GA00004T000500
S28857231A6K27GA00004TB000500IWM   0000736300Y
S28857234ABK27GA0000GNS000100TWM   0000702000Y
S28857235XBK27GA0000GL000100
S28857235XBK27GA0000GG001000
S28857235ABK27GA0000GOB001000SSO   0000764200Y
S28857235XBK27GA0000GN000100
S28857234X6K27GA00004T000500
S28857234A6K27GA00004TB000500IWM   0000736700Y
S28857237ABK27GA0000GPB000100UWM   0000542700Y
S28857235A6K27GA00006QB000100IWM   0000736200Y
S28857235X6K27GA00006Q000100
S28857235X6K27GA00004T000500
S28857235A6K27GA00004TB000500IWM   0000736300Y
S28857237ABK27GA0000GQS000100TWM   0000702000Y
S28857239XBK27GA0000GQ000100
S28857239XBK27GA0000GP000100
S28857241ABK27GA0000GRS000100TWM   0000702200Y
S28857244X6K27GA00004T000500
S28857244A6K27GA00004TB000500IWM   0000736700Y
S28857246XBK27GA0000GR000100
S28857246ABK27GA0000GSS000100TWM   0000702000Y
S28857247ABK27GA0000GTB000100UWM   0000542700Y
S28857246X6K27GA00004T000500
S28857246A6K27GA00004TB000500IWM   0000736300Y
S28857256X6K27GA00004T000500
S28857256A6K27GA00004TB000500IWM   0000736700Y
S28857258XBK27GA0000GT000100
S28857258XBK27GA0000GS000100
S28857258XBK27GA0000F4000100
S28857258XBK27GA0000EV000100
S28857258XBK27GA0000F6000100
S28857256A6K27GA00006RS002000IWM   0000737200Y
S28857259ABK27GA0000GUB000100UWM   0000542700Y
S28857260ABK27GA0000GVB000100TWM   0000700500Y
S28857260ABK27GA0000GWS000100TWM   0000702000Y
S28857260ABK27GA0000GXB000100TWM   0000700600Y
S28857260ABK27GA0000GYS000100UWM   0000543700Y
S28857298X9K27G60000NM005000
S28857298X9K27G60000NL005000
S28857301A9K27G60000NNB005000QQQQ  0000495400Y
S28857301A9K27G60000NOB005000QQQQ  0000495400Y
S28857344X1K27GA000014002000
S28857378X6K27GA00006N002000
S28857384X5K27GA000015002000
S28857384X5K27GA000019002000
S28857395XBK27GA0000BK002000
S28857402XBK27GA0000GJ002000
S28857415XBK27GA0000GH002000
S28857423X1K27GA00004Z002000
S28857430XAK27GA0000TO002000
S28857429XCK27GA00002T002000
S28857437A5K27GA00003PS000100GOOG  0005793400Y
S28857443X9K27G60000NN005000
S28857443X9K27G60000EY005000
S28857443X9K27G60000NO005000
S28857443X9K27G60000FK005000
S28857443A9K27G60000NPB005000QQQQ  0000495800Y
S28857443A9K27G60000NQB005000QQQQ  0000495800Y
S28857444A9K27G60000NRS005000QQQQ  0000496300Y
S28857445A9K27G60000NSS005000QQQQ  0000496300Y
S28857446X3K27G600005C002000
S28857451X9K27G60000ET002000
S28857451A9K27G60000ETS002000QQQQ  0000496200Y
S28857452X9K27G60000GA002000
S28857456X1K27GA000050002000
S28857457X2K27G6000041002000
S28857466X1K27GA00001O002000
S28857472X3K27G600005J002000
S28857492X4K27GA0000B7002000
S28857501X3K27G600005K002000
S28857501XAK27GA0000SS002000
S28857535A2K27G6000046B002000BMY   0000026500Y
S28857536X6K27GA00006O002000
S28857549A5K27GA00003QB002000GM    0000174500Y
S28857557A7K27GA00002XB002000LMT   0000164300Y
S28857561A7K27GA00002YB002000LMT   0000165100Y
S28857575A1K27GA000051B002000AFL   0000098000Y
S28857584A2K27G6000047B002000BDX   0000761100Y
S28857590A2K27G6000048B002000CAG   0000028000Y
S28857591ACK27GA00002UB002000WYE   0000061200Y
S28857595X6K27GA00004T000500
S28857599XBK27GA0000GU000100
S28857599XBK27GA0000GW000100
S28857601ABK27GA0000GZS000100TWM   0000702200Y
S28857600A6K27GA00006SB000500IWM   0000736700Y
S28857603ABK27GA0000H0B000100UWM   0000542700Y
S28857603XBK27GA0000GZ000100
S28857603ABK27GA0000H1S000100TWM   0000702000Y
S28857606A3K27G600005QB002000CVS   0000058800Y
S28857605X6K27GA00006S000500
S28857605A6K27GA00006SB000500IWM   0000736300Y
S28857609XBK27GA0000H0000100
S28857609XBK27GA0000H1000100
S28857609A1K27GA000052B002000AFL   0000098800Y
S28857611ABK27GA0000H2S000100TWM   0000702200Y
S28857615X6K27GA00006S000500
S28857615A6K27GA00006SB000500IWM   0000736700Y
S28857618A5K27GA00003RB002000HMY   0000085100Y
S28857619ABK27GA0000H3B000100UWM   0000542700Y
S28857619XBK27GA0000H2000100
S28857619ABK27GA0000H4S000100TWM   0000702000Y
S28857621A2K27G6000049B002000BDX   0000761900Y
S28857626A5K27GA00003SB002000HNZ   0000063100Y
S28857626X6K27GA00006S000500
S28857626A6K27GA00006SB000500IWM   0000736300Y
S28857629XBK27GA0000H3000100
S28857629XBK27GA0000H4000100
S28857631ABK27GA0000H5S000100TWM   0000702200Y
S28857630X6K27GA00006S000500
S28857630A6K27GA00006SB000500IWM   0000736700Y
S28857633ABK27GA0000H6B000100UWM   0000542700Y
S28857633ABK27GA0000H7S000100TWM   0000702000Y
S28857633XBK27GA0000H5000100
S28857635X6K27GA00006S000500
S28857635A6K27GA00006SB000500IWM   0000736300Y
S28857639XBK27GA0000H6000100
S28857639XBK27GA0000H7000100
S28857638A4K27GA0000BDB002000EIX   0000069600Y
S28857639A6K27GA00006TB000100IWM   0000736200Y
S28857641ABK27GA0000H8S000100TWM   0000702200Y
S28857639X6K27GA00006T000100
S28857640X6K27GA00006S000500
S28857640A6K27GA00006SB000500IWM   0000736700Y
S28857643ABK27GA0000H9B000100UWM   0000542700Y
S28857643ABK27GA0000HAS000100TWM   0000702000Y
S28857643XBK27GA0000H8000100
S28857646A5K27GA00003TB002000HOT   0000065000Y
S28857646X6K27GA00006S000500
S28857646A6K27GA00006SB000500IWM   0000736300Y
S28857646A6K27GA00006US010000IOM   0000038400Y
S28857649XBK27GA0000H9000100
S28857649XBK27GA0000HA000100
S28857649A5K27GA00003UB002000HNZ   0000063900Y
S28857649A6K27GA00006VB000100IWM   0000736200Y
S28857649X6K27GA00006V000100
S28857651ABK27GA0000HBS000100TWM   0000702200Y
S28857650X6K27GA00006S000500
S28857650A6K27GA00006SB000500IWM   0000736700Y
S28857653XBK27GA0000HB000100
S28857653ABK27GA0000HCS000100TWM   0000702000Y
S28857653ABK27GA0000HDB000100UWM   0000542700Y
S28857655X6K27GA00006S000500
S28857655A6K27GA00006SB000500IWM   0000736300Y
S28857659XBK27GA0000HD000100
S28857659XBK27GA0000HC000100
S28857659A7K27GA00002ZB002000MAS   0000167500Y
S28857661ABK27GA0000HES000100TWM   0000702200Y
S28857663A5K27GA00003VB002000HOT   0000065800Y
S28857664X6K27GA00006S000500
S28857664A6K27GA00006SB000500IWM   0000736700Y
S28857665X6K27GA00006S000500
S28857665A6K27GA00006SB000500IWM   0000736300Y
S28857667ABK27GA0000HFB000100UWM   0000542700Y
S28857667ABK27GA0000HGS000100TWM   0000702000Y
S28857667XBK27GA0000HE000100
S28857669XBK27GA0000HF000100
S28857669XBK27GA0000HG000100
S28857671ABK27GA0000HHS000100TWM   0000702200Y
S28857674X6K27GA00006S000500
S28857674A6K27GA00006SB000500IWM   0000736700Y
S28857676A7K27GA000030B002000MAT   0000184100Y
S28857677ABK27GA0000HIB000100UWM   0000542700Y
S28857675X6K27GA00006S000500
S28857675A6K27GA00006SB000500IWM   0000736300Y
S28857677ABK27GA0000HJS000100TWM   0000702000Y
S28857677XBK27GA0000HH000100
S28857679XBK27GA0000HI000100
S28857679XBK27GA0000HJ000100
S28857681ABK27GA0000HKS000100TWM   0000702200Y
S28857686X6K27GA00006S000500
S28857686A6K27GA00006SB000500IWM   0000736700Y
S28857690X6K27GA00006S000500
S28857690A6K27GA00006SB000500IWM   0000736300Y
S28857693A7K27GA000031B002000KMB   0000611900Y
S28857696X6K27GA00006S000500
S28857696A6K27GA00006SB000500IWM   0000736700Y
S28857706X6K27GA00006S000500
S28857706A6K27GA00006SB000500IWM   0000736300Y
S28857716X6K27GA00006S000500
S28857716A6K27GA00006SB000500IWM   0000736700Y
S28857720A7K27GA000032B002000KMX   0000186900Y
S28857726X6K27GA00006S000500
S28857726A6K27GA00006SB000500IWM   0000736300Y
S28857736X6K27GA00006S000500
S28857736A6K27GA00006SB000500IWM   0000736700Y
S28857746X6K27GA00006S000500
S28857746A6K27GA00006SB000500IWM   0000736300Y
S28857756X6K27GA00006S000500
S28857756A6K27GA00006SB000500IWM   0000736700Y
S28857766X6K27GA00006S000500
S28857766A6K27GA00006SB000500IWM   0000736300Y
S28857776X6K27GA00006S000500
S28857776A6K27GA00006SB000500IWM   0000736700Y
S28857778A9K27G60000NTB000500QQQQ  0000495200Y
S28857786X6K27GA00006S000500
S28857786A6K27GA00006SB000500IWM   0000736300Y
S28857796X6K27GA00006S000500
S28857796A6K27GA00006SB000500IWM   0000736700Y
S28857806X6K27GA00006S000500
S28857806A6K27GA00006SB000500IWM   0000736300Y
S28857816X6K27GA00006S000500
S28857816A6K27GA00006SB000500IWM   0000736700Y
S28857826X6K27GA00006S000500
S28857826A6K27GA00006SB000500IWM   0000736300Y
S28857836X6K27GA00006S000500
S28857836A6K27GA00006SB000500IWM   0000736700Y
S28857846X6K27GA00006S000500
S28857846A6K27GA00006SB000500IWM   0000736300Y
S28857856X6K27GA00006S000500
S28857856A6K27GA00006SB000500IWM   0000736700Y
S28857866X6K27GA00006S000500
S28857866A6K27GA00006SB000500IWM   0000736300Y
S28857876X6K27GA00006S000500
S28857876A6K27GA00006SB000500IWM   0000736700Y
S28857883A9K27G60000NUB002000QQQQ  0000495600Y
S28857883X9K27G60000IV002000
S28857883X9K27G60000IW002000
S28857886X6K27GA00006S000500
S28857886A6K27GA00006SB000500IWM   0000736300Y
S28857896X6K27GA00006S000500
S28857896A6K27GA00006SB000500IWM   0000736700Y
S28857906X6K27GA00006S000500
S28857906A6K27GA00006SB000500IWM   0000736300Y
S28857916X6K27GA00006S000500
S28857916A6K27GA00006SB000500IWM   0000736700Y
S28857926X6K27GA00006S000500
S28857926A6K27GA00006SB000500IWM   0000736300Y
S28857936X6K27GA00006S000500
S28857936A6K27GA00006SB000500IWM   0000736700Y
S28857946X6K27GA00006S000500
S28857946A6K27GA00006SB000500IWM   0000736300Y
S28857956X6K27GA00006S000500
S28857956A6K27GA00006SB000500IWM   0000736700Y
S28857989X9K27G60000NR005000
S28857989X9K27G60000NP005000
S28857989X9K27G60000NS005000
S28857989A9K27G60000NVS005000QQQQ  0000495900Y
S28857990A9K27G60000NWS005000QQQQ  0000495900Y
S28857990A9K27G60000NXS002000QQQQ  0000495900Y
S28857991A9K27G60000NYB005000QQQQ  0000495400Y
S28857991X9K27G60000ET002000
S28857991A9K27G60000ETS002000QQQQ  0000495900Y
S28857994X9K27G60000NU002000
S28858026X9K27G60000NY005000
S28858027A9K27G60000NZB005000QQQQ  0000495800Y
S28858028A9K27G60000O0S002000QQQQ  0000496000Y
S28858036X9K27G60000NV005000
S28858037X9K27G60000NW005000
S28858038X9K27G60000O0002000
S28858038A9K27G60000O1S005000QQQQ  0000495900Y
S28858038A9K27G60000O2S005000QQQQ  0000495900Y
S28858048XAK27GA0000E6001000
S28858048AAK27GA0000E6S001000SPY   0001426100Y
S28858048XAK27GA0000E8001000
S28858048AAK27GA0000E8B001000SPY   0001425600Y
S28858048XAK27GA0000FG000500
S28858048AAK27GA0000FGB000500SPY   0001425500Y
S28858048XAK27GA0000F7000500
S28858048AAK27GA0000F7B000500SPY   0001425500Y
S28858048XAK27GA0000NZ000500
S28858048AAK27GA0000NZS000500SPY   0001426100Y
S28858049XAK27GA0000Q6002000
S28858049AAK27GA0000Q6B002000SPY   0001425600Y
S28858049X4K27GA0000BC000047
S28858049XAK27GA0000QD000200
S28858050AAK27GA0000TUB001000SPY   0001425600Y
S28858051X3K27G600005P000100
S28858053A3K27G600005RS000100DDM   0000802900Y
S28858053A4K27GA0000BES000047DIA   0001299400Y
S28858053X4K27GA00009H000100
S28858053X3K27G600005R000100
S28858055A3K27G600005SS000100DDM   0000803000Y
S28858055A4K27GA0000BFB000100DOG   0000596800Y
S28858077ABK27GA0000HLB000100UWM   0000542700Y
S28858077XBK27GA0000HK000100
S28858077ABK27GA0000HMS000100TWM   0000702000Y
S28858076X6K27GA00006S000500
S28858076A6K27GA00006SB000500IWM   0000736300Y
S28858078X6K27GA00006S000500
S28858078A6K27GA00006SB000500IWM   0000736700Y
S28858079A6K27GA00006WB002000IWM   0000736600Y
S28858079X6K27GA000056002000
S28858080X6K27GA00006S000500
S28858080A6K27GA00006SB000500IWM   0000736300Y
S28858084XAK27GA0000PK003000
S28858084XAK27GA0000FI000500
S28858084AAK27GA0000FIB000500SPY   0001425600Y
S28858084XAK27GA0000F5000500
S28858084AAK27GA0000F5B000500SPY   0001425600Y
S28858084XAK27GA0000Q4003000
S28858084XAK27GA0000NY000500
S28858084AAK27GA0000NYS000500SPY   0001426200Y
S28858084XAK27GA0000Q7001000
S28858084XAK27GA0000PL003000
S28858084XAK27GA0000T4002000
S28858084XAK27GA0000QB000500
S28858084AAK27GA0000QBS000500SPY   0001426200Y
S28858084X4K27GA0000B1000200
S28858084X4K27GA000062000200
S28858084A4K27GA000062B000200DIA   0001299000Y
S28858084AAK27GA0000TVB003000SPY   0001425600Y
S28858084XAK27GA0000Q9003000
S28858084XAK27GA0000E9001000
S28858084AAK27GA0000E9S001000SPY   0001426200Y
S28858084XAK27GA0000TT001000
S28858085AAK27GA0000TWB002000SPY   0001425600Y
S28858085XAK27GA0000SP001000
S28858085XAK27GA0000SO001000
S28858085AAK27GA0000TXB003000SPY   0001425600Y
S28858085AAK27GA0000TYS003000SPY   0001426600Y
S28858086AAK27GA0000TZB002000SPY   0001425600Y
S28858086AAK27GA0000U0S001000SPY   0001426100Y
S28858086ABK27GA0000HNB001000SSO   0000764600Y
S28858086AAK27GA0000U1S003000SPY   0001426600Y
S28858086XAK27GA0000PF001000
S28858086XBK27GA0000GK001000
S28858086AAK27GA0000U2S001000SDS   0000548800Y
S28858086XAK27GA0000QS001000
S28858087X3K27G600003X000100
S28858086A4K27GA0000BGS000100DXD   0000499900Y
S28858086A4K27GA0000BHS000100DOG   0000598200Y
S28858086X4K27GA00008W000100
S28858087X4K27GA00003S000100
S28858087XBK27GA0000GI001000
S28858087A3K27G600005TB000100DDM   0000801500Y
S28858087XBK27GA0000HL000100
S28858087XAK27GA0000E7001000
S28858087AAK27GA0000E7B001000SPY   0001425600Y
S28858086X6K27GA00006S000500
S28858086A6K27GA00006SB000500IWM   0000736700Y
S28858087XAK27GA0000QG000200
S28858087XBK27GA0000HM000100
S28858087AAK27GA0000U3B001000SPY   0001425600Y
S28858088AAK27GA0000U4S001000SPY   0001426200Y
S28858088A4K27GA0000BIS000200DIA   0001299500Y
S28858088X6K27GA00006S000500
S28858088A6K27GA00006SB000500IWM   0000736300Y
S28858089ABK27GA0000HOS001000SSO   0000765400Y
S28858089ABK27GA0000HPB000100UWM   0000542700Y
S28858089ABK27GA0000HQS000100TWM   0000702000Y
S28858091XAK27GA0000TL000500
S28858091AAK27GA0000U5B000500SPY   0001425600Y
S28858091XAK27GA0000TK000500
S28858092XAK27GA0000GG000100
S28858092XBK27GA0000HO001000
S28858094ABK27GA0000HRS001000SSO   0000765500Y
S28858094AAK27GA0000U6B000100SH    0000618200Y
S28858095ABK27GA0000HSS001000SSO   0000766400Y
S28858095X6K27GA00006S000500
S28858095A6K27GA00006SB000500IWM   0000736700Y
S28858097XBK27GA0000HP000100
S28858097XBK27GA0000HQ000100
S28858099ABK27GA0000HTB000100UWM   0000542700Y
S28858100ABK27GA0000HUS000100TWM   0000702000Y
S28858102X6K27GA00005K002000
S28858105XAK27GA0000TW002000
S28858106AAK27GA0000U7B001000SPY   0001425500Y
S28858121A8K27G600002TS000500MZZ   0000493700Y
S28858121A8K27G600002UB000100MVV   0000806500Y
S28858120X9K27G60000O1005000
S28858121X9K27G60000G3002000
S28858121A9K27G60000G3S002000QQQQ  0000496400Y
S28858121X9K27G60000O2005000
S28858121X9K27G60000ET002000
S28858121A9K27G60000ETS002000QQQQ  0000496200Y
S28858121X9K27G60000NX002000
S28858122A9K27G60000O3S005000QQQQ  0000496300Y
S28858122A9K27G60000O4S005000QQQQ  0000496300Y
S28858122XAK27GA0000TZ002000
S28858126X9K27G60000G6002000
S28858126A9K27G60000G6B002000QQQQ  0000495800Y
S28858132A9K27G60000O5S002000QQQQ  0000496100Y
S28858133AAK27GA0000U8B002000SPY   0001425600Y
S28858133XAK27GA0000U7001000
S28858133XAK27GA0000TS001000
S28858133AAK27GA0000U9S001000SPY   0001426200Y
S28858133XAK27GA0000T7001000
S28858133XAK27GA0000U9001000
S28858135X8K27G600002O000100
S28858135X8K27G600002N000100
S28858135X8K27G6000026000500
S28858135AAK27GA0000UAS001000SPY   0001426300Y
S28858135AAK27GA0000UBS001000SPY   0001426300Y
S28858136A8K27G600002VB000500MZZ   0000491300Y
S28858137A8K27G600002WS000100MVV   0000809800Y
S28858153XAK27GA0000IC001000
S28858154XBK27GA0000HR001000
S28858155AAK27GA0000UCB001000SDS   0000547400Y
S28858156ABK27GA0000HVS001000SSO   0000765600Y
S28858164XAK27GA0000PY000100
S28858164AAK27GA0000UDB000100SPY   0001424600Y
S28858184XBK27GA0000HS001000
S28858189XAK27GA0000TV003000
S28858189AAK27GA0000TVB003000SPY   0001425700Y
S28858189XAK27GA0000TX003000
S28858189AAK27GA0000TXB003000SPY   0001425700Y
S28858189XAK27GA0000E7001000
S28858189AAK27GA0000E7B001000SPY   0001425700Y
S28858189XAK27GA0000U3001000
S28858189AAK27GA0000U3B001000SPY   0001425700Y
S28858204X9K27G60000F5003200
S28858204A9K27G60000F5B003200QQQQ  0000495800Y
S28858232XAK27GA0000DT000100
S28858232AAK27GA0000UES000100SH    0000618800Y
S28858233XAK27GA0000PH001000
S28858233AAK27GA0000UFS001000SDS   0000548700Y
S28858293AAK27GA0000UGS000500SPY   0001426200Y
S28858402X5K27GA00002S002000
S28858402X7K27GA00002X002000
S28858404X7K27GA00002Q002000
S28858407X9K27G60000MU002000
S28858409X7K27GA00002Y002000
S28858423A1K27GA000053B002000AMZN  0000798900Y
S28858424XCK27GA00002U002000
S28858438A5K27GA00003WB002000GS    0001817600Y
S28858443X1K27GA000052002000
S28858460X2K27G6000043002000
S28858479X4K27GA0000BD002000
S28858490ABK27GA0000HWB002000TGT   0000518000Y
S28858489A6K27GA00006XB002000IMCL  0000340900Y
S28858491X5K27GA000031002000
S28858511ABK27GA0000HXB002000UTX   0000108300Y
S28858512X5K27GA00003U002000
S28858525X5K27GA00003V002000
S28858534AAK27GA0000UHB002000SHLD  0000732500Y
S28858539X6K27GA00006P002000
S28858562A5K27GA00003XB002000GS    0001818400Y
S28858560ACK27GA00002VB002000WYE   0000061500Y
S28858577A3K27G600005UB002000CTSH  0000041100Y
S28858594AAK27GA0000UIB002000SNDK  0000224800Y
S28858610ABK27GA0000HYB002000UTX   0000109100Y
S28858612X1K27GA000051002000
S28858612A1K27GA000054B002000ABT   0000080500Y
S28858647A1K27GA000055B002000ABT   0000081300Y
S28858649X2K27G6000045002000
S28858657A1K27GA000056B002000ACF   0000118500Y
S28858664X3K27G600005L002000
S28858671X3K27G600005Q002000
S28858684A2K27G600004AB002000BBT   0000047000Y
S28858698A4K27GA0000BJB002000EIX   0000070200Y
S28858706X5K27GA00003S002000
S28858707A3K27G600005VB002000COH   0000049700Y
S28858718X5K27GA00003T002000
S28858733A3K27G600005WB002000CVS   0000060800Y
S28858762A6K27GA00006YB002000JCI   0000047200Y
S28858773A7K27GA000033B002000MAY   0000091400Y
S28858792A7K27GA000034B002000LEN   0000181700Y
S28859002A9K27G60000O6B004000QQQQ  0000495600Y
S28859143XAK27GA0000O2000500
S28859143AAK27GA0000O2S000500SPY   0001426300Y
S28859156X9K27G60000F8003200
S28859156A9K27G60000F8S003200QQQQ  0000496500Y
S28859157X9K27G60000KH002000
S28859158XBK27GA0000HN001000
S28859158ABK27GA0000HZB001000SSO   0000764700Y
S28859157XAK27GA0000F2000500
S28859157AAK27GA0000F2B000500SPY   0001425700Y
S28859157A9K27G60000O7B002000QQQQ  0000495800Y
S28859159A9K27G60000O8S001000QID   0000381800Y
S28859159A9K27G60000O9B001000QLD   0000889500Y
S28859159X9K27G60000KL001000
S28859160A9K27G60000OAS000100QID   0000382100Y
S28859162X9K27G60000O9001000
S28859162A9K27G60000OBB001000QLD   0000889700Y
S28859163A9K27G60000OCS000100QID   0000382000Y
S28859174X9K27G60000O7002000
S28859174A9K27G60000O7B002000QQQQ  0000495900Y
S28859182A9K27G60000ODB001000QLD   0000889600Y
S28859182X9K27G60000M0001000
S28859192XAK27GA0000F2000500
S28859192AAK27GA0000F2B000500SPY   0001425300Y
S28859197X6K27GA000026000500
S28859197A6K27GA000026S000500IWM   0000737300Y
S28859207XBK27GA0000GY000100
S28859207XBK27GA0000F5000100
S28859207XBK27GA0000GX000100
S28859206A6K27GA00006ZS002000IWM   0000737300Y
S28859209ABK27GA0000I0S000100UWM   0000543800Y
S28859209ABK27GA0000I1B000100TWM   0000700300Y
S28859210ABK27GA0000I2B000100TWM   0000700400Y
S28859383X6K27GA00004I002000
S28859385XAK27GA0000UH002000
S28859388XBK27GA0000HX002000
S28859388X1K27GA00003L002000
S28859408X2K27G6000046002000
S28859410X1K27GA00001L002000
S28859410XCK27GA00002V002000
S28859429X1K27GA000054002000
S28859437XBK27GA0000CK002000
S28859440A7K27GA000035B002000LPNT  0000201200Y
S28859446X2K27G6000031002000
S28859451XBK27GA0000HY002000
S28859452X2K27G6000048002000
S28859460X4K27GA0000BJ002000
S28859470A5K27GA00003YB002000GM    0000175500Y
S28859472A9K27G60000OEB002000PDLI  0000020000Y
S28859487A7K27GA000036B002000LMT   0000170300Y
S28859504X1K27GA000055002000
S28859535A7K27GA000037B002000LMT   0000171100Y
S28859552X2K27G600002P002000
S28859565AAK27GA0000UJB002500SPY   0001425600Y
S28859576A1K27GA000057B002000AFL   0000101700Y
S28859582X2K27G600002Z002000
S28859591A2K27G600004BB002000BBT   0000047200Y
S28859605A3K27G600005XB002000COH   0000049900Y
S28859617A3K27G600005YB002000CVS   0000061100Y
S28859624ACK27GA00002WB002000WYE   0000063600Y
S28859630X3K27G600005W002000
S28859634A5K27GA00003ZB002000HNZ   0000065700Y
S28859651A5K27GA000040B002000HOT   0000067600Y
S28859663A1K27GA000058B002000AFL   0000102500Y
S28859675A2K27G600004CB002000CAG   0000030100Y
S28859676A7K27GA000038B002000MCD   0000588000Y
S28859705A4K27GA0000BKB002000EIX   0000072400Y
S28859716A5K27GA000041B002000HMY   0000086100Y
S28859724A5K27GA000042B002000HNZ   0000066500Y
S28859732A5K27GA000043B002000HOT   0000068400Y
S28859948ABK27GA0000I3B001000SSO   0000764500Y
S28860395X7K27GA000037002000
S28860398X2K27G600002G002000
S28860403XAK27GA0000TP002000
S28860406XCK27GA00002W002000
S28860416X7K27GA000036002000
S28860421AAK27GA0000UKB002000SHLD  0000735600Y
S28860421X1K27GA000058002000
S28860437X1K27GA000049002000
S28860437X1K27GA000057002000
S28860445X1K27GA000047002000
S28860448X2K27G600002X002000
S28860468X2K27G6000030002000
S28860469A1K27GA000059B002000APOL  0000407500Y
S28860471X2K27G600002U002000
S28860472X2K27G600004A002000
S28860490X3K27G600005Y002000
S28860506A2K27G600004DB002000BMY   0000028400Y
S28860508X5K27GA00003Z002000
S28860525X5K27GA000040002000
S28860539A1K27GA00005AB002000APPX  0000094500Y
S28860544X2K27G600002W002000
S28860545X6K27GA00006Y002000
S28860556X3K27G600005V002000
S28860578ABK27GA0000I4B002000TGT   0000518900Y
S28860582X4K27GA0000BK002000
S28860595X5K27GA000042002000
S28860615X5K27GA000043002000
S28860620A6K27GA000070B002000JNJ   0000640200Y
S28860634ABK27GA0000I5B002000UTX   0000112300Y
S28860635ABK27GA0000I6B002000UTX   0000113100Y
S28860644ACK27GA00002XB002000WYE   0000064000Y
S28860650A1K27GA00005BB002000ABT   0000084400Y
S28860664A1K27GA00005CB002000ABT   0000083600Y
S28860665A2K27G600004EB002000BK    0000426300Y
S28860682A2K27G600004FB002000BNI   0001058800Y
S28860682A2K27G600004GB002000BNI   0001059600Y
S28860689A2K27G600004HB002000CAG   0000029900Y
S28860699A3K27G600005ZB002000CVS   0000063100Y
S28860709A4K27GA0000BLB002000EIX   0000073000Y
S28860718A6K27GA000071B002000JCI   0000049900Y
S28860736XBK27GA0000GA000500
S28860739A7K27GA000039B002000MDY   0001573900Y
S28860757A7K27GA00003AB002000MEE   0000623300Y
S28861085XAK27GA0000O2000500
S28861085AAK27GA0000O2S000500SPY   0001425900Y
S28861085X4K27GA0000BI000200
S28861085XAK27GA0000TY003000
S28861085XAK27GA0000TX003000
S28861085XAK27GA0000U1003000
S28861085XAK27GA0000TV003000
S28861086AAK27GA0000ULS003000SPY   0001426000Y
S28861086AAK27GA0000UMS003000SPY   0001426000Y
S28861086X4K27GA000062000200
S28861086A4K27GA000062B000200DIA   0001298700Y
S28861086XAK27GA0000QB000500
S28861086AAK27GA0000QBS000500SPY   0001425900Y
S28861086XAK27GA0000U8002000
S28861086AAK27GA0000UNS002000SPY   0001426100Y
S28861087XBK27GA0000I3001000
S28861087XAK27GA0000F5000500
S28861087AAK27GA0000F5B000500SPY   0001425200Y
S28861087XAK27GA0000E7001000
S28861087AAK27GA0000E7B001000SPY   0001425300Y
S28861087AAK27GA0000UOB003000SPY   0001425000Y
S28861087XAK27GA0000U3001000
S28861087AAK27GA0000UPB003000SPY   0001425000Y
S28861088AAK27GA0000UQB002000SPY   0001425500Y
S28861089AAK27GA0000URB001000SPY   0001425300Y
S28861089XAK27GA0000Q6002000
S28861091XAK27GA0000UJ002500
S28861091AAK27GA0000USB002500SPY   0001425500Y
S28861092XAK27GA0000U5000500
S28861092AAK27GA0000UTB000500SPY   0001425400Y
S28861092XAK27GA0000UG000500
S28861092A4K27GA0000BMS000200DIA   0001299200Y
S28861093XAK27GA0000UE000100
S28861093XAK27GA0000UF001000
S28861094X3K27G600005T000100
S28861093XBK27GA0000HZ001000
S28861093X4K27GA0000BG000100
S28861093X4K27GA0000BH000100
S28861095ABK27GA0000I7B001000SSO   0000764600Y
S28861112XAK27GA0000UQ001000
S28861120A4K27GA0000BNB000100DOG   0000596900Y
S28861120A3K27G6000060S000100DDM   0000802800Y
S28861122XAK27GA0000F5000500
S28861122AAK27GA0000F5B000500SPY   0001425600Y
S28861122X4K27GA000062000200
S28861122A4K27GA000062B000200DIA   0001299000Y
S28861122XAK27GA0000E7001000
S28861122AAK27GA0000E7B001000SPY   0001425700Y
S28861122XAK27GA0000QB000500
S28861122AAK27GA0000QBS000500SPY   0001426200Y
S28861122XAK27GA0000UL003000
S28861122XAK27GA0000UO003000
S28861122XAK27GA0000UR001000
S28861122XAK27GA0000UP003000
S28861122XAK27GA0000UM003000
S28861122AAK27GA0000UUB003000SPY   0001425600Y
S28861122AAK27GA0000UVB003000SPY   0001425600Y
S28861122XAK27GA0000UN002000
S28861123AAK27GA0000UWB001000SPY   0001425700Y
S28861123AAK27GA0000UXB002000SPY   0001425600Y
S28861124A4K27GA0000BOS000100DOG   0000598200Y
S28861124AAK27GA0000UYS003000SPY   0001426600Y
S28861124A4K27GA0000BPS000100DXD   0000499900Y
S28861124A3K27G6000061B000100DDM   0000801500Y
S28861124AAK27GA0000UZS003000SPY   0001426600Y
S28861124AAK27GA0000V0S002000SPY   0001426200Y
S28861133AAK27GA0000V1S001000SDS   0000548700Y
S28861134AAK27GA0000V2S000100SH    0000618800Y
S28861135XAK27GA0000UB001000
S28861135AAK27GA0000V3S001000SPY   0001426100Y
S28861136XAK27GA0000UA001000
S28861140X4K27GA000062000200
S28861140A4K27GA000062B000200DIA   0001298700Y
S28861142X4K27GA000062000200
S28861142A4K27GA000062B000200DIA   0001299000Y
S28861142XAK27GA0000O2000500
S28861142AAK27GA0000O2S000500SPY   0001426300Y
S28861142X4K27GA0000BO000100
S28861143X3K27G6000061000100
S28861142X4K27GA0000BP000100
S28861143X4K27GA0000BN000100
S28861143X4K27GA0000BM000200
S28861143X3K27G6000060000100
S28861143XAK27GA0000UX002000
S28861144ABK27GA0000I8B001000SSO   0000764700Y
S28861144XBK27GA0000I7001000
S28861144A4K27GA0000BQS000100DOG   0000598200Y
S28861145A3K27G6000062B000100DDM   0000801500Y
S28861144A4K27GA0000BRS000100DXD   0000499900Y
S28861148A4K27GA0000BSS000200DIA   0001299500Y
S28861155XAK27GA0000V3001000
S28861183X6K27GA000026000500
S28861183A6K27GA000026S000500IWM   0000736900Y
S28861185XAK27GA0000V0002000
S28861186ABK27GA0000I9S000100UWM   0000543700Y
S28861186ABK27GA0000IAB000100TWM   0000700700Y
S28861186ABK27GA0000IBB000100TWM   0000700600Y
S28861186AAK27GA0000V4S002000SPY   0001426300Y
S28861194A4K27GA0000BTB000100DOG   0000596900Y
S28861195A3K27G6000063S000100DDM   0000802800Y
S28861231X6K27GA000026000500
S28861231A6K27GA000026S000500IWM   0000737300Y
S28861234X9K27G60000F8003200
S28861234A9K27G60000F8S003200QQQQ  0000496000Y
S28861237XBK27GA0000I9000100
S28861237XBK27GA0000IB000100
S28861237XBK27GA0000IA000100
S28861313AAK27GA0000V5B005000SPY   0001425500Y
S28861315AAK27GA0000V6S000500SPY   0001426200Y
S28861315XAK27GA0000UT000500
S28861355XAK27GA0000O2000500
S28861355AAK27GA0000O2S000500SPY   0001425900Y
S28861356X4K27GA0000BS000200
S28861356XAK27GA0000T7001000
S28861356AAK27GA0000V7B001000SPY   0001425600Y
S28861357XAK27GA0000V5005000
S28861357XBK27GA0000I8001000
S28861359ABK27GA0000ICB001000SSO   0000764600Y
S28861362A4K27GA0000BUS000200DIA   0001299200Y
S28861371X3K27G600005H002000
S28861374X7K27GA00001W002000
S28861388X6K27GA00004Z002000
S28861411X7K27GA00001X002000
S28861421X3K27G600005U002000
S28861429X4K27GA00004Q002000
S28861441XBK27GA0000I5002000
S28861445XBK27GA0000I6002000
S28861454XCK27GA00002X002000
S28861472X1K27GA00005B002000
S28861476X1K27GA00005C002000
S28861480AAK27GA0000V8B002000SPLS  0000029200Y
S28861484X1K27GA00001Y002000
S28861488X2K27G6000044002000
S28861491AAK27GA0000V9B002500SPY   0001425600Y
S28861492XAK27GA0000US002500
S28861497X2K27G600004B002000
S28861509X2K27G6000042002000
S28861519AAK27GA0000VAB000500SPY   0001425600Y
S28861530X3K27G600005X002000
S28861531X2K27G600004C002000
S28861546X4K27GA0000BL002000
S28861548X3K27G600005Z002000
S28861550XAK27GA0000O2000500
S28861550AAK27GA0000O2S000500SPY   0001426300Y
S28861550X4K27GA0000BU000200
S28861551XAK27GA0000V7001000
S28861552XAK27GA0000VA000500
S28861552XAK27GA0000V9002500
S28861553A4K27GA0000BVS000200DIA   0001299500Y
S28861554XBK27GA0000IC001000
S28861554ABK27GA0000IDB001000SSO   0000764700Y
S28861566A2K27G600004IB002000BRL   0000372600Y
S28861572XAK27GA0000O2000500
S28861572AAK27GA0000O2S000500SPY   0001425900Y
S28861572XAK27GA0000UZ003000
S28861572XAK27GA0000UY003000
S28861572X4K27GA0000BV000200
S28861572AAK27GA0000VBS003000SPY   0001426000Y
S28861572AAK27GA0000VCS003000SPY   0001426000Y
S28861573XBK27GA0000ID001000
S28861573XAK27GA0000QB000500
S28861573AAK27GA0000QBS000500SPY   0001425900Y
S28861574XAK27GA0000U4001000
S28861575ABK27GA0000IES001000SSO   0000765500Y
S28861575XBK27GA0000HV001000
S28861575ABK27GA0000IFB001000SSO   0000764600Y
S28861575AAK27GA0000VDS001000SPY   0001425900Y
S28861576XAK27GA0000UW001000
S28861576XAK27GA0000UC001000
S28861576AAK27GA0000VEB001000SDS   0000547500Y
S28861576XAK27GA0000F5000500
S28861576AAK27GA0000F5B000500SPY   0001425200Y
S28861582XAK27GA0000V1001000
S28861582XAK27GA0000V2000100
S28861582A4K27GA0000BWS000200DIA   0001299200Y
S28861583A7K27GA00003BB002000LMT   0000176300Y
S28861591X4K27GA000062000200
S28861591A4K27GA000062B000200DIA   0001298700Y
S28861591XAK27GA0000O2000500
S28861591AAK27GA0000O2S000500SPY   0001426300Y
S28861592X4K27GA0000BW000200
S28861592AAK27GA0000VFB002000SPY   0001425700Y
S28861592XAK27GA0000QB000500
S28861592AAK27GA0000QBS000500SPY   0001426200Y
S28861592XAK27GA0000F5000500
S28861592AAK27GA0000F5B000500SPY   0001425600Y
S28861592XAK27GA0000VD001000
S28861592AAK27GA0000VGB001000SPY   0001425700Y
S28861592XAK27GA0000VE001000
S28861593XBK27GA0000IE001000
S28861593X4K27GA000062000200
S28861593A4K27GA000062B000200DIA   0001299000Y
S28861593X4K27GA0000BQ000100
S28861593X3K27G6000062000100
S28861593X4K27GA0000BR000100
S28861593AAK27GA0000VHS001000SPY   0001426200Y
S28861594AAK27GA0000VIS000100SH    0000618800Y
S28861594AAK27GA0000VJS001000SDS   0000548700Y
S28861594ABK27GA0000IGB001000SSO   0000764700Y
S28861594XBK27GA0000IF001000
S28861594AAK27GA0000VKB001000SDS   0000547400Y
S28861595ABK27GA0000IHS001000SSO   0000765600Y
S28861595A4K27GA0000BXS000100DOG   0000598200Y
S28861595A4K27GA0000BYS000100DXD   0000499900Y
S28861595A1K27GA00005DB002000AFL   0000105400Y
S28861596A3K27G6000064B000100DDM   0000801500Y
S28861597A4K27GA0000BZS000200DIA   0001299500Y
S28861601A1K27GA00005EB002000ARO   0000294500Y
S28861607A2K27G600004JB002000AZN   0000417800Y
S28861613A7K27GA00003CB002000LMT   0000177100Y
S28861614A2K27G600004KB002000BK    0000425500Y
S28861621A3K27G6000065B002000CVS   0000063500Y
S28861628ACK27GA00002YB002000WYE   0000066000Y
S28861637A5K27GA000044B002000HNZ   0000068200Y
S28861644X4K27GA0000BZ000200
S28861644XAK27GA0000VF002000
S28861644XAK27GA0000O2000500
S28861644AAK27GA0000O2S000500SPY   0001425900Y
S28861645XAK27GA0000QB000500
S28861645AAK27GA0000QBS000500SPY   0001425900Y
S28861645XBK27GA0000IG001000
S28861645XAK27GA0000VJ001000
S28861646A1K27GA00005FB002000AFL   0000106200Y
S28861647ABK27GA0000IIB001000SSO   0000764600Y
S28861649A4K27GA0000C0S000200DIA   0001299200Y
S28861652XAK27GA0000VI000100
S28861653A5K27GA000045B002000HOT   0000070300Y
S28861664A1K27GA00005GB002000ARO   0000295300Y
S28861669A6K27GA000072B002000JCI   0000050000Y
S28861677X4K27GA000062000200
S28861677A4K27GA000062B000200DIA   0001298700Y
S28861679X4K27GA0000BX000100
S28861679X4K27GA0000BY000100
S28861679X3K27G6000064000100
S28861679XAK27GA0000O2000500
S28861679AAK27GA0000O2S000500SPY   0001426300Y
S28861679AAK27GA0000VLB002000SPY   0001425700Y
S28861679XAK27GA0000QB000500
S28861679AAK27GA0000QBS000500SPY   0001426200Y
S28861679X4K27GA0000C0000200
S28861679X4K27GA000062000200
S28861679A4K27GA000062B000200DIA   0001299000Y
S28861681A8K27G600002XB000500MZZ   0000491400Y
S28861681A8K27G600002YS000100MVV   0000809600Y
S28861682A3K27G6000066B000100DDM   0000801500Y
S28861682XBK27GA0000II001000
S28861681AAK27GA0000VMS000100SH    0000618800Y
S28861681AAK27GA0000VNS001000SDS   0000548700Y
S28861682ABK27GA0000IJB001000SSO   0000764700Y
S28861681A4K27GA0000C1S000100DOG   0000598200Y
S28861681A4K27GA0000C2S000100DXD   0000499900Y
S28861681A4K27GA0000C3S000200DIA   0001299500Y
S28861684XAK27GA0000VB003000
S28861684XAK27GA0000VL002000
S28861684XAK27GA0000O2000500
S28861684AAK27GA0000O2S000500SPY   0001425900Y
S28861684XAK27GA0000VC003000
S28861684X4K27GA0000C3000200
S28861685AAK27GA0000VOB001000SPY   0001425500Y
S28861685XAK27GA0000QB000500
S28861685AAK27GA0000QBS000500SPY   0001425900Y
S28861685X4K27GA000062000200
S28861685A4K27GA000062B000200DIA   0001298700Y
S28861685XBK27GA0000IJ001000
S28861685XAK27GA0000VN001000
S28861685XAK27GA0000VM000100
S28861686AAK27GA0000VPS003000SPY   0001426600Y
S28861686AAK27GA0000VQS003000SPY   0001426600Y
S28861687A2K27G600004LB002000AZN   0000418600Y
S28861687ABK27GA0000IKB001000SSO   0000764600Y
S28861689A4K27GA0000C4S000200DIA   0001299200Y
S28861692AAK27GA0000VRS000100SH    0000618800Y
S28861692XAK27GA0000VR000100
S28861693X4K27GA0000C1000100
S28861694X3K27G6000066000100
S28861693X4K27GA0000C2000100
S28861706X4K27GA000062000200
S28861706A4K27GA000062B000200DIA   0001299000Y
S28861709A4K27GA0000C5S000100DOG   0000598200Y
S28861709A4K27GA0000C6S000100DXD   0000499900Y
S28861710A3K27G6000067B000100DDM   0000801500Y
S28861714A2K27G600004MB002000BBT   0000049900Y
S28861718AAK27GA0000VSB005000SPY   0001425400Y
S28861720AAK27GA0000VTB000500SPY   0001425600Y
S28861724XAK27GA0000QB000500
S28861724AAK27GA0000QBS000500SPY   0001425800Y
S28861726XBK27GA0000IH001000
S28861726ABK27GA0000ILS001000SSO   0000765500Y
S28861727A2K27G600004NB002000CAT   0000816900Y
S28861736A3K27G6000068B002000COH   0000052700Y
S28861746A4K27GA0000C7B002000EIX   0000075300Y
S28861839X6K27GA000026000500
S28861839A6K27GA000026S000500IWM   0000736900Y
S28861842ABK27GA0000IMS000100UWM   0000543700Y
S28861842ABK27GA0000INB000100TWM   0000700700Y
S28861842ABK27GA0000IOB000100TWM   0000700600Y
S28861893AAK27GA0000VUB002500SPY   0001425600Y
S28861901XAK27GA0000VP003000
S28861901XAK27GA0000VQ003000
S28861901XAK27GA0000VO001000
S28861901AAK27GA0000VVS003000SPY   0001426000Y
S28861901AAK27GA0000VWS003000SPY   0001426000Y
S28861903XAK27GA0000VU002500
S28861905XAK27GA0000VT000500
S28861917X4K27GA000062000200
S28861917A4K27GA000062B000200DIA   0001298700Y
S28861919X4K27GA0000C5000100
S28861919X4K27GA0000C6000100
S28861920X3K27G6000067000100
S28861922AAK27GA0000VXS000500SPY   0001426000Y
S28861922XAK27GA0000V6000500
S28861923XAK27GA0000O2000500
S28861923AAK27GA0000O2S000500SPY   0001426300Y
S28861923XAK27GA0000QB000500
S28861923AAK27GA0000QBS000500SPY   0001426200Y
S28861923AAK27GA0000VYB002000SPY   0001425700Y
S28861923X4K27GA000062000200
S28861923A4K27GA000062B000200DIA   0001299000Y
S28861924X4K27GA0000C4000200
S28861925A4K27GA0000C8S000100DOG   0000598200Y
S28861925A4K27GA0000C9S000100DXD   0000499900Y
S28861926A3K27G6000069B000100DDM   0000801500Y
S28861926A4K27GA0000CAS000200DIA   0001299500Y
S28861931XAK27GA0000VX000500
S28861932XBK27GA0000IL001000
S28861934ABK27GA0000IPS001000SSO   0000765600Y
S28861966X1K27GA00000Y000100
S28861966A1K27GA00000YS000100AAPL  0001833400Y
S28862031AAK27GA0000VZS000100SH    0000618800Y
S28862031AAK27GA0000W0S001000SDS   0000548700Y
S28862032XBK27GA0000IK001000
S28862032ABK27GA0000IQB001000SSO   0000764700Y
S28862037X6K27GA000026000500
S28862037A6K27GA000026S000500IWM   0000737300Y
S28862047XBK27GA0000IM000100
S28862049XBK27GA0000IN000100
S28862049XBK27GA0000IO000100
S28862062X4K27GA0000CA000200
S28862063XAK27GA0000VV003000
S28862063XAK27GA0000VW003000
S28862063XAK27GA0000O2000500
S28862063AAK27GA0000O2S000500SPY   0001425900Y
S28862063XAK27GA0000VY002000
S28862063AAK27GA0000W1B001000SPY   0001425600Y
S28862064AAK27GA0000W2S003000SPY   0001426600Y
S28862064AAK27GA0000W3S003000SPY   0001426600Y
S28862072XBK27GA0000IQ001000
S28862072A4K27GA0000CBS000200DIA   0001299200Y
S28862074ABK27GA0000IRB001000SSO   0000764600Y
S28862112X4K27GA000062000200
S28862112A4K27GA000062B000200DIA   0001298700Y
S28862114X4K27GA0000C8000100
S28862114X4K27GA0000C9000100
S28862114X3K27G6000069000100
S28862128AAK27GA0000W4S005000SPY   0001426400Y
S28862129AAK27GA0000W5B000500SPY   0001425600Y
S28862299AAK27GA0000W6B002500SPY   0001425600Y
S28862330AAK27GA0000W7S000500SPY   0001426200Y
S28862330ACK27GA00002ZB000737ZVZZT 0000000100Y
S28862331XCK27GA00002Z000737
S28862331ACK27GA00002ZB000737ZVZZT 0000000100Y
S28862332XCK27GA00002Z000737
S28862351A3K27G600006AB002000CELG  0000474900Y
S28862366A3K27G600006BB002000CTSH  0000044500Y
S28862371X2K27G600004D002000
S28862414X7K27GA00003B002000
S28862417A6K27GA000073B002000JNJ   0000641100Y
S28862439X1K27GA00005D002000
S28862439A4K27GA0000CCB002000FITB  0000178700Y
S28862471X2K27G600004H002000
S28862475X7K27GA00003C002000
S28862482A7K27GA00003DB002000KSS   0000456000Y
S28862484X2K27G6000034002000
S28862490X3K27G6000065002000
S28862497X5K27GA000044002000
S28862500X5K27GA000045002000
S28862505A7K27GA00003EB002000KSS   0000455200Y
S28862517XCK27GA00002Y002000
S28862525ABK27GA0000ISB002000UTX   0000117100Y
S28862542ABK27GA0000ITB002000UTX   0000116300Y
S28862553ACK27GA000030B002000WYE   0000066400Y
S28862556A1K27GA00005HB002000ABT   0000087500Y
S28862570X1K27GA00005F002000
S28862573A1K27GA00005IB002000ACF   0000119400Y
S28862584A1K27GA00005JB002000ABT   0000086600Y
S28862597A2K27G600004OB002000AXP   0000404800Y
S28862599A2K27G600004PB002000AXP   0000404000Y
S28862611A2K27G600004QB002000BBT   0000050000Y
S28862620A2K27G600004RB002000CAG   0000032000Y
S28862629A3K27G600006CB002000COH   0000052800Y
S28862643X3K27G600004V002000
S28862657A4K27GA0000CDB002000EIX   0000075900Y
S28862662AAK27GA0000W8B001000SPY   0001425600Y
S28862667X4K27GA0000C7002000
S28862670A3K27G600006DB002000CVS   0000065500Y
S28862681X6K27GA000071002000
S28863107XAK27GA0000VZ000100
S28863107XAK27GA0000W8001000
S28863107XAK27GA0000W0001000
S28863107XAK27GA0000W1001000
S28863108ABK27GA0000IUS001000SSO   0000765500Y
S28863108XBK27GA0000IP001000
S28863109AAK27GA0000W9S001000SPY   0001425900Y
S28863109XAK27GA0000QB000500
S28863109AAK27GA0000QBS000500SPY   0001425900Y
S28863109XAK27GA0000VH001000
S28863109AAK27GA0000WAB001000SPY   0001425500Y
S28863109XAK27GA0000VK001000
S28863109AAK27GA0000WBB001000SDS   0000547500Y
S28863111XAK27GA0000WA001000
S28863112AAK27GA0000WCB001000SPY   0001425600Y
S28863130XAK27GA0000WC001000
S28863132AAK27GA0000WDB001000SPY   0001425500Y
S28863151XAK27GA0000W4005000
S28863194XAK27GA0000W9001000
S28863194AAK27GA0000W9S001000SPY   0001425800Y
S28863194XAK27GA0000QB000500
S28863194AAK27GA0000QBS000500SPY   0001425800Y
S28863282X4K27GA000062000200
S28863282A4K27GA000062B000200DIA   0001299000Y
S28863282XAK27GA0000W9001000
S28863282XAK27GA0000O2000500
S28863282AAK27GA0000O2S000500SPY   0001426300Y
S28863282XAK27GA0000WD001000
S28863282AAK27GA0000WEB002000SPY   0001425700Y
S28863282XAK27GA0000QB000500
S28863282AAK27GA0000QBS000500SPY   0001426200Y
S28863283AAK27GA0000WFS001000SPY   0001426200Y
S28863283XAK27GA0000W3003000
S28863283XAK27GA0000W2003000
S28863284AAK27GA0000WGS003000SPY   0001426000Y
S28863284A4K27GA0000CES000100DOG   0000598200Y
S28863284AAK27GA0000WHS003000SPY   0001426000Y
S28863284A4K27GA0000CFS000100DXD   0000499900Y
S28863284A3K27G600006EB000100DDM   0000801500Y
S28863284XAK27GA0000W5000500
S28863284XAK27GA0000WB001000
S28863285XAK27GA0000W6002500
S28863286AAK27GA0000WIS000100SH    0000618800Y
S28863286AAK27GA0000WJB002500SPY   0001425500Y
S28863286AAK27GA0000WKB001000SDS   0000547400Y
S28863286AAK27GA0000WLS001000SDS   0000548700Y
S28863287AAK27GA0000WMB005000SPY   0001425500Y
S28863288XAK27GA0000VS005000
S28863292XBK27GA0000IU001000
S28863294ABK27GA0000IVS001000SSO   0000765600Y
S28863294ABK27GA0000IWS001000SSO   0000766700Y
S28863326ABK27GA0000IXB001000SSO   0000764700Y
S28863326XBK27GA0000IR001000
S28863359XAK27GA0000E7001000
S28863359AAK27GA0000E7B001000SPY   0001425300Y
S28863359XAK27GA0000UU003000
S28863359XAK27GA0000WE002000
S28863359XAK27GA0000F5000500
S28863359AAK27GA0000F5B000500SPY   0001425200Y
S28863359X4K27GA000062000200
S28863359A4K27GA000062B000200DIA   0001298700Y
S28863359XAK27GA0000O2000500
S28863359AAK27GA0000O2S000500SPY   0001425900Y
S28863359XAK27GA0000FI000500
S28863359AAK27GA0000FIB000500SPY   0001425200Y
S28863359XAK27GA0000UV003000
S28863359AAK27GA0000WNS002000SPY   0001426100Y
S28863359X4K27GA0000BE000047
S28863360XAK27GA0000QB000500
S28863360AAK27GA0000QBS000500SPY   0001425800Y
S28863360XAK27GA0000VG001000
S28863360XBK27GA0000IX001000
S28863360XAK27GA0000WF001000
S28863360XAK27GA0000WI000100
S28863360AAK27GA0000WOS001000SPY   0001425800Y
S28863360XAK27GA0000WL001000
S28863360XAK27GA0000WM005000
S28863360AAK27GA0000WPB003000SPY   0001425000Y
S28863361XAK27GA0000E9001000
S28863361AAK27GA0000E9S001000SPY   0001425800Y
S28863361XAK27GA0000NY000500
S28863361AAK27GA0000NYS000500SPY   0001425800Y
S28863361X4K27GA0000CE000100
S28863361X4K27GA0000CF000100
S28863362X3K27G600006E000100
S28863362XBK27GA0000IV001000
S28863361AAK27GA0000WQB003000SPY   0001425000Y
S28863361XAK27GA0000WK001000
S28863361AAK27GA0000WRB001000SDS   0000547500Y
S28863362ABK27GA0000IYS001000SSO   0000765500Y
S28863362AAK27GA0000WSB001000SPY   0001425300Y
S28863362ABK27GA0000IZB001000SSO   0000764600Y
S28863362AAK27GA0000WTB000500SPY   0001425400Y
S28863362XAK27GA0000W7000500
S28863363A4K27GA0000CGS000200DIA   0001299100Y
S28863364XBK27GA0000IS002000
S28863372X9K27G60000NF001000
S28863371X6K27GA000026000500
S28863371A6K27GA000026S000500IWM   0000736900Y
S28863372X6K27GA00006S000500
S28863372A6K27GA00006SB000500IWM   0000736300Y
S28863374A9K27G60000OFB001000QQQQ  0000495400Y
S28863374ABK27GA0000J0S000100UWM   0000543700Y
S28863374ABK27GA0000J1B000100TWM   0000700700Y
S28863374ABK27GA0000J2B000100TWM   0000700600Y
S28863375X6K27GA00006S000500
S28863375A6K27GA00006SB000500IWM   0000736700Y
S28863377XBK27GA0000HT000100
S28863377XBK27GA0000HU000100
S28863377X9K27G60000OF001000
S28863379ABK27GA0000J3B000100UWM   0000542700Y
S28863379ABK27GA0000J4S000100TWM   0000702000Y
S28863391X8K27G600002T000500
S28863391X8K27G600002U000100
S28863393A8K27G600002ZB000100MVV   0000806400Y
S28863398A7K27GA00003FB002000LMT   0000182300Y
S28863404X1K27GA00005H002000
S28863414XAK27GA0000UQ001000
S28863415XBK27GA0000IT002000
S28863415A2K27G600004SB002000BMY   0000030200Y
S28863415AAK27GA0000WUB001000SPY   0001425400Y
S28863419XCK27GA000030002000
S28863433X1K27GA00005J002000
S28863434X2K27G600004M002000
S28863440X2K27G6000049002000
S28863442A4K27GA0000CHB000100DXD   0000499300Y
S28863443A3K27G600006FS000100DDM   0000802700Y
S28863455X3K27G6000068002000
S28863464X2K27G6000047002000
S28863474X3K27G600006D002000
S28863477X3K27G6000053002000
S28863484X4K27GA0000CD002000
S28863499A7K27GA00003GB002000LMT   0000183100Y
S28863499X6K27GA000072002000
S28863506X6K27GA000060002000
S28863509A1K27GA00005KB002000AFL   0000109100Y
S28863511ACK27GA000031B002000WYE   0000068400Y
S28863528A1K27GA00005LB002000AFL   0000109900Y
S28863546A3K27G600006GB002000DD    0000456800Y
S28863546A2K27G600004TB002000CAG   0000031900Y
S28863551X6K27GA00006S000500
S28863551A6K27GA00006SB000500IWM   0000736300Y
S28863557XBK27GA0000J3000100
S28863557XBK27GA0000J4000100
S28863557A6K27GA000074B000100IWM   0000736200Y
S28863558X6K27GA000074000100
S28863559ABK27GA0000J5S000100TWM   0000702200Y
S28863560ABK27GA0000J6B000100UWM   0000542700Y
S28863560XBK27GA0000J5000100
S28863560ABK27GA0000J7S000100TWM   0000702000Y
S28863561A4K27GA0000CIB002000EIX   0000078100Y
S28863562XBK27GA0000J6000100
S28863562XBK27GA0000J7000100
S28863564A2K27G600004UB002000CAT   0000816200Y
S28863564ABK27GA0000J8S000100TWM   0000702200Y
S28863566AAK27GA0000WVS000500SPY   0001426000Y
S28863567ABK27GA0000J9B000100UWM   0000542700Y
S28863567ABK27GA0000JAS000100TWM   0000702000Y
S28863567XBK27GA0000J8000100
S28863570A3K27G600006HB002000CVS   0000065900Y
S28863572X9K27G60000G6002000
S28863572A9K27G60000G6B002000QQQQ  0000495300Y
S28863575A5K27GA000046B002000HNZ   0000070800Y
S28863578XBK27GA0000J9000100
S28863578XBK27GA0000JA000100
S28863580ABK27GA0000JBS000100TWM   0000702200Y
S28863582A5K27GA000047B002000HOT   0000072900Y
S28863587ABK27GA0000JCB000100UWM   0000542700Y
S28863587XBK27GA0000JB000100
S28863587ABK27GA0000JDS000100TWM   0000702000Y
S28863591A7K27GA00003HB002000MER   0000463100Y
S28863597XBK27GA0000JC000100
S28863597XBK27GA0000JD000100
S28863599ABK27GA0000JES000100TWM   0000702200Y
S28863602A5K27GA000048B002000HNZ   0000071600Y
S28863607ABK27GA0000JFB000100UWM   0000542700Y
S28863607XBK27GA0000JE000100
S28863607ABK27GA0000JGS000100TWM   0000702000Y
S28863618XBK27GA0000JF000100
S28863618XBK27GA0000JG000100
S28863619ABK27GA0000JHS000100TWM   0000702200Y
S28863628ABK27GA0000JIB000100UWM   0000542700Y
S28863628ABK27GA0000JJS000100TWM   0000702000Y
S28863628XBK27GA0000JH000100
S28863630A5K27GA000049B002000HOT   0000073700Y
S28863638XBK27GA0000JI000100
S28863638XBK27GA0000JJ000100
S28863638A6K27GA000075B002000JCI   0000052700Y
S28863640ABK27GA0000JKS000100TWM   0000702200Y
S28863647ABK27GA0000JLB000100UWM   0000542700Y
S28863647XBK27GA0000JK000100
S28863647ABK27GA0000JMS000100TWM   0000702000Y
S28863658XBK27GA0000JL000100
S28863658XBK27GA0000JM000100
S28863660ABK27GA0000JNS000100TWM   0000702200Y
S28863667ABK27GA0000JOB000100UWM   0000542700Y
S28863667XBK27GA0000JN000100
S28863667ABK27GA0000JPS000100TWM   0000702000Y
S28863677XBK27GA0000JO000100
S28863677XBK27GA0000JP000100
S28863679ABK27GA0000JQS000100TWM   0000702200Y
S28863687ABK27GA0000JRB000100UWM   0000542700Y
S28863687XBK27GA0000JQ000100
S28863687ABK27GA0000JSS000100TWM   0000702000Y
S28863707XBK27GA0000JR000100
S28863707XBK27GA0000JS000100
S28863709ABK27GA0000JTS000100TWM   0000702200Y
S28863758AAK27GA0000WWB005000SPY   0001425400Y
S28863759AAK27GA0000WXS002500SPY   0001426000Y
S28863890X6K27GA00006S000500
S28863891A6K27GA000076B000500IWM   0000736200Y
S28863895X6K27GA000076000500
S28863895A6K27GA000076B000500IWM   0000736300Y
S28863905X6K27GA000076000500
S28863905A6K27GA000076B000500IWM   0000736700Y
S28863909ABK27GA0000JUB000100UWM   0000542700Y
S28863909XBK27GA0000JT000100
S28863909ABK27GA0000JVS000100TWM   0000702000Y
S28863911X6K27GA000076000500
S28863911A6K27GA000076B000500IWM   0000736300Y
S28863914XBK27GA0000JU000100
S28863914XBK27GA0000JV000100
S28863916ABK27GA0000JWS000100TWM   0000702200Y
S28863915X6K27GA000076000500
S28863915A6K27GA000076B000500IWM   0000736700Y
S28863918ABK27GA0000JXB000100UWM   0000542700Y
S28863919ABK27GA0000JYS000100TWM   0000702000Y
S28863919XBK27GA0000JW000100
S28863925X6K27GA000076000500
S28863925A6K27GA000076B000500IWM   0000736300Y
S28863928XBK27GA0000JX000100
S28863928XBK27GA0000JY000100
S28863930ABK27GA0000JZS000100TWM   0000702200Y
S28863929A6K27GA000077B000100IWM   0000736200Y
S28863929X6K27GA000077000100
S28863929X6K27GA000076000500
S28863929A6K27GA000076B000500IWM   0000736700Y
S28863931X6K27GA000076000500
S28863931A6K27GA000076B000500IWM   0000736300Y
S28863933ABK27GA0000K0B000100UWM   0000542700Y
S28863933XBK27GA0000JZ000100
S28863933ABK27GA0000K1S000100TWM   0000702000Y
S28863934XBK27GA0000K0000100
S28863934XBK27GA0000K1000100
S28863936ABK27GA0000K2S000100TWM   0000702200Y
S28863935X6K27GA000076000500
S28863935A6K27GA000076B000500IWM   0000736700Y
S28863938ABK27GA0000K3B000100UWM   0000542700Y
S28863939XBK27GA0000K2000100
S28863939ABK27GA0000K4S000100TWM   0000702000Y
S28863945X6K27GA000076000500
S28863945A6K27GA000076B000500IWM   0000736300Y
S28863948XBK27GA0000K3000100
S28863948XBK27GA0000K4000100
S28863950ABK27GA0000K5S000100TWM   0000702200Y
S28863949A6K27GA000078B000100IWM   0000736200Y
S28863949X6K27GA000078000100
S28863949X6K27GA000076000500
S28863949A6K27GA000076B000500IWM   0000736700Y
S28863953ABK27GA0000K6B000100UWM   0000542700Y
S28863953XBK27GA0000K5000100
S28863953ABK27GA0000K7S000100TWM   0000702000Y
S28863956X6K27GA000076000500
S28863956A6K27GA000076B000500IWM   0000736300Y
S28863959XBK27GA0000K6000100
S28863959XBK27GA0000K7000100
S28863961ABK27GA0000K8S000100TWM   0000702200Y
S28863965X6K27GA000076000500
S28863965A6K27GA000076B000500IWM   0000736700Y
S28863969ABK27GA0000K9B000100UWM   0000542700Y
S28863969ABK27GA0000KAS000100TWM   0000702000Y
S28863969XBK27GA0000K8000100
S28863975X6K27GA000076000500
S28863975A6K27GA000076B000500IWM   0000736300Y
S28863978XBK27GA0000K9000100
S28863978XBK27GA0000KA000100
S28863980ABK27GA0000KBS000100TWM   0000702200Y
S28863982X6K27GA000076000500
S28863982A6K27GA000076B000500IWM   0000736700Y
S28863986ABK27GA0000KCB000100UWM   0000542700Y
S28863986ABK27GA0000KDS000100TWM   0000702000Y
S28863986XBK27GA0000KB000100
S28863985X6K27GA000076000500
S28863985A6K27GA000076B000500IWM   0000736300Y
S28863989XBK27GA0000KC000100
S28863989XBK27GA0000KD000100
S28863991ABK27GA0000KES000100TWM   0000702200Y
S28863995X6K27GA000076000500
S28863995A6K27GA000076B000500IWM   0000736700Y
S28863998X6K27GA000076000500
S28863998A6K27GA000076B000500IWM   0000736300Y
S28864002X6K27GA000076000500
S28864002A6K27GA000076B000500IWM   0000736700Y
S28864005X6K27GA000076000500
S28864005A6K27GA000076B000500IWM   0000736300Y
S28864011X6K27GA000076000500
S28864011A6K27GA000076B000500IWM   0000736700Y
S28864015X6K27GA000076000500
S28864015A6K27GA000076B000500IWM   0000736300Y
S28864025X6K27GA000076000500
S28864025A6K27GA000076B000500IWM   0000736700Y
S28864036X6K27GA000076000500
S28864036A6K27GA000076B000500IWM   0000736300Y
S28864047X6K27GA000076000500
S28864047A6K27GA000076B000500IWM   0000736700Y
S28864053X6K27GA000076000500
S28864053A6K27GA000076B000500IWM   0000736300Y
S28864056X6K27GA000076000500
S28864056A6K27GA000076B000500IWM   0000736700Y
S28864065X6K27GA000076000500
S28864065A6K27GA000076B000500IWM   0000736300Y
S28864076X6K27GA000076000500
S28864076A6K27GA000076B000500IWM   0000736700Y
S28864081X6K27GA000076000500
S28864081A6K27GA000076B000500IWM   0000736300Y
S28864086X6K27GA000076000500
S28864086A6K27GA000076B000500IWM   0000736700Y
S28864096X6K27GA000076000500
S28864096A6K27GA000076B000500IWM   0000736300Y
S28864106X6K27GA000076000500
S28864106A6K27GA000076B000500IWM   0000736700Y
S28864116X6K27GA000076000500
S28864116A6K27GA000076B000500IWM   0000736300Y
S28864126X6K27GA000076000500
S28864126A6K27GA000076B000500IWM   0000736700Y
S28864132X6K27GA000076000500
S28864132A6K27GA000076B000500IWM   0000736300Y
S28864136X6K27GA000076000500
S28864136A6K27GA000076B000500IWM   0000736700Y
S28864142X6K27GA000076000500
S28864142A6K27GA000076B000500IWM   0000736300Y
S28864153X6K27GA000076000500
S28864153A6K27GA000076B000500IWM   0000736700Y
S28864155X6K27GA000076000500
S28864155A6K27GA000076B000500IWM   0000736300Y
S28864165X6K27GA000076000500
S28864165A6K27GA000076B000500IWM   0000736700Y
S28864167X6K27GA000076000500
S28864167A6K27GA000076B000500IWM   0000736300Y
S28864175X6K27GA000076000500
S28864175A6K27GA000076B000500IWM   0000736700Y
S28864180X6K27GA000076000500
S28864180A6K27GA000076B000500IWM   0000736300Y
S28864185X6K27GA000076000500
S28864185A6K27GA000076B000500IWM   0000736700Y
S28864192X6K27GA000076000500
S28864192A6K27GA000076B000500IWM   0000736300Y
S28864195X6K27GA000076000500
S28864195A6K27GA000076B000500IWM   0000736700Y
S28864201X6K27GA000076000500
S28864201A6K27GA000076B000500IWM   0000736300Y
S28864206X6K27GA000076000500
S28864206A6K27GA000076B000500IWM   0000736700Y
S28864212X6K27GA000076000500
S28864212A6K27GA000076B000500IWM   0000736300Y
S28864216X6K27GA000076000500
S28864216A6K27GA000076B000500IWM   0000736700Y
S28864223X6K27GA000076000500
S28864223A6K27GA000076B000500IWM   0000736300Y
S28864260AAK27GA0000WYS005000SPY   0001426200Y
S28864360XAK27GA0000UK002000
S28864386X7K27GA00003G002000
S28864391X7K27GA00003F002000
S28864395XCK27GA000031002000
S28864410X1K27GA00005K002000
S28864411X1K27GA00005L002000
S28864417X2K27G600004R002000
S28864420X2K27G600004Q002000
S28864423X4K27GA0000CI002000
S28864429X3K27G600006C002000
S28864432X5K27GA000048002000
S28864435X3K27G600006H002000
S28864441X5K27GA000046002000
S28864442X5K27GA000049002000
S28864448X5K27GA000047002000
S28864461ABK27GA0000KFB002000UTX   0000121100Y
S28864466ABK27GA0000KGB002000UTX   0000120300Y
S28864482A1K27GA00005MB002000ABT   0000090500Y
S28864483ACK27GA000032B002000WYE   0000068800Y
S28864496A1K27GA00005NB002000ABT   0000089700Y
S28864501A2K27G600004VB002000BBT   0000052700Y
S28864517A2K27G600004WB002000BDX   0000763300Y
S28864523A2K27G600004XB002000BDX   0000762500Y
S28864532A3K27G600006IB002000COH   0000055600Y
S28864545A3K27G600006JB002000DD    0000456100Y
S28864554A4K27GA0000CJB002000EIX   0000078700Y
S28864555A3K27G600006KB002000CVS   0000067800Y
S28864566X6K27GA000076000500
S28864567A6K27GA000079B000500IWM   0000736200Y
S28864575X6K27GA000079000500
S28864575A6K27GA000079B000500IWM   0000736300Y
S28864577A7K27GA00003IB002000LLL   0001087000Y
S28864587XBK27GA0000IZ001000
S28864587XAK27GA0000NZ000500
S28864587AAK27GA0000NZS000500SPY   0001425800Y
S28864589ABK27GA0000KHB001000SSO   0000764500Y
S28864591XAK27GA0000NZ000500
S28864591AAK27GA0000NZS000500SPY   0001426100Y
S28864592XAK27GA0000U2001000
S28864592XBK27GA0000KH001000
S28864592X6K27GA000079000500
S28864592A6K27GA000079B000500IWM   0000736700Y
S28864594ABK27GA0000KIB001000SSO   0000764400Y
S28864593X6K27GA000079000500
S28864593A6K27GA000079B000500IWM   0000736300Y
S28864595ABK27GA0000KJB000100UWM   0000542700Y
S28864595ABK27GA0000KKS000100TWM   0000702000Y
S28864595XBK27GA0000KE000100
S28864597XBK27GA0000KJ000100
S28864597XBK27GA0000KK000100
S28864596X6K27GA000079000500
S28864596A6K27GA000079B000500IWM   0000736700Y
S28864599ABK27GA0000KLS000100TWM   0000702200Y
S28864599ABK27GA0000KMB000100UWM   0000542700Y
S28864599XBK27GA0000KL000100
S28864599ABK27GA0000KNS000100TWM   0000702000Y
S28864606X6K27GA000079000500
S28864606A6K27GA000079B000500IWM   0000736300Y
S28864609XBK27GA0000KM000100
S28864610XBK27GA0000KN000100
S28864609A6K27GA00007AB000100IWM   0000736200Y
S28864611ABK27GA0000KOS000100TWM   0000702200Y
S28864610X6K27GA00007A000100
S28864611A6K27GA00007BB002000JCI   0000052900Y
S28864616X6K27GA000079000500
S28864616A6K27GA000079B000500IWM   0000736700Y
S28864619ABK27GA0000KPB000100UWM   0000542700Y
S28864619XBK27GA0000KO000100
S28864619ABK27GA0000KQS000100TWM   0000702000Y
S28864643X6K27GA000079000500
S28864643A6K27GA000079B000500IWM   0000736300Y
S28864646XBK27GA0000KP000100
S28864646XBK27GA0000KQ000100
S28864648ABK27GA0000KRS000100TWM   0000702200Y
S28864647X6K27GA000079000500
S28864647A6K27GA000079B000500IWM   0000736700Y
S28864650ABK27GA0000KSB000100UWM   0000542700Y
S28864650ABK27GA0000KTS000100TWM   0000702000Y
S28864650XBK27GA0000KR000100
S28864655X6K27GA000079000500
S28864655A6K27GA000079B000500IWM   0000736300Y
S28864658XBK27GA0000KS000100
S28864659XBK27GA0000KT000100
S28864659A6K27GA00007CB000100IWM   0000736200Y
S28864659X6K27GA00007C000100
S28864660ABK27GA0000KUS000100TWM   0000702200Y
S28864660X6K27GA000079000500
S28864660A6K27GA000079B000500IWM   0000736700Y
S28864663XBK27GA0000KU000100
S28864663ABK27GA0000KVB000100UWM   0000542700Y
S28864663ABK27GA0000KWS000100TWM   0000702000Y
S28864665X6K27GA000079000500
S28864665A6K27GA000079B000500IWM   0000736300Y
S28864668XBK27GA0000KV000100
S28864669XBK27GA0000KW000100
S28864670ABK27GA0000KXS000100TWM   0000702200Y
S28864682X6K27GA000079000500
S28864682A6K27GA000079B000500IWM   0000736700Y
S28864686ABK27GA0000KYB000100UWM   0000542700Y
S28864686ABK27GA0000KZS000100TWM   0000702000Y
S28864686XBK27GA0000KX000100
S28864695X6K27GA000079000500
S28864695A6K27GA000079B000500IWM   0000736300Y
S28864699XBK27GA0000KY000100
S28864699XBK27GA0000KZ000100
S28864701ABK27GA0000L0S000100TWM   0000702200Y
S28864706X6K27GA000079000500
S28864706A6K27GA000079B000500IWM   0000736700Y
S28864709ABK27GA0000L1B000100UWM   0000542700Y
S28864709ABK27GA0000L2S000100TWM   0000702000Y
S28864709XBK27GA0000L0000100
S28864716X6K27GA000079000500
S28864716A6K27GA000079B000500IWM   0000736300Y
S28864719XBK27GA0000L1000100
S28864719XBK27GA0000L2000100
S28864721ABK27GA0000L3S000100TWM   0000702200Y
S28864726X6K27GA000079000500
S28864726A6K27GA000079B000500IWM   0000736700Y
S28864736X6K27GA000079000500
S28864736A6K27GA000079B000500IWM   0000736300Y
S28864746X6K27GA000079000500
S28864746A6K27GA000079B000500IWM   0000736700Y
S28864756X6K27GA000079000500
S28864756A6K27GA000079B000500IWM   0000736300Y
S28864766X6K27GA000079000500
S28864766A6K27GA000079B000500IWM   0000736700Y
S28864776X6K27GA000079000500
S28864776A6K27GA000079B000500IWM   0000736300Y
S28864786X6K27GA000079000500
S28864786A6K27GA000079B000500IWM   0000736700Y
S28864796X6K27GA000079000500
S28864796A6K27GA000079B000500IWM   0000736300Y
S28864806X6K27GA000079000500
S28864806A6K27GA000079B000500IWM   0000736700Y
S28864816X6K27GA000079000500
S28864816A6K27GA000079B000500IWM   0000736300Y
S28864826X6K27GA000079000500
S28864826A6K27GA000079B000500IWM   0000736700Y
S28864836X6K27GA000079000500
S28864836A6K27GA000079B000500IWM   0000736300Y
S28864847X6K27GA000079000500
S28864847A6K27GA000079B000500IWM   0000736700Y
S28864856X6K27GA000079000500
S28864856A6K27GA000079B000500IWM   0000736300Y
S28864866X6K27GA000079000500
S28864866A6K27GA000079B000500IWM   0000736700Y
S28864876X6K27GA000079000500
S28864876A6K27GA000079B000500IWM   0000736300Y
S28864886X6K27GA000079000500
S28864886A6K27GA000079B000500IWM   0000736700Y
S28864896X6K27GA000079000500
S28864896A6K27GA000079B000500IWM   0000736300Y
S28864906X6K27GA000079000500
S28864906A6K27GA000079B000500IWM   0000736700Y
S28864916X6K27GA000079000500
S28864916A6K27GA000079B000500IWM   0000736300Y
S28864926X6K27GA000079000500
S28864926A6K27GA000079B000500IWM   0000736700Y
S28864936X6K27GA000079000500
S28864936A6K27GA000079B000500IWM   0000736300Y
S28864946X6K27GA000079000500
S28864946A6K27GA000079B000500IWM   0000736700Y
S28864956X6K27GA000079000500
S28864956A6K27GA000079B000500IWM   0000736300Y
S28864966X6K27GA000079000500
S28864966A6K27GA000079B000500IWM   0000736700Y
S28864976X6K27GA000079000500
S28864976A6K27GA000079B000500IWM   0000736300Y
S28864986X6K27GA000079000500
S28864986A6K27GA000079B000500IWM   0000736700Y
S28864996X6K27GA000079000500
S28864996A6K27GA000079B000500IWM   0000736300Y
S28865016X6K27GA000079000500
S28865016A6K27GA000079B000500IWM   0000736700Y
S28865026X6K27GA000079000500
S28865026A6K27GA000079B000500IWM   0000736300Y
S28865036X6K27GA000079000500
S28865036A6K27GA000079B000500IWM   0000736700Y
S28865047X6K27GA000079000500
S28865047A6K27GA000079B000500IWM   0000736300Y
S28865056X6K27GA000079000500
S28865056A6K27GA000079B000500IWM   0000736700Y
S28865066X6K27GA000079000500
S28865066A6K27GA000079B000500IWM   0000736300Y
S28865076X6K27GA000079000500
S28865076A6K27GA000079B000500IWM   0000736700Y
S28865086X6K27GA000079000500
S28865086A6K27GA000079B000500IWM   0000736300Y
S28865141XAK27GA0000E9001000
S28865141AAK27GA0000E9S001000SPY   0001426200Y
S28865142X9K27G60000G6002000
S28865142A9K27G60000G6B002000QQQQ  0000495800Y
S28865141AAK27GA0000WZB002000SPY   0001425600Y
S28865141XAK27GA0000WP003000
S28865141XAK27GA0000F5000500
S28865141AAK27GA0000F5B000500SPY   0001425600Y
S28865141XAK27GA0000QB000500
S28865141AAK27GA0000QBS000500SPY   0001426200Y
S28865141XAK27GA0000FI000500
S28865141AAK27GA0000FIB000500SPY   0001425600Y
S28865141AAK27GA0000X0B003000SPY   0001425700Y
S28865141XAK27GA0000WG003000
S28865142XAK27GA0000WQ003000
S28865142XAK27GA0000E7001000
S28865142AAK27GA0000E7B001000SPY   0001425700Y
S28865142XAK27GA0000WH003000
S28865142XAK27GA0000NY000500
S28865142AAK27GA0000NYS000500SPY   0001426200Y
S28865142AAK27GA0000X1B003000SPY   0001425700Y
S28865142XAK27GA0000WN001000
S28865142XAK27GA0000WS001000
S28865143AAK27GA0000X2B001000SPY   0001425700Y
S28865143AAK27GA0000X3S001000SDS   0000548800Y
S28865143X4K27GA0000CG000200
S28865143ABK27GA0000L4B001000SSO   0000764500Y
S28865143ABK27GA0000L5B001000SSO   0000764600Y
S28865143XBK27GA0000KI001000
S28865143AAK27GA0000X4B002000SPY   0001425600Y
S28865143XBK27GA0000L4001000
S28865143XAK27GA0000WO001000
S28865143AAK27GA0000X5S003000SPY   0001426600Y
S28865143AAK27GA0000X6S003000SPY   0001426600Y
S28865144XAK27GA0000WT000500
S28865144AAK27GA0000X7B005000SPY   0001425500Y
S28865145XAK27GA0000WW005000
S28865145AAK27GA0000X8S001000SPY   0001426200Y
S28865145XAK27GA0000F2000500
S28865145AAK27GA0000F2B000500SPY   0001425700Y
S28865146XAK27GA0000WX002500
S28865146AAK27GA0000X9B002500SPY   0001425600Y
S28865147XAK27GA0000WJ002500
S28865147XAK27GA0000X7005000
S28865148XAK27GA0000WV000500
S28865149AAK27GA0000XAB000500SPY   0001425600Y
S28865150A4K27GA0000CKS000200DIA   0001299400Y
S28865152XAK27GA0000WR001000
S28865153XBK27GA0000IY001000
S28865154AAK27GA0000XBB001000SDS   0000547400Y
S28865155ABK27GA0000L6S001000SSO   0000765600Y
S28865163X4K27GA0000CH000100
S28865163X3K27G600006F000100
S28865164XAK27GA0000WN001000
S28865164AAK27GA0000XCS001000SPY   0001426200Y
S28865166AAK27GA0000XDS001000SPY   0001426200Y
S28865168XAK27GA0000F2000500
S28865168AAK27GA0000F2B000500SPY   0001425300Y
S28865170XAK27GA0000X4002000
S28865172AAK27GA0000XEB001000SPY   0001425400Y
S28865178AAK27GA0000XFB001000SPY   0001425500Y
S28865197XAK27GA0000XC001000
S28865197XAK27GA0000XD001000
S28865227XAK27GA0000XE001000
S28865238AAK27GA0000XGB001000SPY   0001425500Y
S28865309AAK27GA0000XHB001000SPY   0001425600Y
S28865309XAK27GA0000XG001000
S28865309XAK27GA0000WU001000
S28865361AAK27GA0000XIS000500SPY   0001426200Y
S28865369XAK27GA0000V8002000
S28865373XBK27GA0000KG002000
S28865373X2K27G600004S002000
S28865405XCK27GA000032002000
S28865410XBK27GA0000KF002000
S28865412X3K27G600006B002000
S28865423X1K27GA00005N002000
S28865427X1K27GA00005M002000
S28865433X3K27G600006K002000
S28865438AAK27GA0000XJB002000SHLD  0000738500Y
S28865460A7K27GA00003JB002000LMT   0000189100Y
S28865460A7K27GA00003KB002000LMT   0000188300Y
S28865471X6K27GA000075002000
S28865484X2K27G600004T002000
S28865492ACK27GA000033B002000WYE   0000070800Y
S28865514A1K27GA00005OB002000AFL   0000112800Y
S28865517A1K27GA00005PB002000AFL   0000113600Y
S28865536X4K27GA0000CJ002000
S28865540A2K27G600004YB002000CAG   0000034000Y
S28865540A2K27G600004ZB002000BBT   0000052900Y
S28865553A4K27GA0000CLB002000EIX   0000080900Y
S28865569AAK27GA0000XKB005000SPY   0001425400Y
S28865568X6K27GA00005G002000
S28865574A3K27G600006LB002000COH   0000055800Y
S28865575A5K27GA00004AB002000HNZ   0000074100Y
S28865604A3K27G600006MB002000CVS   0000068200Y
S28865609A5K27GA00004BB002000HOT   0000076400Y
S28865619A5K27GA00004CB002000HNZ   0000073300Y
S28865626A7K27GA00003LB002000LLY   0000464600Y
S28865630A5K27GA00004DB002000HOT   0000075600Y
S28865634A6K27GA00007DB002000KEY   0000210300Y
S28865646A7K27GA00003MB002000MET   0000588700Y
S28865646A7K27GA00003NB002000LTD   0000167600Y
S28866354AAK27GA0000XLB002000SPLS  0000032300Y
S28866363X7K27GA00003J002000
S28866397X8K27G600000Q002000
S28866406X7K27GA00003K002000
S28866431A2K27G6000050B002000BMY   0000032000Y
S28866440X1K27GA00005O002000
S28866462A3K27G600006NB002000CTSH  0000048000Y
S28866469X3K27G600006M002000
S28866479XCK27GA000033002000
S28866491X4K27GA00009W000100
S28866497A4K27GA0000CMB000100DRYS  0001067100Y
S28866508X5K27GA00004C002000
S28866514X5K27GA00004D002000
S28866516ABK27GA0000L7B002000UTX   0000125100Y
S28866520X6K27GA00007B002000
S28866533X1K27GA00005P002000
S28866546X2K27G600004V002000
S28866556ABK27GA0000L8B002000UTX   0000124300Y
S28866557X3K27G600006I002000
S28866566ACK27GA000034B002000WYE   0000071200Y
S28866591A1K27GA00005QB002000ABT   0000092700Y
S28866609A2K27G6000051B002000CAG   0000033800Y
S28866610A1K27GA00005RB002000ABT   0000093600Y
S28866622X4K27GA0000CL002000
S28866632X5K27GA00004A002000
S28866642A4K27GA0000CNB002000EIX   0000081500Y
S28866645X5K27GA00004B002000
S28866651A6K27GA00007EB002000IWN   0000664600Y
S28866657A3K27G600006OB002000CVS   0000070200Y
S28866660A7K27GA00003OB002000MFE   0000341500Y
S28866674A6K27GA00007FB002000JCI   0000055600Y
S28866681A7K27GA00003PB002000MMC   0000034500Y
S28866700A7K27GA00003QB002000MON   0001192500Y
S28866706A7K27GA00003RB002000LXK   0000336600Y
S28866719A7K27GA00003SB002000MOT   0000089000Y
S28866729A7K27GA00003TB002000MAR   0000331400Y
S28866754A7K27GA00003UB002000MAS   0000168600Y
S28866828X1K27GA00000V000100
S28866828A1K27GA00000VB000100AAPL  0001828600Y
S28866837X1K27GA00000W000100
S28866846A1K27GA00005SS000090AAPL  0001833400Y
S28867387X4K27GA00008S002000
S28867389X4K27GA00008R002000
S28867396XBK27GA0000L7002000
S28867402XAK27GA0000UI002000
S28867402A7K27GA00003VB002000LMT   0000194300Y
S28867402X1K27GA00005R002000
S28867407X2K27G600004O002000
S28867425X2K27G600004Y002000
S28867426A8K27G6000030B002000NVTL  0000078600Y
S28867441X3K27G600006O002000
S28867449X3K27G600001S002000
S28867459XBK27GA0000L8002000
S28867462X4K27GA0000AA002000
S28867477X6K27GA00005P002000
S28867486XCK27GA000034002000
S28867493A7K27GA00003WB002000LMT   0000195100Y
S28867497X1K27GA00005Q002000
S28867504A1K27GA00005TB002000AFL   0000116500Y
S28867521X2K27G600004P002000
S28867524X2K27G600004Z002000
S28867524ACK27GA000035B002000WYE   0000073200Y
S28867548A1K27GA00005UB002000AFL   0000117300Y
S28867549X3K27G600006L002000
S28867562A3K27G600006PB002000CVS   0000070600Y
S28867578A2K27G6000052B002000BBT   0000055600Y
S28867583A3K27G600006QB002000COH   0000058600Y
S28867599A4K27GA0000COB002000EIX   0000083700Y
S28867606X3K27G6000020002000
S28867610X4K27GA0000CN002000
S28867616X4K27GA0000AB002000
S28867625A5K27GA00004EB002000HNZ   0000076700Y
S28867629A5K27GA00004FB002000HNZ   0000075900Y
S28867640A5K27GA00004GB002000HOT   0000079100Y
S28867652A5K27GA00004HB002000HOT   0000078300Y
S28867674A6K27GA00007GB002000JCI   0000055700Y
S28867681X6K27GA00005X002000
S28867704XAK27GA0000F2000500
S28867704AAK27GA0000F2B000500SPY   0001425700Y
S28867704X7K27GA000039002000
S28867721E4K27GA0000A800010000004AQ00007
S28867724X4K27GA0000A5000100
S28867724A4K27GA0000CQB000100DIG   0001237800Y
S28867724A4K27GA0000CRS000100DIG   0001246900Y
S28867725X4K27GA0000CR000100
S28867727A4K27GA0000CSS000100DIG   0001246900Y
S28867732X4K27GA0000CS000100
S28867732A4K27GA0000CTS000100DIG   0001244200Y
S28867731X6K27GA000069000100
S28867733X4K27GA0000CT000100
S28867732X6K27GA000068000100
S28867732A6K27GA00007HB000100IYE   0001532300Y
S28867735A4K27GA0000CUS000100DIG   0001246900Y
S28867741A6K27GA00007IB000100IYE   0001532800Y
S28867741X6K27GA00007H000100
S28867832X4K27GA0000AU000100
S28867832A4K27GA0000CVS000100DRYS  0001071900Y
S28867877X4K27GA0000CV000100
S28867880X4K27GA0000AE000100
S28867880A4K27GA0000CWS000100DRYS  0001070900Y
S28867883X4K27GA0000CW000100
S28867884A4K27GA0000CXB000100DRYS  0001067100Y
S28867884A4K27GA0000CYS000100DRYS  0001071900Y
S28867887X4K27GA0000CX000100
S28867887X4K27GA0000CM000100
S28867887X4K27GA0000AN000100
S28867887A4K27GA0000CZB000100DRYS  0001069900Y
S28867887A4K27GA0000D0B000100DRYS  0001069900Y
S28867887A4K27GA0000D1S000100DRYS  0001071900Y
S28867928XAK27GA0000F2000500
S28867928AAK27GA0000F2B000500SPY   0001425300Y
S28867928XAK27GA0000X0003000
S28867928XAK27GA0000X5003000
S28867928XAK27GA0000X6003000
S28867929XAK27GA0000X1003000
S28867929XAK27GA0000XH001000
S28867929AAK27GA0000XMS003000SPY   0001426000Y
S28867929AAK27GA0000XNS003000SPY   0001426000Y
S28867929AAK27GA0000XOS002000SPY   0001426100Y
S28867929XAK27GA0000X8001000
S28867929XAK27GA0000E7001000
S28867929AAK27GA0000E7B001000SPY   0001425300Y
S28867929AAK27GA0000XPS001000SPY   0001425800Y
S28867930XAK27GA0000X2001000
S28867930AAK27GA0000XQB003000SPY   0001425000Y
S28867930XAK27GA0000QB000500
S28867930AAK27GA0000QBS000500SPY   0001425800Y
S28867930AAK27GA0000XRB003000SPY   0001425000Y
S28867930XAK27GA0000XK005000
S28867931XAK27GA0000XB001000
S28867931AAK27GA0000XSB001000SDS   0000547500Y
S28867931ABK27GA0000L9S001000SSO   0000765500Y
S28867931XBK27GA0000L6001000
S28867931AAK27GA0000XTB001000SPY   0001425300Y
S28867932XAK27GA0000X9002500
S28867933AAK27GA0000XUB002500SPY   0001425500Y
S28867934XAK27GA0000XA000500
S28867934AAK27GA0000XVS000500SPY   0001426000Y
S28867934XAK27GA0000XI000500
S28867940X6K27GA000079000500
S28867942ABK27GA0000LAB000100UWM   0000542700Y
S28867942XBK27GA0000L3000100
S28867942ABK27GA0000LBS000100TWM   0000702000Y
S28867944A6K27GA00007JB000500IWM   0000736700Y
S28867947XBK27GA0000LA000100
S28867947XBK27GA0000LB000100
S28867949ABK27GA0000LCB000100UWM   0000542700Y
S28867949ABK27GA0000LDS000100TWM   0000702000Y
S28867949X6K27GA00007J000500
S28867949A6K27GA00007JB000500IWM   0000736300Y
S28867954X6K27GA00007J000500
S28867954A6K27GA00007JB000500IWM   0000736700Y
S28867956XBK27GA0000LC000100
S28867956XBK27GA0000LD000100
S28867956X6K27GA00007J000500
S28867956A6K27GA00007JB000500IWM   0000736300Y
S28867957ABK27GA0000LEB000100UWM   0000542700Y
S28867958ABK27GA0000LFS000100TWM   0000702000Y
S28867959X4K27GA0000CK000200
S28867959XBK27GA0000LE000100
S28867959XBK27GA0000LF000100
S28867959A4K27GA0000D2S000047DIA   0001299100Y
S28867960A4K27GA0000D3B000100DXD   0000499300Y
S28867960A3K27G600006RS000100DDM   0000802700Y
S28867961ABK27GA0000LGS000100TWM   0000702200Y
S28867965X6K27GA00007J000500
S28867965A6K27GA00007JB000500IWM   0000736700Y
S28867967ABK27GA0000LHB000100UWM   0000542700Y
S28867967ABK27GA0000LIS000100TWM   0000702000Y
S28867967XBK27GA0000LG000100
S28867970X4K27GA0000CZ000100
S28867970A4K27GA0000CZB000100DRYS  0001070000Y
S28867970X4K27GA0000D0000100
S28867970A4K27GA0000D0B000100DRYS  0001070000Y
S28867975X6K27GA00007J000500
S28867975A6K27GA00007JB000500IWM   0000736300Y
S28867978XBK27GA0000LH000100
S28867978XBK27GA0000LI000100
S28867980ABK27GA0000LJS000100TWM   0000702200Y
S28867985X6K27GA00007J000500
S28867985A6K27GA00007JB000500IWM   0000736700Y
S28867987ABK27GA0000LKB000100UWM   0000542700Y
S28867987ABK27GA0000LLS000100TWM   0000702000Y
S28867987XBK27GA0000LJ000100
S28867995X6K27GA00007J000500
S28867995A6K27GA00007JB000500IWM   0000736300Y
S28867998XBK27GA0000LK000100
S28867998XBK27GA0000LL000100
S28867997X6K27GA00007J000500
S28867997A6K27GA00007JB000500IWM   0000736700Y
S28868000ABK27GA0000LMB000100UWM   0000542700Y
S28868000ABK27GA0000LNS000100TWM   0000702000Y
S28868001XAK27GA0000E9001000
S28868001AAK27GA0000E9S001000SPY   0001425800Y
S28868005X6K27GA00007J000500
S28868005A6K27GA00007JB000500IWM   0000736300Y
S28868015X6K27GA00007J000500
S28868015A6K27GA00007JB000500IWM   0000736700Y
S28868017XBK27GA0000LM000100
S28868017XBK27GA0000LN000100
S28868017XAK27GA0000XF001000
S28868017A6K27GA00007KB000100IWM   0000736200Y
S28868018ABK27GA0000LOB000100UWM   0000542700Y
S28868017X6K27GA00007K000100
S28868019ABK27GA0000LPS000100TWM   0000702000Y
S28868019AAK27GA0000XWB001000SPY   0001425400Y
S28868025X6K27GA00007J000500
S28868025A6K27GA00007JB000500IWM   0000736300Y
S28868035X6K27GA00007J000500
S28868035A6K27GA00007JB000500IWM   0000736700Y
S28868037XBK27GA0000LO000100
S28868037XBK27GA0000LP000100
S28868037A6K27GA00007LB000100IWM   0000736200Y
S28868039ABK27GA0000LQS000100TWM   0000702200Y
S28868038X6K27GA00007L000100
S28868039ABK27GA0000LRS000100TWM   0000702000Y
S28868039XBK27GA0000LQ000100
S28868039ABK27GA0000LSB000100UWM   0000542700Y
S28868045X6K27GA00007J000500
S28868045A6K27GA00007JB000500IWM   0000736300Y
S28868055X6K27GA00007J000500
S28868055A6K27GA00007JB000500IWM   0000736700Y
S28868057XBK27GA0000LS000100
S28868057XBK27GA0000LR000100
S28868057A6K27GA00007MB000100IWM   0000736200Y
S28868059ABK27GA0000LTS000100TWM   0000702200Y
S28868059X6K27GA00007M000100
S28868067X6K27GA00007J000500
S28868067A6K27GA00007JB000500IWM   0000736300Y
S28868068ABK27GA0000LUB000100UWM   0000542700Y
S28868068XBK27GA0000LT000100
S28868068ABK27GA0000LVS000100TWM   0000702000Y
S28868075X6K27GA00007J000500
S28868075A6K27GA00007JB000500IWM   0000736700Y
S28868077XBK27GA0000LU000100
S28868077XBK27GA0000LV000100
S28868077A6K27GA00007NB000100IWM   0000736200Y
S28868078ABK27GA0000LWS000100TWM   0000702200Y
S28868077X6K27GA00007N000100
S28868085X6K27GA00007J000500
S28868085A6K27GA00007JB000500IWM   0000736300Y
S28868095X6K27GA00007J000500
S28868095A6K27GA00007JB000500IWM   0000736700Y
S28868105X6K27GA00007J000500
S28868105A6K27GA00007JB000500IWM   0000736300Y
S28868115X6K27GA00007J000500
S28868115A6K27GA00007JB000500IWM   0000736700Y
S28868125X6K27GA00007J000500
S28868125A6K27GA00007JB000500IWM   0000736300Y
S28868135X6K27GA00007J000500
S28868135A6K27GA00007JB000500IWM   0000736700Y
S28868145X6K27GA00007J000500
S28868145A6K27GA00007JB000500IWM   0000736300Y
S28868155X6K27GA00007J000500
S28868155A6K27GA00007JB000500IWM   0000736700Y
S28868162X6K27GA00007J000500
S28868162A6K27GA00007JB000500IWM   0000736300Y
S28868165X6K27GA00007J000500
S28868165A6K27GA00007JB000500IWM   0000736700Y
S28868175X6K27GA00007J000500
S28868175A6K27GA00007JB000500IWM   0000736300Y
S28868185X6K27GA00007J000500
S28868185A6K27GA00007JB000500IWM   0000736700Y
S28868195X6K27GA00007J000500
S28868195A6K27GA00007JB000500IWM   0000736300Y
S28868205X6K27GA00007J000500
S28868205A6K27GA00007JB000500IWM   0000736700Y
S28868215X6K27GA00007J000500
S28868215A6K27GA00007JB000500IWM   0000736300Y
S28868225X6K27GA00007J000500
S28868225A6K27GA00007JB000500IWM   0000736700Y
S28868235X6K27GA00007J000500
S28868235A6K27GA00007JB000500IWM   0000736300Y
S28868247X6K27GA00007J000500
S28868247A6K27GA00007JB000500IWM   0000736700Y
S28868256X6K27GA00007J000500
S28868256A6K27GA00007JB000500IWM   0000736300Y
S28868265X6K27GA00007J000500
S28868265A6K27GA00007JB000500IWM   0000736700Y
S28868275X6K27GA00007J000500
S28868275A6K27GA00007JB000500IWM   0000736300Y
S28868285X6K27GA00007J000500
S28868285A6K27GA00007JB000500IWM   0000736700Y
S28868295X6K27GA00007J000500
S28868295A6K27GA00007JB000500IWM   0000736300Y
S28868305X6K27GA00007J000500
S28868305A6K27GA00007JB000500IWM   0000736700Y
S28868315X6K27GA00007J000500
S28868315A6K27GA00007JB000500IWM   0000736300Y
S28868325X6K27GA00007J000500
S28868325A6K27GA00007JB000500IWM   0000736700Y
S28868335X6K27GA00007J000500
S28868335A6K27GA00007JB000500IWM   0000736300Y
S28868342X3K27G600006A002000
S28868345X6K27GA00007J000500
S28868345A6K27GA00007JB000500IWM   0000736700Y
S28868354X6K27GA00006X002000
S28868355X6K27GA00007J000500
S28868355A6K27GA00007JB000500IWM   0000736300Y
S28868357X9K27G60000ER005000
S28868357X9K27G60000FG005000
S28868357X9K27G60000F8003200
S28868357A9K27G60000F8S003200QQQQ  0000496500Y
S28868357A9K27G60000OGB005000QQQQ  0000495900Y
S28868357A9K27G60000OHB005000QQQQ  0000495900Y
S28868358X9K27G60000EU002000
S28868358A9K27G60000EUB002000QQQQ  0000495900Y
S28868361X7K27GA00003V002000
S28868365X6K27GA00007J000500
S28868365A6K27GA00007JB000500IWM   0000736700Y
S28868369X2K27G6000050002000
S28868375AAK27GA0000XXS002500SPY   0001426000Y
S28868375X6K27GA00007J000500
S28868375A6K27GA00007JB000500IWM   0000736300Y
S28868386A4K27GA0000D4B002000EMR   0000553200Y
S28868385X6K27GA00007J000500
S28868385A6K27GA00007JB000500IWM   0000736700Y
S28868388X6K27GA00007J000500
S28868388A6K27GA00007JB000500IWM   0000736300Y
S28868396X6K27GA00007J000500
S28868396A6K27GA00007JB000500IWM   0000736700Y
S28868406X6K27GA00007J000500
S28868406A6K27GA00007JB000500IWM   0000736300Y
S28868410A4K27GA0000D5B002000EMR   0000554000Y
S28868414AAK27GA0000XYB002000SNDK  0000227300Y
S28868417ABK27GA0000LXB002000UTX   0000128300Y
S28868435X7K27GA00003W002000
S28868460ACK27GA000036B002000WYE   0000073600Y
S28868486X9K27G60000OH005000
S28868488A9K27G60000OIB005000QQQQ  0000495500Y
S28868489ABK27GA0000LYB002000UTX   0000129100Y
S28868488A1K27GA00005VB002000ABT   0000095800Y
S28868492X1K27GA00005T002000
S28868491XCK27GA000035002000
S28868495A9K27G60000OJB000500QQQQ  0000495300Y
S28868502A2K27G6000053B002000AXP   0000405300Y
S28868510A2K27G6000054B002000BBT   0000055700Y
S28868510A1K27GA00005WB002000ABT   0000096600Y
S28868529X2K27G6000051002000
S28868534X1K27GA00005U002000
S28868559A2K27G6000055B002000AXP   0000406100Y
S28868566A3K27G600006SB002000COH   0000058800Y
S28868580X3K27G600006P002000
S28868591X4K27GA0000A0002000
S28868598X5K27GA00003R002000
S28868600X5K27GA00004F002000
S28868609A2K27G6000056B002000CAG   0000035900Y
S28868609X5K27GA00004H002000
S28868611A3K27G600006TB002000DE    0000792000Y
S28868622A4K27GA0000D6B002000EIX   0000084300Y
S28868630A4K27GA0000D7B002000ESI   0000616900Y
S28868631A3K27G600006UB002000CVS   0000072600Y
S28868633X7K27GA00003P002000
S28868652A3K27G600006VB002000DE    0000792800Y
S28868651A6K27GA00007OB002000JCP   0000413000Y
S28868673X4K27GA0000A3002000
S28868690XAK27GA0000FI000500
S28868690AAK27GA0000FIB000500SPY   0001425200Y
S28868691X4K27GA0000CO002000
S28868695A4K27GA0000D8B002000ESI   0000617700Y
S28868706X5K27GA00004E002000
S28868712X5K27GA00004G002000
S28868718X6K27GA00007F002000
S28868755X6K27GA00007J000500
S28868756A6K27GA00007PB000500IWM   0000736200Y
S28868765X6K27GA00007P000500
S28868765A6K27GA00007PB000500IWM   0000736700Y
S28868768ABK27GA0000LZB000100UWM   0000542700Y
S28868769ABK27GA0000M0S000100TWM   0000702000Y
S28868769XBK27GA0000LW000100
S28868776X6K27GA00007P000500
S28868776A6K27GA00007PB000500IWM   0000736300Y
S28868779XBK27GA0000LZ000100
S28868779XBK27GA0000M0000100
S28868781ABK27GA0000M1S000100TWM   0000702200Y
S28868795X6K27GA00007P000500
S28868795A6K27GA00007PB000500IWM   0000736700Y
S28868799XBK27GA0000M1000100
S28868799ABK27GA0000M2B000100UWM   0000542700Y
S28868799ABK27GA0000M3S000100TWM   0000702000Y
S28868806X6K27GA00007P000500
S28868806A6K27GA00007PB000500IWM   0000736300Y
S28868809XBK27GA0000M2000100
S28868809XBK27GA0000M3000100
S28868811ABK27GA0000M4S000100TWM   0000702200Y
S28868811X4K27GA0000CY000100
S28868815X6K27GA00007P000500
S28868815A6K27GA00007PB000500IWM   0000736700Y
S28868818ABK27GA0000M5B000100UWM   0000542700Y
S28868818ABK27GA0000M6S000100TWM   0000702000Y
S28868818XBK27GA0000M4000100
S28868825X6K27GA00007P000500
S28868825A6K27GA00007PB000500IWM   0000736300Y
S28868828XBK27GA0000M5000100
S28868828XBK27GA0000M6000100
S28868830ABK27GA0000M7S000100TWM   0000702200Y
S28868829A6K27GA00007QB000100IWM   0000736200Y
S28868829X6K27GA00007Q000100
S28868829X6K27GA00007P000500
S28868829A6K27GA00007PB000500IWM   0000736700Y
S28868833ABK27GA0000M8B000100UWM   0000542700Y
S28868833XBK27GA0000M7000100
S28868833ABK27GA0000M9S000100TWM   0000702000Y
S28868832X6K27GA00007P000500
S28868832A6K27GA00007PB000500IWM   0000736300Y
S28868836XBK27GA0000M8000100
S28868836XBK27GA0000M9000100
S28868836X6K27GA00007P000500
S28868836A6K27GA00007PB000500IWM   0000736700Y
S28868838ABK27GA0000MAS000100TWM   0000702200Y
S28868839ABK27GA0000MBB000100UWM   0000542700Y
S28868840ABK27GA0000MCS000100TWM   0000702000Y
S28868840XBK27GA0000MA000100
S28868839X6K27GA00007P000500
S28868839A6K27GA00007PB000500IWM   0000736300Y
S28868842XBK27GA0000MB000100
S28868842XBK27GA0000MC000100
S28868844ABK27GA0000MDS000100TWM   0000702200Y
S28868847X6K27GA00007P000500
S28868847A6K27GA00007PB000500IWM   0000736700Y
S28868851ABK27GA0000MEB000100UWM   0000542700Y
S28868851ABK27GA0000MFS000100TWM   0000702000Y
S28868851XBK27GA0000MD000100
S28868856X6K27GA00007P000500
S28868856A6K27GA00007PB000500IWM   0000736300Y
S28868859XBK27GA0000ME000100
S28868859XBK27GA0000MF000100
S28868859A6K27GA00007RB000100IWM   0000736200Y
S28868861ABK27GA0000MGS000100TWM   0000702200Y
S28868860X6K27GA00007R000100
S28868865X6K27GA00007P000500
S28868865A6K27GA00007PB000500IWM   0000736700Y
S28868869ABK27GA0000MHB000100UWM   0000542700Y
S28868869XBK27GA0000MG000100
S28868869ABK27GA0000MIS000100TWM   0000702000Y
S28868875X6K27GA00007P000500
S28868875A6K27GA00007PB000500IWM   0000736300Y
S28868879XBK27GA0000MH000100
S28868879XBK27GA0000MI000100
S28868881ABK27GA0000MJS000100TWM   0000702200Y
S28868895X6K27GA00007P000500
S28868895A6K27GA00007PB000500IWM   0000736700Y
S28868897X6K27GA00007P000500
S28868897A6K27GA00007PB000500IWM   0000736300Y
S28868906X6K27GA00007P000500
S28868906A6K27GA00007PB000500IWM   0000736700Y
S28868916X6K27GA00007P000500
S28868916A6K27GA00007PB000500IWM   0000736300Y
S28868926X6K27GA00007P000500
S28868926A6K27GA00007PB000500IWM   0000736700Y
S28868936X6K27GA00007P000500
S28868936A6K27GA00007PB000500IWM   0000736300Y
S28868946X6K27GA00007P000500
S28868946A6K27GA00007PB000500IWM   0000736700Y
S28868956X6K27GA00007P000500
S28868956A6K27GA00007PB000500IWM   0000736300Y
S28868966X6K27GA00007P000500
S28868966A6K27GA00007PB000500IWM   0000736700Y
S28868975XAK27GA0000QB000500
S28868975AAK27GA0000QBS000500SPY   0001426200Y
S28868975XAK27GA0000FI000500
S28868975AAK27GA0000FIB000500SPY   0001425600Y
S28868975XAK27GA0000E9001000
S28868975AAK27GA0000E9S001000SPY   0001426200Y
S28868975XAK27GA0000XM003000
S28868975AAK27GA0000XZB003000SPY   0001425600Y
S28868976XAK27GA0000XQ003000
S28868976XAK27GA0000XR003000
S28868976XAK27GA0000XN003000
S28868976XAK27GA0000XO001000
S28868976XAK27GA0000E7001000
S28868976AAK27GA0000E7B001000SPY   0001425700Y
S28868976AAK27GA0000Y0B003000SPY   0001425600Y
S28868976AAK27GA0000Y1B001000SPY   0001425400Y
S28868976XAK27GA0000XO001000
S28868977AAK27GA0000Y2B005000SPY   0001425500Y
S28868976X6K27GA00007P000500
S28868976A6K27GA00007PB000500IWM   0000736300Y
S28868978AAK27GA0000Y3S001000SPY   0001426200Y
S28868978AAK27GA0000Y4S003000SPY   0001426600Y
S28868978AAK27GA0000Y5S003000SPY   0001426600Y
S28868978AAK27GA0000Y6S001000SPY   0001426200Y
S28868979XAK27GA0000XX002500
S28868979XAK27GA0000Y2005000
S28868979AAK27GA0000Y7B002500SPY   0001425600Y
S28868980XAK27GA0000XU002500
S28868980XAK27GA0000XV000500
S28868981AAK27GA0000Y8B000500SPY   0001425600Y
S28868986X6K27GA00007P000500
S28868986A6K27GA00007PB000500IWM   0000736700Y
S28868990X6K27GA00007P000500
S28868990A6K27GA00007PB000500IWM   0000736300Y
S28868996XAK27GA0000XT001000
S28868996X6K27GA00007P000500
S28868996A6K27GA00007PB000500IWM   0000736700Y
S28868997XAK27GA0000Y1001000
S28868997AAK27GA0000Y9B001000SPY   0001425700Y
S28868997AAK27GA0000YAB001000SPY   0001425600Y
S28868997X6K27GA00007P000500
S28868997A6K27GA00007PB000500IWM   0000736300Y
S28868999X6K27GA00007P000500
S28868999A6K27GA00007PB000500IWM   0000736700Y
S28869008X9K27G60000OI005000
S28869006X6K27GA00007P000500
S28869006A6K27GA00007PB000500IWM   0000736300Y
S28869008A9K27G60000OKB005000QQQQ  0000495900Y
S28869007X4K27GA0000D2000047
S28869009A4K27GA0000D9S000200DIA   0001299400Y
S28869013X3K27G600006R000100
S28869013X4K27GA0000D3000100
S28869015X6K27GA00007P000500
S28869015A6K27GA00007PB000500IWM   0000736700Y
S28869016A6K27GA00007SS015000IOM   0000038400Y
S28869018XAK27GA0000Y6001000
S28869018XAK27GA0000Y3001000
S28869018X6K27GA00007P000500
S28869018A6K27GA00007PB000500IWM   0000736300Y
S28869021X6K27GA00007P000500
S28869021A6K27GA00007PB000500IWM   0000736700Y
S28869025X6K27GA00007P000500
S28869025A6K27GA00007PB000500IWM   0000736300Y
S28869036X6K27GA00007P000500
S28869036A6K27GA00007PB000500IWM   0000736700Y
S28869047X6K27GA00007P000500
S28869047A6K27GA00007PB000500IWM   0000736300Y
S28869056X6K27GA00007P000500
S28869056A6K27GA00007PB000500IWM   0000736700Y
S28869066X6K27GA00007P000500
S28869066A6K27GA00007PB000500IWM   0000736300Y
S28869076X6K27GA00007P000500
S28869076A6K27GA00007PB000500IWM   0000736700Y
S28869086X6K27GA00007P000500
S28869086A6K27GA00007PB000500IWM   0000736300Y
S28869096X6K27GA00007P000500
S28869096A6K27GA00007PB000500IWM   0000736700Y
S28869105X6K27GA00007P000500
S28869105A6K27GA00007PB000500IWM   0000736300Y
S28869116X6K27GA00007P000500
S28869116A6K27GA00007PB000500IWM   0000736700Y
S28869125X6K27GA00007P000500
S28869125A6K27GA00007PB000500IWM   0000736300Y
S28869135X6K27GA00007P000500
S28869135A6K27GA00007PB000500IWM   0000736700Y
S28869141X6K27GA00007P000500
S28869141A6K27GA00007PB000500IWM   0000736300Y
S28869144X6K27GA00007P000500
S28869144A6K27GA00007PB000500IWM   0000736700Y
S28869155X6K27GA00007P000500
S28869155A6K27GA00007PB000500IWM   0000736300Y
S28869165X6K27GA00007P000500
S28869165A6K27GA00007PB000500IWM   0000736700Y
S28869175X6K27GA00007P000500
S28869175A6K27GA00007PB000500IWM   0000736300Y
S28869186X6K27GA00007P000500
S28869186A6K27GA00007PB000500IWM   0000736700Y
S28869198X4K27GA0000D1000100
S28869198A4K27GA0000DAS000100DRYS  0001078300Y
S28869210AAK27GA0000YBS000500SPY   0001426200Y
S28869297ABK27GA0000MKB000100UWM   0000542700Y
S28869297XBK27GA0000MJ000100
S28869297ABK27GA0000MLS000100TWM   0000702000Y
S28869319XAK27GA0000Y4003000
S28869319XAK27GA0000Y5003000
S28869319XAK27GA0000Y9001000
S28869319XAK27GA0000YA001000
S28869319AAK27GA0000YCS003000SPY   0001426000Y
S28869320AAK27GA0000YDS001000SPY   0001426200Y
S28869320AAK27GA0000YES003000SPY   0001426000Y
S28869321AAK27GA0000YFB001000SPY   0001425300Y
S28869321AAK27GA0000YGB001000SPY   0001425400Y
S28869321XAK27GA0000Y7002500
S28869321XAK27GA0000Y0003000
S28869322XAK27GA0000Y8000500
S28869324AAK27GA0000YHB003000SPY   0001425000Y
S28869329AAK27GA0000YIS001000SPY   0001426100Y
S28869330XAK27GA0000V4001000
S28869338X9K27G60000OK005000
S28869341A9K27G60000OLB005000QQQQ  0000495500Y
S28869343A4K27GA0000DBB000100DXD   0000499300Y
S28869344A3K27G600006WS000100DDM   0000802700Y
S28869366XAK27GA0000YI001000
S28869368XAK27GA0000XJ002000
S28869368AAK27GA0000YJS001000SPY   0001426200Y
S28869370XBK27GA0000LX002000
S28869371A2K27G6000057B002000BMY   0000033900Y
S28869376XAK27GA0000YG001000
S28869378AAK27GA0000YKB005000SPY   0001425500Y
S28869381AAK27GA0000YLB002500SPY   0001425500Y
S28869384XAK27GA0000YJ001000
S28869389X3K27G600006N002000
S28869403X9K27G60000OE002000
S28869411AAK27GA0000YMS000500SPY   0001426000Y
S28869411XAK27GA0000YB000500
S28869416X4K27GA0000D0000100
S28869419XCK27GA000036002000
S28869422X1K27GA00005V002000
S28869422A7K27GA00003XB002000LMT   0000200300Y
S28869423A3K27G600006XB002000CELG  0000477400Y
S28869428A4K27GA0000DCB000100DRYS  0001070100Y
S28869436X4K27GA0000DA000100
S28869438XAK27GA0000XZ003000
S28869438XAK27GA0000E7001000
S28869438AAK27GA0000E7B001000SPY   0001425300Y
S28869438X4K27GA0000D9000200
S28869439XAK27GA0000V4001000
S28869439AAK27GA0000YNS001000SPY   0001426100Y
S28869440AAK27GA0000YOB003000SPY   0001425000Y
S28869446A4K27GA0000DDS000100DRYS  0001071900Y
S28869447A6K27GA00007TB002000IMCL  0000343200Y
S28869455X2K27G600004X002000
S28869456A7K27GA00003YB002000LMT   0000201100Y
S28869467A4K27GA0000DES000200DIA   0001299100Y
S28869475XBK27GA0000LY002000
S28869495X3K27G600004E002000
S28869511X4K27GA0000DD000100
S28869516P4K27GA0000DDS000100DRYS  0001071900000N4AQ00008
S28869523A1K27GA00005XB002000AFL   0000120200Y
S28869531X4K27GA0000D6002000
S28869533ACK27GA000037B002000WYE   0000075700Y
S28869546X6K27GA00007P000500
S28869549XBK27GA0000MK000100
S28869549XBK27GA0000ML000100
S28869551X1K27GA00005W002000
S28869551ABK27GA0000MMS000100TWM   0000702200Y
S28869552X5K27GA00003C002000
S28869550A6K27GA00007UB000500IWM   0000736300Y
S28869554X6K27GA00007U000500
S28869554A6K27GA00007UB000500IWM   0000736700Y
S28869557ABK27GA0000MNB000100UWM   0000542700Y
S28869557XBK27GA0000MM000100
S28869557ABK27GA0000MOS000100TWM   0000702000Y
S28869575A1K27GA00005YB002000AFL   0000121000Y
S28869580X2K27G6000052002000
S28869581A2K27G6000058B002000CAG   0000035800Y
S28869595X2K27G600004W002000
S28869611X3K27G600004B002000
S28869613A3K27G600006YB002000CVS   0000072900Y
S28869624X3K27G600006Q002000
S28869633X3K27G600006U002000
S28869635X6K27GA00007G002000
S28869643X6K27GA00005Z002000
S28869651A4K27GA0000DFB002000EAT   0000198700Y
S28869661A4K27GA0000DGB002000EAT   0000199500Y
S28869663A5K27GA00004IB002000HMY   0000086300Y
S28869672A5K27GA00004JB002000HNZ   0000078400Y
S28869684A5K27GA00004KB002000HOT   0000080900Y
S28869689X5K27GA00003F002000
S28869702A4K27GA0000DHB002000EIX   0000086500Y
S28869718A7K27GA00003ZB002000MDY   0001575400Y
S28869722A5K27GA00004LB002000HNZ   0000079200Y
S28869743A5K27GA00004MB002000HOT   0000081700Y
S28869746A6K27GA00007VB002000IWN   0000665600Y
S28869809AAK27GA0000YPS002500SPY   0001426000Y
S28869817X6K27GA00007U000500
S28869817A6K27GA00007UB000500IWM   0000736300Y
S28869821XBK27GA0000MN000100
S28869821XBK27GA0000MO000100
S28869823ABK27GA0000MPS000100TWM   0000702200Y
S28869828X6K27GA00007U000500
S28869828A6K27GA00007UB000500IWM   0000736700Y
S28869831ABK27GA0000MQB000100UWM   0000542700Y
S28869831XBK27GA0000MP000100
S28869831ABK27GA0000MRS000100TWM   0000702000Y
S28869835XAK27GA0000QB000500
S28869835AAK27GA0000QBS000500SPY   0001425800Y
S28869835AAK27GA0000YQS001000SPY   0001426100Y
S28869835X6K27GA00007U000500
S28869835A6K27GA00007UB000500IWM   0000736300Y
S28869838XBK27GA0000MQ000100
S28869838XBK27GA0000MR000100
S28869838A6K27GA00007WB000100IWM   0000736200Y
S28869838X6K27GA00007W000100
S28869840ABK27GA0000MSS000100TWM   0000702200Y
S28869839X6K27GA00007U000500
S28869839A6K27GA00007UB000500IWM   0000736700Y
S28869841ABK27GA0000MTB000100UWM   0000542700Y
S28869841XBK27GA0000MS000100
S28869841ABK27GA0000MUS000100TWM   0000702000Y
S28869845X6K27GA00007U000500
S28869845A6K27GA00007UB000500IWM   0000736300Y
S28869848XBK27GA0000MT000100
S28869848XBK27GA0000MU000100
S28869848X6K27GA00007U000500
S28869848A6K27GA00007UB000500IWM   0000736700Y
S28869850ABK27GA0000MVS000100TWM   0000702200Y
S28869851ABK27GA0000MWB000100UWM   0000542700Y
S28869851XBK27GA0000MV000100
S28869851ABK27GA0000MXS000100TWM   0000702000Y
S28869856X6K27GA00007U000500
S28869856A6K27GA00007UB000500IWM   0000736300Y
S28869876X6K27GA00007U000500
S28869876A6K27GA00007UB000500IWM   0000736700Y
S28869877XBK27GA0000MW000100
S28869877XBK27GA0000MX000100
S28869879ABK27GA0000MYB000100UWM   0000542700Y
S28869877A6K27GA00007XB000100IWM   0000736200Y
S28869879ABK27GA0000MZS000100TWM   0000702000Y
S28869878X6K27GA00007X000100
S28869879X6K27GA00007U000500
S28869879A6K27GA00007UB000500IWM   0000736300Y
S28869882XBK27GA0000MY000100
S28869882XBK27GA0000MZ000100
S28869882A6K27GA00007YB000100IWM   0000736200Y
S28869884ABK27GA0000N0S000100TWM   0000702200Y
S28869882X6K27GA00007Y000100
S28869886ABK27GA0000N1B000100UWM   0000542700Y
S28869887XBK27GA0000N0000100
S28869887ABK27GA0000N2S000100TWM   0000702000Y
S28869887XBK27GA0000N1000100
S28869887XBK27GA0000N2000100
S28869886X6K27GA00007U000500
S28869886A6K27GA00007UB000500IWM   0000736700Y
S28869887A6K27GA00007ZB000100IWM   0000736200Y
S28869889ABK27GA0000N3S000100TWM   0000702200Y
S28869888X6K27GA00007Z000100
S28869889ABK27GA0000N4B000100UWM   0000542700Y
S28869889XBK27GA0000N3000100
S28869889ABK27GA0000N5S000100TWM   0000702000Y
S28869889X6K27GA00007U000500
S28869889A6K27GA00007UB000500IWM   0000736300Y
S28869892XBK27GA0000N4000100
S28869892XBK27GA0000N5000100
S28869894ABK27GA0000N6S000100TWM   0000702200Y
S28869896X6K27GA00007U000500
S28869896A6K27GA00007UB000500IWM   0000736700Y
S28869899ABK27GA0000N7B000100UWM   0000542700Y
S28869899XBK27GA0000N6000100
S28869899ABK27GA0000N8S000100TWM   0000702000Y
S28869905X6K27GA00007U000500
S28869905A6K27GA00007UB000500IWM   0000736300Y
S28869925X6K27GA00007U000500
S28869925A6K27GA00007UB000500IWM   0000736700Y
S28869926XBK27GA0000N7000100
S28869926XBK27GA0000N8000100
S28869927A6K27GA000080B000100IWM   0000736200Y
S28869928ABK27GA0000N9S000100TWM   0000702200Y
S28869927X6K27GA00007U000500
S28869927A6K27GA00007UB000500IWM   0000736300Y
S28869927X6K27GA000080000100
S28869944XAK27GA0000FI000500
S28869944AAK27GA0000FIB000500SPY   0001425200Y
S28869944XAK27GA0000E9001000
S28869944AAK27GA0000E9S001000SPY   0001425800Y
S28869951A6K27GA000081S002000IWM   0000737100Y
S28870028X4K27GA0000DC000100
S28870028X4K27GA0000CZ000100
S28870135XAK27GA0000XW001000
S28870135AAK27GA0000YRB001000SPY   0001425300Y
S28870137AAK27GA0000YSB001000SPY   0001425300Y
S28870147XAK27GA0000E9001000
S28870147AAK27GA0000E9S001000SPY   0001426200Y
S28870147XAK27GA0000FI000500
S28870147AAK27GA0000FIB000500SPY   0001425600Y
S28870147XAK27GA0000QB000500
S28870147AAK27GA0000QBS000500SPY   0001426200Y
S28870147XAK27GA0000YC003000
S28870147XAK27GA0000YE003000
S28870147XAK27GA0000YH003000
S28870147XAK27GA0000YO003000
S28870147AAK27GA0000YTB003000SPY   0001425600Y
S28870147XAK27GA0000E7001000
S28870147AAK27GA0000E7B001000SPY   0001425700Y
S28870148AAK27GA0000YUB003000SPY   0001425600Y
S28870148XAK27GA0000YQ001000
S28870148AAK27GA0000YVB001000SPY   0001425400Y
S28870148XAK27GA0000YN001000
S28870148A4K27GA0000DIB000100DRYS  0001070100Y
S28870148A4K27GA0000DJB000100DRYS  0001070100Y
S28870149AAK27GA0000YWS003000SPY   0001426600Y
S28870149AAK27GA0000YXS003000SPY   0001426600Y
S28870150AAK27GA0000YYS001000SPY   0001426200Y
S28870155XAK27GA0000YP002500
S28870156XAK27GA0000YK005000
S28870156XAK27GA0000YM000500
S28870156AAK27GA0000YZB000500SPY   0001425600Y
S28870156AAK27GA0000Z0B005000SPY   0001425400Y
S28870165XAK27GA0000E7001000
S28870165AAK27GA0000E7B001000SPY   0001425300Y
S28870165XAK27GA0000YW003000
S28870165XAK27GA0000YX003000
S28870165XAK27GA0000YV001000
S28870166AAK27GA0000Z1S003000SPY   0001426000Y
S28870166AAK27GA0000Z2S001000SPY   0001426100Y
S28870166AAK27GA0000Z3S003000SPY   0001426000Y
S28870165X6K27GA000081002000
S28870168XAK27GA0000YZ000500
S28870172X6K27GA00007I000100
S28870175A4K27GA0000DKB000100DIG   0001238500Y
S28870175X4K27GA0000CQ000100
S28870175A6K27GA000082B000100IYE   0001532100Y
S28870182X4K27GA0000DK000100
S28870181X6K27GA000082000100
S28870183A6K27GA000083B000100IYE   0001531500Y
S28870188XAK27GA0000YT003000
S28870187A6K27GA000084S002000IWM   0000737100Y
S28870189XAK27GA0000YU003000
S28870192AAK27GA0000Z4B003000SPY   0001425000Y
S28870192AAK27GA0000Z5B003000SPY   0001425000Y
S28870192A4K27GA0000DLB000100DIG   0001237800Y
S28870210AAK27GA0000Z6S002500SPY   0001426000Y
S28870261AAK27GA0000Z7S001000SPY   0001426100Y
S28870353AAK27GA0000Z8S000500SPY   0001426000Y
S28870353XAK27GA0000XL002000
S28870364X7K27GA00003X002000
S28870387X9K27G60000OG005000
S28870387X9K27G60000F8003200
S28870387A9K27G60000F8S003200QQQQ  0000496000Y
S28870391A9K27G60000OMB005000QQQQ  0000495500Y
S28870391X9K27G60000EU002000
S28870391A9K27G60000EUB002000QQQQ  0000495600Y
S28870398X4K27GA000049002000
S28870398X7K27GA00003Y002000
S28870413X9K27G60000O7002000
S28870414X9K27G60000OD001000
S28870414AAK27GA0000Z9B002000SHLD  0000741400Y
S28870416A9K27G60000ONB001000QQQQ  0000495500Y
S28870416A9K27G60000OOB001000QQQQ  0000495400Y
S28870417X9K27G60000ON001000
S28870417X9K27G60000OO001000
S28870416XCK27GA000037002000
S28870421X9K27G60000OB001000
S28870421A9K27G60000OPB001000QLD   0000889300Y
S28870423A9K27G60000OQB001000QLD   0000889400Y
S28870423A9K27G60000ORB001000QQQQ  0000495500Y
S28870423A9K27G60000OSB001000QQQQ  0000495400Y
S28870424X9K27G60000G6002000
S28870424A9K27G60000G6B002000QQQQ  0000495300Y
S28870424X9K27G60000F5003200
S28870424A9K27G60000F5B003200QQQQ  0000495300Y
S28870424X9K27G60000O8001000
S28870425A9K27G60000OTB001000QQQQ  0000495300Y
S28870425X9K27G60000OQ001000
S28870425X9K27G60000O6002000
S28870426X9K27G60000O6002000
S28870426A9K27G60000OUS002000QQQQ  0000496000Y
S28870429X9K27G60000OC000100
S28870429X9K27G60000OR001000
S28870429X9K27G60000OA000100
S28870429X9K27G60000OS001000
S28870443XAK27GA0000QB000500
S28870443AAK27GA0000QBS000500SPY   0001425800Y
S28870447ABK27GA0000NAB002000UTX   0000132300Y
S28870449X1K27GA00005Y002000
S28870451X9K27G60000OU002000
S28870467X2K27G6000056002000
S28870472A3K27G600006ZB002000CTSH  0000051400Y
S28870473X1K27GA00005X002000
S28870476X6K27GA00006W002000
S28870487X9K27G60000O3005000
S28870487A9K27G60000OVS000200QQQQ  0000495900Y
S28870487X9K27G60000O4005000
S28870487X9K27G60000G3002000
S28870487A9K27G60000G3S002000QQQQ  0000495900Y
S28870487A9K27G60000OWS005000QQQQ  0000495900Y
S28870487A9K27G60000OXS005000QQQQ  0000495900Y
S28870504X2K27G6000054002000
S28870506X4K27GA0000DH002000
S28870524ABK27GA0000NBB002000UTX   0000133100Y
S28870522ACK27GA000038B002000WYE   0000076000Y
S28870532X9K27G60000OW005000
S28870532X9K27G60000F5003200
S28870532A9K27G60000F5B003200QQQQ  0000495800Y
S28870532X9K27G60000OX005000
S28870534A9K27G60000OYS005000QQQQ  0000496300Y
S28870534A9K27G60000OZS005000QQQQ  0000496300Y
S28870534A9K27G60000P0B002000PDLI  0000022300Y
S28870540A1K27GA00005ZB002000ABT   0000098900Y
S28870547X3K27G600006S002000
S28870549X5K27GA000041002000
S28870554X3K27G600006Y002000
S28870565X5K27GA00004L002000
S28870578X5K27GA00004M002000
S28870582A2K27G6000059B002000BDX   0000763800Y
S28870590A3K27G6000070B002000CCE   0000190500Y
S28870593AAK27GA0000ZAB005000SPY   0001425500Y
S28870594XAK27GA0000E9001000
S28870594AAK27GA0000E9S001000SPY   0001425800Y
S28870594XAK27GA0000Z0005000
S28870616A1K27GA000060B002000ABT   0000099700Y
S28870619A4K27GA0000DMB002000EIX   0000087100Y
S28870631X5K27GA00004J002000
S28870632A2K27G600005AB002000BBT   0000058400Y
S28870645X5K27GA00004K002000
S28870648A2K27G600005BB002000BDX   0000764600Y
S28870658A5K27GA00004NB002000GE    0000299300Y
S28870664XAK27GA0000FI000500
S28870664AAK27GA0000FIB000500SPY   0001425200Y
S28870665A3K27G6000071B002000CCE   0000191300Y
S28870668XAK27GA0000F5000500
S28870668AAK27GA0000F5B000500SPY   0001425200Y
S28870669XAK27GA0000ZA005000
S28870670AAK27GA0000ZBB000500SPY   0001425400Y
S28870672XBK27GA0000L5001000
S28870674ABK27GA0000NCB001000SSO   0000764500Y
S28870685X8K27G600002X000500
S28870685X8K27G600002Y000100
S28870686A3K27G6000072B002000COH   0000061600Y
S28870686A8K27G6000031S000100MVV   0000809700Y
S28870687A8K27G6000032B000500MZZ   0000491400Y
S28870689X6K27GA00002B000500
S28870689A6K27GA00002BS000500IWM   0000736800Y
S28870691XBK27GA0000NC001000
S28870691XAK27GA0000X3001000
S28870692ABK27GA0000NDS000100UWM   0000543500Y
S28870692ABK27GA0000NEB000100TWM   0000700900Y
S28870692ABK27GA0000NFB000100TWM   0000700800Y
S28870692XBK27GA0000I1000100
S28870693ABK27GA0000NGB001000SSO   0000764400Y
S28870693X6K27GA00002C000500
S28870693A6K27GA00002CB000500IWM   0000736200Y
S28870693A6K27GA000085B002000JCI   0000058600Y
S28870695X6K27GA00002C000500
S28870695A6K27GA00002CB000500IWM   0000736600Y
S28870698A8K27G6000033B000500MZZ   0000491500Y
S28870698A8K27G6000034S000100MVV   0000809500Y
S28870697X6K27GA00002C000500
S28870697A6K27GA00002CB000500IWM   0000736200Y
S28870706A3K27G6000073B002000CVS   0000074900Y
S28870705X6K27GA00002C000500
S28870705A6K27GA00002CB000500IWM   0000736600Y
S28870716X6K27GA00002C000500
S28870716A6K27GA00002CB000500IWM   0000736200Y
S28870720X8K27G600002R000500
S28870720X8K27G600002S000100
S28870720X8K27G600002Z000100
S28870722A8K27G6000035S000500MZZ   0000493800Y
S28870722A8K27G6000036B000100MVV   0000806300Y
S28870720X6K27GA00002C000500
S28870720A6K27GA00002CB000500IWM   0000736600Y
S28870722XBK27GA0000GC000100
S28870722XBK27GA0000N9000100
S28870724ABK27GA0000NHB000100UWM   0000542500Y
S28870724ABK27GA0000NIS000100TWM   0000702200Y
S28870726X6K27GA00002C000500
S28870726A6K27GA00002CB000500IWM   0000736200Y
S28870729X9K27G60000OJ000500
S28870729X9K27G60000OT001000
S28870732A5K27GA00004OB002000GE    0000300100Y
S28870736X6K27GA00002C000500
S28870736A6K27GA00002CB000500IWM   0000736600Y
S28870746X6K27GA00002C000500
S28870746A6K27GA00002CB000500IWM   0000736200Y
S28870767XBK27GA0000NH000100
S28870767XBK27GA0000NI000100
S28870768ABK27GA0000NJS000100TWM   0000702200Y
S28870769ABK27GA0000NKB000100UWM   0000542500Y
S28870786XBK27GA0000NK000100
S28870787XBK27GA0000NJ000100
S28870788ABK27GA0000NLB000100UWM   0000542500Y
S28870787A6K27GA000086B000100IWM   0000736100Y
S28870787X6K27GA000086000100
S28870788ABK27GA0000NMS000100TWM   0000702200Y
S28870806XBK27GA0000NL000100
S28870806XBK27GA0000NM000100
S28870808ABK27GA0000NNS000100TWM   0000702400Y
S28870811AAK27GA0000ZCB000100SH    0000618300Y
S28870812ABK27GA0000NOS001000SSO   0000765400Y
S28870812XBK27GA0000L9001000
S28870816XBK27GA0000NN000100
S28870816ABK27GA0000NPB000100UWM   0000542500Y
S28870817ABK27GA0000NQS000100TWM   0000702200Y
S28870826XBK27GA0000NP000100
S28870827XBK27GA0000NQ000100
S28870829ABK27GA0000NRS000100TWM   0000702400Y
S28870925XAK27GA0000NY000500
S28870925AAK27GA0000NYS000500SPY   0001425800Y
S28870925XAK27GA0000WZ002000
S28870934X4K27GA00003H000200
S28870934A4K27GA00003HB000200DIA   0001298600Y
S28870936X4K27GA0000B9000100
S28870937X3K27G600005M000100
S28871095X6K27GA00002C000500
S28871104A4K27GA0000DNB000100DOG   0000597000Y
S28871104A4K27GA0000DOB000100DXD   0000499400Y
S28871105A3K27G6000074S000100DDM   0000802600Y
S28871105AAK27GA0000ZDB005000SPY   0001425400Y
S28871105A6K27GA000087B000500IWM   0000736600Y
S28871108ABK27GA0000NSB000100UWM   0000542500Y
S28871108XBK27GA0000NR000100
S28871108ABK27GA0000NTS000100TWM   0000702200Y
S28871115X6K27GA000087000500
S28871115A6K27GA000087B000500IWM   0000736200Y
S28871118XBK27GA0000NT000100
S28871118XBK27GA0000NS000100
S28871120ABK27GA0000NUS000100TWM   0000702400Y
S28871119X6K27GA000087000500
S28871119A6K27GA000087B000500IWM   0000736600Y
S28871123ABK27GA0000NVB000100UWM   0000542500Y
S28871123ABK27GA0000NWS000100TWM   0000702200Y
S28871123XBK27GA0000NU000100
S28871125X6K27GA000087000500
S28871125A6K27GA000087B000500IWM   0000736200Y
S28871128XBK27GA0000NV000100
S28871128XBK27GA0000NW000100
S28871130ABK27GA0000NXS000100TWM   0000702400Y
S28871133X6K27GA000087000500
S28871133A6K27GA000087B000500IWM   0000736600Y
S28871135X6K27GA000087000500
S28871135A6K27GA000087B000500IWM   0000736200Y
S28871136ABK27GA0000NYB000100UWM   0000542500Y
S28871137XBK27GA0000NX000100
S28871137ABK27GA0000NZS000100TWM   0000702200Y
S28871138XBK27GA0000NZ000100
S28871138XBK27GA0000NY000100
S28871140ABK27GA0000O0S000100TWM   0000702400Y
S28871145X6K27GA000087000500
S28871145A6K27GA000087B000500IWM   0000736600Y
S28871148ABK27GA0000O1B000100UWM   0000542500Y
S28871148XBK27GA0000O0000100
S28871148ABK27GA0000O2S000100TWM   0000702200Y
S28871155X6K27GA000087000500
S28871155A6K27GA000087B000500IWM   0000736200Y
S28871158XBK27GA0000O1000100
S28871158XBK27GA0000O2000100
S28871160ABK27GA0000O3S000100TWM   0000702400Y
S28871159A6K27GA000088B000100IWM   0000736100Y
S28871159X6K27GA000088000100
S28871159X6K27GA000087000500
S28871159A6K27GA000087B000500IWM   0000736600Y
S28871162ABK27GA0000O4B000100UWM   0000542500Y
S28871163ABK27GA0000O5S000100TWM   0000702200Y
S28871163XBK27GA0000O3000100
S28871165X6K27GA000087000500
S28871165A6K27GA000087B000500IWM   0000736200Y
S28871168XBK27GA0000O4000100
S28871168XBK27GA0000O5000100
S28871170ABK27GA0000O6S000100TWM   0000702400Y
S28871175X6K27GA000087000500
S28871175A6K27GA000087B000500IWM   0000736600Y
S28871178ABK27GA0000O7B000100UWM   0000542500Y
S28871178XBK27GA0000O6000100
S28871178ABK27GA0000O8S000100TWM   0000702200Y
S28871183X4K27GA0000DJ000100
S28871183X4K27GA0000DI000100
S28871185X6K27GA000087000500
S28871185A6K27GA000087B000500IWM   0000736200Y
S28871188XBK27GA0000O7000100
S28871188XBK27GA0000O8000100
S28871190ABK27GA0000O9S000100TWM   0000702400Y
S28871189X6K27GA000087000500
S28871189A6K27GA000087B000500IWM   0000736600Y
S28871193ABK27GA0000OAB000100UWM   0000542500Y
S28871193ABK27GA0000OBS000100TWM   0000702200Y
S28871193XBK27GA0000O9000100
S28871195X6K27GA000087000500
S28871195A6K27GA000087B000500IWM   0000736200Y
S28871198XBK27GA0000OA000100
S28871198XBK27GA0000OB000100
S28871200ABK27GA0000OCS000100TWM   0000702400Y
S28871205X6K27GA000087000500
S28871205A6K27GA000087B000500IWM   0000736600Y
S28871215X6K27GA000087000500
S28871215A6K27GA000087B000500IWM   0000736200Y
S28871217XAK27GA0000YL002500
S28871217AAK27GA0000ZEB002500SPY   0001425400Y
S28871235X6K27GA000087000500
S28871235A6K27GA000087B000500IWM   0000736600Y
S28871245X6K27GA000087000500
S28871245A6K27GA000087B000500IWM   0000736200Y
S28871255X6K27GA000087000500
S28871255A6K27GA000087B000500IWM   0000736600Y
S28871265X6K27GA000087000500
S28871265A6K27GA000087B000500IWM   0000736200Y
S28871275X6K27GA000087000500
S28871275A6K27GA000087B000500IWM   0000736600Y
S28871285X6K27GA000087000500
S28871285A6K27GA000087B000500IWM   0000736200Y
S28871295X6K27GA000087000500
S28871295A6K27GA000087B000500IWM   0000736600Y
S28871305X6K27GA000087000500
S28871305A6K27GA000087B000500IWM   0000736200Y
S28871315X6K27GA000087000500
S28871315A6K27GA000087B000500IWM   0000736600Y
S28871325X6K27GA000087000500
S28871325A6K27GA000087B000500IWM   0000736200Y
S28871335X6K27GA000087000500
S28871335A6K27GA000087B000500IWM   0000736600Y
S28871345X6K27GA000087000500
S28871345A6K27GA000087B000500IWM   0000736200Y
S28871353AAK27GA0000ZFB002000SPLS  0000035500Y
S28871355X6K27GA000087000500
S28871355A6K27GA000087B000500IWM   0000736600Y
S28871364X2K27G6000057002000
S28871365X6K27GA000087000500
S28871365A6K27GA000087B000500IWM   0000736200Y
S28871375X5K27GA000013002000
S28871375X6K27GA000087000500
S28871375A6K27GA000087B000500IWM   0000736600Y
S28871383X5K27GA00003Q002000
S28871385X6K27GA000087000500
S28871385A6K27GA000087B000500IWM   0000736200Y
S28871395X6K27GA000087000500
S28871395A6K27GA000087B000500IWM   0000736600Y
S28871405X6K27GA000087000500
S28871405A6K27GA000087B000500IWM   0000736200Y
S28871415A4K27GA0000DPB002000FFIV  0000264600Y
S28871415A7K27GA000040B002000LMT   0000206300Y
S28871416X5K27GA000017002000
S28871415X6K27GA000087000500
S28871415A6K27GA000087B000500IWM   0000736600Y
S28871425X6K27GA000087000500
S28871425A6K27GA000087B000500IWM   0000736200Y
S28871435X6K27GA000087000500
S28871435A6K27GA000087B000500IWM   0000736600Y
S28871444XBK27GA0000NA002000
S28871445X6K27GA000087000500
S28871445A6K27GA000087B000500IWM   0000736200Y
S28871450XBK27GA0000NB002000
S28871455X6K27GA000087000500
S28871455A6K27GA000087B000500IWM   0000736600Y
S28871459XCK27GA000038002000
S28871460X1K27GA000060002000
S28871465X6K27GA000087000500
S28871465A6K27GA000087B000500IWM   0000736200Y
S28871473X3K27G6000073002000
S28871475X6K27GA000087000500
S28871475A6K27GA000087B000500IWM   0000736600Y
S28871481X1K27GA00005Z002000
S28871485X4K27GA0000A2002000
S28871485X6K27GA000087000500
S28871485A6K27GA000087B000500IWM   0000736200Y
S28871490A4K27GA0000DQB000100DRYS  0001070100Y
S28871490A4K27GA0000DRB000100DRYS  0001070100Y
S28871495X6K27GA000087000500
S28871495A6K27GA000087B000500IWM   0000736600Y
S28871505X6K27GA000087000500
S28871505A6K27GA000087B000500IWM   0000736200Y
S28871506A1K27GA000061B002000AFL   0000123900Y
S28871510A7K27GA000041B002000LMT   0000207100Y
S28871515X6K27GA000087000500
S28871515A6K27GA000087B000500IWM   0000736600Y
S28871525X6K27GA000087000500
S28871525A6K27GA000087B000500IWM   0000736200Y
S28871529A2K27G600005CB002000BBT   0000058600Y
S28871534ACK27GA000039B002000WYE   0000078100Y
S28871535X6K27GA000087000500
S28871535A6K27GA000087B000500IWM   0000736600Y
S28871545X6K27GA000087000500
S28871545A6K27GA000087B000500IWM   0000736200Y
S28871550X2K27G6000058002000
S28871555X6K27GA000087000500
S28871555A6K27GA000087B000500IWM   0000736600Y
S28871560A1K27GA000062B002000AFL   0000124700Y
S28871562A3K27G6000075B002000COH   0000061800Y
S28871565X6K27GA000087000500
S28871565A6K27GA000087B000500IWM   0000736200Y
S28871574A2K27G600005DB002000CAG   0000037900Y
S28871575X6K27GA000087000500
S28871575A6K27GA000087B000500IWM   0000736600Y
S28871585A4K27GA0000DSB002000EIX   0000089300Y
S28871585X6K27GA000087000500
S28871585A6K27GA000087B000500IWM   0000736200Y
S28871592A5K27GA00004PB002000HMY   0000087300Y
S28871602A5K27GA00004QB002000HNZ   0000081800Y
S28871626A5K27GA00004RB002000HOT   0000084400Y
S28871630X9K27G60000F5003200
S28871630A9K27G60000F5B003200QQQQ  0000495300Y
S28871630X9K27G60000OY005000
S28871630X9K27G60000OZ005000
S28871631A9K27G60000P1S005000QQQQ  0000495900Y
S28871631A9K27G60000P2S005000QQQQ  0000495900Y
S28871634A3K27G6000076B002000CVS   0000075300Y
S28871645A6K27GA000089B002000JCI   0000060300Y
S28871652X4K27GA0000DM002000
S28871678A5K27GA00004SB002000HNZ   0000081000Y
S28871687A5K27GA00004TB002000HOT   0000083600Y
S28871695A6K27GA00008AB002000JWN   0000350500Y
S28871699A7K27GA000042B002000MMC   0000037900Y
S28871734X9K27G60000F5003200
S28871734A9K27G60000F5B003200QQQQ  0000495800Y
S28871734X9K27G60000P1005000
S28871734X9K27G60000P2005000
S28871736A9K27G60000P3S005000QQQQ  0000496300Y
S28871736A9K27G60000P4S005000QQQQ  0000496300Y
S28872204X4K27GA0000B8000200
S28872205A4K27GA0000DTS000047DIA   0001299000Y
S28872231AAK27GA0000ZGS002500SPY   0001425900Y
S28872231XAK27GA0000Z6002500
S28872346X9K27G60000F5003200
S28872346A9K27G60000F5B003200QQQQ  0000495300Y
S28872347A9K27G60000P5S002000QQQQ  0000496000Y
S28872389A5K27GA00004UB002000GG    0000385200Y
S28872393A2K27G600005EB002000BMY   0000035700Y
S28872404A5K27GA00004VB002000GM    0000175600Y
S28872414X7K27GA000040002000
S28872423ABK27GA0000ODB002000UTX   0000136300Y
S28872423X7K27GA000041002000
S28872437XCK27GA00002N002000
S28872445ACK27GA00003AB002000WYE   0000078500Y
S28872450A5K27GA00004WB002000GG    0000386000Y
S28872463X9K27G60000P4005000
S28872464A1K27GA000063B002000ABT   0000101900Y
S28872462XCK27GA00002P002000
S28872465A9K27G60000P6S005000QQQQ  0000495900Y
S28872474XCK27GA000039002000
S28872487X1K27GA000061002000
S28872498ABK27GA0000OEB002000UTX   0000137100Y
S28872509X1K27GA000062002000
S28872511A2K27G600005FB002000CAG   0000037700Y
S28872532X2K27G600005A002000
S28872532X3K27G6000072002000
S28872550A1K27GA000064B002000ABT   0000102800Y
S28872555X3K27G6000076002000
S28872584A4K27GA0000DUB002000EIX   0000089900Y
S28872595X5K27GA00004S002000
S28872600X5K27GA00004T002000
S28872608X6K27GA000085002000
S28872629A3K27G6000077B002000CVS   0000077300Y
S28872639X4K27GA0000DS002000
S28872647X4K27GA0000AL002000
S28872650X6K27GA000087000500
S28872651A4K27GA0000DVB002000DIS   0000329200Y
S28872650A6K27GA00008BB000500IWM   0000736100Y
S28872652XBK27GA0000OC000100
S28872652ABK27GA0000OFS000100TWM   0000702200Y
S28872652ABK27GA0000OGB000100UWM   0000542500Y
S28872654X5K27GA00004Q002000
S28872655X6K27GA00008B000500
S28872655A6K27GA00008BB000500IWM   0000736200Y
S28872657XBK27GA0000OF000100
S28872657XBK27GA0000OG000100
S28872659ABK27GA0000OHS000100TWM   0000702400Y
S28872658X6K27GA00008B000500
S28872658A6K27GA00008BB000500IWM   0000736600Y
S28872661ABK27GA0000OIB000100UWM   0000542500Y
S28872661XBK27GA0000OH000100
S28872661X5K27GA00004R002000
S28872661ABK27GA0000OJS000100TWM   0000702200Y
S28872665X6K27GA00008B000500
S28872665A6K27GA00008BB000500IWM   0000736200Y
S28872668XBK27GA0000OI000100
S28872668XBK27GA0000OJ000100
S28872670ABK27GA0000OKS000100TWM   0000702400Y
S28872669X6K27GA00008B000500
S28872669A6K27GA00008BB000500IWM   0000736600Y
S28872672ABK27GA0000OLB000100UWM   0000542500Y
S28872672XBK27GA0000OK000100
S28872672ABK27GA0000OMS000100TWM   0000702200Y
S28872675X6K27GA00008B000500
S28872675A6K27GA00008BB000500IWM   0000736200Y
S28872678XBK27GA0000OL000100
S28872678XBK27GA0000OM000100
S28872680ABK27GA0000ONS000100TWM   0000702400Y
S28872684A7K27GA000043B002000MAT   0000185000Y
S28872686ABK27GA0000OOB000100UWM   0000542500Y
S28872685X6K27GA00008B000500
S28872685A6K27GA00008BB000500IWM   0000736600Y
S28872687ABK27GA0000OPS000100TWM   0000702200Y
S28872687XBK27GA0000ON000100
S28872695X6K27GA00008B000500
S28872695A6K27GA00008BB000500IWM   0000736200Y
S28872698XBK27GA0000OO000100
S28872698XBK27GA0000OP000100
S28872700ABK27GA0000OQS000100TWM   0000702400Y
S28872699X6K27GA00008B000500
S28872699A6K27GA00008BB000500IWM   0000736600Y
S28872702ABK27GA0000ORB000100UWM   0000542500Y
S28872702XBK27GA0000OQ000100
S28872702ABK27GA0000OSS000100TWM   0000702200Y
S28872705X6K27GA00008B000500
S28872705A6K27GA00008BB000500IWM   0000736200Y
S28872708XBK27GA0000OR000100
S28872708XBK27GA0000OS000100
S28872710ABK27GA0000OTS000100TWM   0000702400Y
S28872709X6K27GA00008B000500
S28872709A6K27GA00008BB000500IWM   0000736600Y
S28872712ABK27GA0000OUB000100UWM   0000542500Y
S28872712XBK27GA0000OT000100
S28872712ABK27GA0000OVS000100TWM   0000702200Y
S28872715X6K27GA00008B000500
S28872715A6K27GA00008BB000500IWM   0000736200Y
S28872718XBK27GA0000OU000100
S28872718XBK27GA0000OV000100
S28872718A6K27GA00008CB000100IWM   0000736100Y
S28872718X6K27GA00008C000100
S28872720ABK27GA0000OWS000100TWM   0000702400Y
S28872719X6K27GA00008B000500
S28872719A6K27GA00008BB000500IWM   0000736600Y
S28872721ABK27GA0000OXB000100UWM   0000542500Y
S28872722ABK27GA0000OYS000100TWM   0000702200Y
S28872722XBK27GA0000OW000100
S28872725X6K27GA00008B000500
S28872725A6K27GA00008BB000500IWM   0000736200Y
S28872728XBK27GA0000OX000100
S28872729XBK27GA0000OY000100
S28872728A6K27GA00008DB000100IWM   0000736100Y
S28872730ABK27GA0000OZS000100TWM   0000702400Y
S28872729X6K27GA00008D000100
S28872729X6K27GA00008B000500
S28872729A6K27GA00008BB000500IWM   0000736600Y
S28872733ABK27GA0000P0B000100UWM   0000542500Y
S28872733XBK27GA0000OZ000100
S28872733ABK27GA0000P1S000100TWM   0000702200Y
S28872735X6K27GA00008B000500
S28872735A6K27GA00008BB000500IWM   0000736200Y
S28872738XBK27GA0000P0000100
S28872738XBK27GA0000P1000100
S28872740ABK27GA0000P2S000100TWM   0000702400Y
S28872745X6K27GA00008B000500
S28872745A6K27GA00008BB000500IWM   0000736600Y
S28872746ABK27GA0000P3B000100UWM   0000542500Y
S28872747ABK27GA0000P4S000100TWM   0000702200Y
S28872747XBK27GA0000P2000100
S28872755X6K27GA00008B000500
S28872755A6K27GA00008BB000500IWM   0000736200Y
S28872756XBK27GA0000P3000100
S28872756XBK27GA0000P4000100
S28872758ABK27GA0000P5S000100TWM   0000702400Y
S28872758X6K27GA00008B000500
S28872758A6K27GA00008BB000500IWM   0000736600Y
